[2024-05-24 16:04:55,303][flwr][INFO] - Starting Flower simulation, config: ServerConfig(num_rounds=5, round_timeout=None)
[2024-05-24 16:05:00,365][flwr][INFO] - Flower VCE: Ray initialized with resources: {'node:127.0.0.1': 1.0, 'memory': 495063860.0, 'object_store_memory': 247531929.0, 'CPU': 8.0}
[2024-05-24 16:05:00,368][flwr][INFO] - Initializing global parameters
[2024-05-24 16:05:00,369][flwr][INFO] - Requesting initial parameters from one random client
[2024-05-24 16:05:04,282][flwr][INFO] - Received initial parameters from one random client
[2024-05-24 16:05:04,282][flwr][INFO] - Evaluating initial parameters
[2024-05-24 16:05:06,954][flwr][INFO] - initial parameters (loss, other metrics): 182.40915274620056, {'accuracy': 0.1068}
[2024-05-24 16:05:06,955][flwr][INFO] - FL starting
[2024-05-24 16:05:06,956][flwr][DEBUG] - fit_round 1: strategy sampled 10 clients (out of 100)
[2024-05-24 16:05:11,056][flwr][ERROR] - [36mray::launch_and_fit()[39m (pid=7840, ip=127.0.0.1)
  File "python\ray\_raylet.pyx", line 600, in ray._raylet.execute_task
  File "C:\Users\B00830189\AppData\Local\anaconda3\envs\flower_tutorial\lib\site-packages\ray\_private\memory_monitor.py", line 156, in raise_if_low_memory
    raise RayOutOfMemoryError(
ray._private.memory_monitor.RayOutOfMemoryError: More than 95% of the memory on node 2RWV8C3 is used (7.26 / 7.63 GB). The top 10 memory consumers are:

PID	MEM	COMMAND
12024	0.39GiB	python main.py num_rounds=5
11220	0.32GiB	C:\Users\B00830189\AppData\Local\anaconda3\envs\flower_tutorial\python.exe C:\Users\B00830189\AppDat
8948	0.24GiB	C:\Users\B00830189\AppData\Local\anaconda3\envs\flower_tutorial\python.exe C:\Users\B00830189\AppDat
10828	0.21GiB	C:\Program Files\Google\Chrome\Application\chrome.exe --type=renderer --enable-dinosaur-easter-egg-a
4028	0.2GiB	C:\Program Files\Google\Chrome\Application\chrome.exe --type=renderer --enable-dinosaur-easter-egg-a
7720	0.18GiB	C:\Program Files (x86)\Microsoft\EdgeWebView\Application\124.0.2478.97\msedgewebview2.exe --type=ren
7628	0.18GiB	C:\Users\B00830189\AppData\Local\Programs\Microsoft VS Code\Code.exe --type=renderer --user-data-dir
4904	0.16GiB	C:\Program Files\Google\Chrome\Application\chrome.exe
3212	0.16GiB	C:\Users\B00830189\AppData\Local\Programs\Microsoft VS Code\Code.exe c:\Users\B00830189\.vscode\exte
16760	0.14GiB	C:\Windows\Explorer.EXE

In addition, up to 0.0 GiB of shared memory is currently being used by the Ray object store.
---
--- Tip: Use the `ray memory` command to list active objects in the cluster.
--- To disable OOM exceptions, set RAY_DISABLE_MEMORY_MONITOR=1.
---
[2024-05-24 16:05:11,069][flwr][ERROR] - [36mray::launch_and_fit()[39m (pid=11220, ip=127.0.0.1)
  File "python\ray\_raylet.pyx", line 600, in ray._raylet.execute_task
  File "C:\Users\B00830189\AppData\Local\anaconda3\envs\flower_tutorial\lib\site-packages\ray\_private\memory_monitor.py", line 156, in raise_if_low_memory
    raise RayOutOfMemoryError(
ray._private.memory_monitor.RayOutOfMemoryError: More than 95% of the memory on node 2RWV8C3 is used (7.32 / 7.63 GB). The top 10 memory consumers are:

PID	MEM	COMMAND
12024	0.38GiB	python main.py num_rounds=5
11220	0.32GiB	C:\Users\B00830189\AppData\Local\anaconda3\envs\flower_tutorial\python.exe C:\Users\B00830189\AppDat
8948	0.24GiB	C:\Users\B00830189\AppData\Local\anaconda3\envs\flower_tutorial\python.exe C:\Users\B00830189\AppDat
10828	0.21GiB	C:\Program Files\Google\Chrome\Application\chrome.exe --type=renderer --enable-dinosaur-easter-egg-a
7720	0.2GiB	C:\Program Files (x86)\Microsoft\EdgeWebView\Application\124.0.2478.97\msedgewebview2.exe --type=ren
4028	0.2GiB	C:\Program Files\Google\Chrome\Application\chrome.exe --type=renderer --enable-dinosaur-easter-egg-a
7628	0.18GiB	C:\Users\B00830189\AppData\Local\Programs\Microsoft VS Code\Code.exe --type=renderer --user-data-dir
4904	0.16GiB	C:\Program Files\Google\Chrome\Application\chrome.exe
3212	0.16GiB	C:\Users\B00830189\AppData\Local\Programs\Microsoft VS Code\Code.exe c:\Users\B00830189\.vscode\exte
16760	0.14GiB	C:\Windows\Explorer.EXE

In addition, up to 0.0 GiB of shared memory is currently being used by the Ray object store.
---
--- Tip: Use the `ray memory` command to list active objects in the cluster.
--- To disable OOM exceptions, set RAY_DISABLE_MEMORY_MONITOR=1.
---
[2024-05-24 16:05:19,531][flwr][ERROR] - [36mray::launch_and_fit()[39m (pid=11220, ip=127.0.0.1)
  File "C:\Users\B00830189\AppData\Local\anaconda3\envs\flower_tutorial\lib\multiprocessing\queues.py", line 108, in get
    raise Empty
_queue.Empty

The above exception was the direct cause of the following exception:

[36mray::launch_and_fit()[39m (pid=11220, ip=127.0.0.1)
  File "python\ray\_raylet.pyx", line 633, in ray._raylet.execute_task
  File "python\ray\_raylet.pyx", line 674, in ray._raylet.execute_task
  File "python\ray\_raylet.pyx", line 640, in ray._raylet.execute_task
  File "python\ray\_raylet.pyx", line 644, in ray._raylet.execute_task
  File "C:\Users\B00830189\AppData\Local\anaconda3\envs\flower_tutorial\lib\site-packages\flwr\simulation\ray_transport\ray_client_proxy.py", line 148, in launch_and_fit
    return maybe_call_fit(
  File "C:\Users\B00830189\AppData\Local\anaconda3\envs\flower_tutorial\lib\site-packages\flwr\client\client.py", line 184, in maybe_call_fit
    return client.fit(fit_ins)
  File "C:\Users\B00830189\AppData\Local\anaconda3\envs\flower_tutorial\lib\site-packages\flwr\client\app.py", line 297, in _fit
    results = self.numpy_client.fit(parameters, ins.config)  # type: ignore
  File "C:\Users\B00830189\OneDrive - Ulster University\phd\Code\Demos\Flower\FlowerTutorial\client.py", line 48, in fit
    train(self.model, self.trainload, optim, epochs, self.device) # Model no longer has weights sent my the server
  File "C:\Users\B00830189\OneDrive - Ulster University\phd\Code\Demos\Flower\FlowerTutorial\model.py", line 45, in train
    for images, labels in trainloader:
  File "C:\Users\B00830189\AppData\Local\anaconda3\envs\flower_tutorial\lib\site-packages\torch\utils\data\dataloader.py", line 628, in __next__
    data = self._next_data()
  File "C:\Users\B00830189\AppData\Local\anaconda3\envs\flower_tutorial\lib\site-packages\torch\utils\data\dataloader.py", line 1316, in _next_data
    idx, data = self._get_data()
  File "C:\Users\B00830189\AppData\Local\anaconda3\envs\flower_tutorial\lib\site-packages\torch\utils\data\dataloader.py", line 1282, in _get_data
    success, data = self._try_get_data()
  File "C:\Users\B00830189\AppData\Local\anaconda3\envs\flower_tutorial\lib\site-packages\torch\utils\data\dataloader.py", line 1133, in _try_get_data
    raise RuntimeError('DataLoader worker (pid(s) {}) exited unexpectedly'.format(pids_str)) from e
RuntimeError: DataLoader worker (pid(s) 3984, 12516) exited unexpectedly
[2024-05-24 16:05:21,121][flwr][ERROR] - [36mray::launch_and_fit()[39m (pid=11220, ip=127.0.0.1)
  File "python\ray\_raylet.pyx", line 600, in ray._raylet.execute_task
  File "C:\Users\B00830189\AppData\Local\anaconda3\envs\flower_tutorial\lib\site-packages\ray\_private\memory_monitor.py", line 156, in raise_if_low_memory
    raise RayOutOfMemoryError(
ray._private.memory_monitor.RayOutOfMemoryError: More than 95% of the memory on node 2RWV8C3 is used (7.47 / 7.63 GB). The top 10 memory consumers are:

PID	MEM	COMMAND
8948	0.34GiB	C:\Users\B00830189\AppData\Local\anaconda3\envs\flower_tutorial\python.exe C:\Users\B00830189\AppDat
7840	0.34GiB	C:\Users\B00830189\AppData\Local\anaconda3\envs\flower_tutorial\python.exe C:\Users\B00830189\AppDat
12024	0.32GiB	python main.py num_rounds=5
11220	0.29GiB	C:\Users\B00830189\AppData\Local\anaconda3\envs\flower_tutorial\python.exe C:\Users\B00830189\AppDat
7504	0.25GiB	C:\Users\B00830189\AppData\Local\anaconda3\envs\flower_tutorial\python.exe C:\Users\B00830189\AppDat
11204	0.24GiB	C:\Users\B00830189\AppData\Local\anaconda3\envs\flower_tutorial\python.exe -c from multiprocessing.s
8416	0.16GiB	C:\Users\B00830189\AppData\Local\anaconda3\envs\flower_tutorial\python.exe C:\Users\B00830189\AppDat
3212	0.15GiB	C:\Users\B00830189\AppData\Local\Programs\Microsoft VS Code\Code.exe c:\Users\B00830189\.vscode\exte
7628	0.13GiB	C:\Users\B00830189\AppData\Local\Programs\Microsoft VS Code\Code.exe --type=renderer --user-data-dir
4028	0.13GiB	C:\Program Files\Google\Chrome\Application\chrome.exe --type=renderer --enable-dinosaur-easter-egg-a

In addition, up to 0.0 GiB of shared memory is currently being used by the Ray object store.
---
--- Tip: Use the `ray memory` command to list active objects in the cluster.
--- To disable OOM exceptions, set RAY_DISABLE_MEMORY_MONITOR=1.
---
[2024-05-24 16:05:21,226][flwr][ERROR] - [36mray::launch_and_fit()[39m (pid=8948, ip=127.0.0.1)
  File "C:\Users\B00830189\AppData\Local\anaconda3\envs\flower_tutorial\lib\multiprocessing\queues.py", line 108, in get
    raise Empty
_queue.Empty

The above exception was the direct cause of the following exception:

[36mray::launch_and_fit()[39m (pid=8948, ip=127.0.0.1)
  File "python\ray\_raylet.pyx", line 633, in ray._raylet.execute_task
  File "python\ray\_raylet.pyx", line 674, in ray._raylet.execute_task
  File "python\ray\_raylet.pyx", line 640, in ray._raylet.execute_task
  File "python\ray\_raylet.pyx", line 644, in ray._raylet.execute_task
  File "C:\Users\B00830189\AppData\Local\anaconda3\envs\flower_tutorial\lib\site-packages\flwr\simulation\ray_transport\ray_client_proxy.py", line 148, in launch_and_fit
    return maybe_call_fit(
  File "C:\Users\B00830189\AppData\Local\anaconda3\envs\flower_tutorial\lib\site-packages\flwr\client\client.py", line 184, in maybe_call_fit
    return client.fit(fit_ins)
  File "C:\Users\B00830189\AppData\Local\anaconda3\envs\flower_tutorial\lib\site-packages\flwr\client\app.py", line 297, in _fit
    results = self.numpy_client.fit(parameters, ins.config)  # type: ignore
  File "C:\Users\B00830189\OneDrive - Ulster University\phd\Code\Demos\Flower\FlowerTutorial\client.py", line 48, in fit
    train(self.model, self.trainload, optim, epochs, self.device) # Model no longer has weights sent my the server
  File "C:\Users\B00830189\OneDrive - Ulster University\phd\Code\Demos\Flower\FlowerTutorial\model.py", line 45, in train
    for images, labels in trainloader:
  File "C:\Users\B00830189\AppData\Local\anaconda3\envs\flower_tutorial\lib\site-packages\torch\utils\data\dataloader.py", line 628, in __next__
    data = self._next_data()
  File "C:\Users\B00830189\AppData\Local\anaconda3\envs\flower_tutorial\lib\site-packages\torch\utils\data\dataloader.py", line 1316, in _next_data
    idx, data = self._get_data()
  File "C:\Users\B00830189\AppData\Local\anaconda3\envs\flower_tutorial\lib\site-packages\torch\utils\data\dataloader.py", line 1282, in _get_data
    success, data = self._try_get_data()
  File "C:\Users\B00830189\AppData\Local\anaconda3\envs\flower_tutorial\lib\site-packages\torch\utils\data\dataloader.py", line 1133, in _try_get_data
    raise RuntimeError('DataLoader worker (pid(s) {}) exited unexpectedly'.format(pids_str)) from e
RuntimeError: DataLoader worker (pid(s) 19188) exited unexpectedly
[2024-05-24 16:05:22,577][flwr][ERROR] - [36mray::launch_and_fit()[39m (pid=7840, ip=127.0.0.1)
  File "C:\Users\B00830189\AppData\Local\anaconda3\envs\flower_tutorial\lib\multiprocessing\queues.py", line 108, in get
    raise Empty
_queue.Empty

The above exception was the direct cause of the following exception:

[36mray::launch_and_fit()[39m (pid=7840, ip=127.0.0.1)
  File "python\ray\_raylet.pyx", line 633, in ray._raylet.execute_task
  File "python\ray\_raylet.pyx", line 674, in ray._raylet.execute_task
  File "python\ray\_raylet.pyx", line 640, in ray._raylet.execute_task
  File "python\ray\_raylet.pyx", line 644, in ray._raylet.execute_task
  File "C:\Users\B00830189\AppData\Local\anaconda3\envs\flower_tutorial\lib\site-packages\flwr\simulation\ray_transport\ray_client_proxy.py", line 148, in launch_and_fit
    return maybe_call_fit(
  File "C:\Users\B00830189\AppData\Local\anaconda3\envs\flower_tutorial\lib\site-packages\flwr\client\client.py", line 184, in maybe_call_fit
    return client.fit(fit_ins)
  File "C:\Users\B00830189\AppData\Local\anaconda3\envs\flower_tutorial\lib\site-packages\flwr\client\app.py", line 297, in _fit
    results = self.numpy_client.fit(parameters, ins.config)  # type: ignore
  File "C:\Users\B00830189\OneDrive - Ulster University\phd\Code\Demos\Flower\FlowerTutorial\client.py", line 48, in fit
    train(self.model, self.trainload, optim, epochs, self.device) # Model no longer has weights sent my the server
  File "C:\Users\B00830189\OneDrive - Ulster University\phd\Code\Demos\Flower\FlowerTutorial\model.py", line 45, in train
    for images, labels in trainloader:
  File "C:\Users\B00830189\AppData\Local\anaconda3\envs\flower_tutorial\lib\site-packages\torch\utils\data\dataloader.py", line 628, in __next__
    data = self._next_data()
  File "C:\Users\B00830189\AppData\Local\anaconda3\envs\flower_tutorial\lib\site-packages\torch\utils\data\dataloader.py", line 1316, in _next_data
    idx, data = self._get_data()
  File "C:\Users\B00830189\AppData\Local\anaconda3\envs\flower_tutorial\lib\site-packages\torch\utils\data\dataloader.py", line 1282, in _get_data
    success, data = self._try_get_data()
  File "C:\Users\B00830189\AppData\Local\anaconda3\envs\flower_tutorial\lib\site-packages\torch\utils\data\dataloader.py", line 1133, in _try_get_data
    raise RuntimeError('DataLoader worker (pid(s) {}) exited unexpectedly'.format(pids_str)) from e
RuntimeError: DataLoader worker (pid(s) 19016, 4444) exited unexpectedly
[2024-05-24 16:05:28,159][flwr][ERROR] - [36mray::launch_and_fit()[39m (pid=7840, ip=127.0.0.1)
  File "C:\Users\B00830189\AppData\Local\anaconda3\envs\flower_tutorial\lib\multiprocessing\queues.py", line 108, in get
    raise Empty
_queue.Empty

The above exception was the direct cause of the following exception:

[36mray::launch_and_fit()[39m (pid=7840, ip=127.0.0.1)
  File "python\ray\_raylet.pyx", line 633, in ray._raylet.execute_task
  File "python\ray\_raylet.pyx", line 674, in ray._raylet.execute_task
  File "python\ray\_raylet.pyx", line 640, in ray._raylet.execute_task
  File "python\ray\_raylet.pyx", line 644, in ray._raylet.execute_task
  File "C:\Users\B00830189\AppData\Local\anaconda3\envs\flower_tutorial\lib\site-packages\flwr\simulation\ray_transport\ray_client_proxy.py", line 148, in launch_and_fit
    return maybe_call_fit(
  File "C:\Users\B00830189\AppData\Local\anaconda3\envs\flower_tutorial\lib\site-packages\flwr\client\client.py", line 184, in maybe_call_fit
    return client.fit(fit_ins)
  File "C:\Users\B00830189\AppData\Local\anaconda3\envs\flower_tutorial\lib\site-packages\flwr\client\app.py", line 297, in _fit
    results = self.numpy_client.fit(parameters, ins.config)  # type: ignore
  File "C:\Users\B00830189\OneDrive - Ulster University\phd\Code\Demos\Flower\FlowerTutorial\client.py", line 48, in fit
    train(self.model, self.trainload, optim, epochs, self.device) # Model no longer has weights sent my the server
  File "C:\Users\B00830189\OneDrive - Ulster University\phd\Code\Demos\Flower\FlowerTutorial\model.py", line 45, in train
    for images, labels in trainloader:
  File "C:\Users\B00830189\AppData\Local\anaconda3\envs\flower_tutorial\lib\site-packages\torch\utils\data\dataloader.py", line 628, in __next__
    data = self._next_data()
  File "C:\Users\B00830189\AppData\Local\anaconda3\envs\flower_tutorial\lib\site-packages\torch\utils\data\dataloader.py", line 1316, in _next_data
    idx, data = self._get_data()
  File "C:\Users\B00830189\AppData\Local\anaconda3\envs\flower_tutorial\lib\site-packages\torch\utils\data\dataloader.py", line 1282, in _get_data
    success, data = self._try_get_data()
  File "C:\Users\B00830189\AppData\Local\anaconda3\envs\flower_tutorial\lib\site-packages\torch\utils\data\dataloader.py", line 1133, in _try_get_data
    raise RuntimeError('DataLoader worker (pid(s) {}) exited unexpectedly'.format(pids_str)) from e
RuntimeError: DataLoader worker (pid(s) 3180, 13328) exited unexpectedly
[2024-05-24 16:05:29,202][flwr][ERROR] - [36mray::launch_and_fit()[39m (pid=7840, ip=127.0.0.1)
  File "python\ray\_raylet.pyx", line 600, in ray._raylet.execute_task
  File "C:\Users\B00830189\AppData\Local\anaconda3\envs\flower_tutorial\lib\site-packages\ray\_private\memory_monitor.py", line 156, in raise_if_low_memory
    raise RayOutOfMemoryError(
ray._private.memory_monitor.RayOutOfMemoryError: More than 95% of the memory on node 2RWV8C3 is used (7.29 / 7.63 GB). The top 10 memory consumers are:

PID	MEM	COMMAND
8948	0.39GiB	C:\Users\B00830189\AppData\Local\anaconda3\envs\flower_tutorial\python.exe C:\Users\B00830189\AppDat
11220	0.39GiB	C:\Users\B00830189\AppData\Local\anaconda3\envs\flower_tutorial\python.exe C:\Users\B00830189\AppDat
7840	0.34GiB	C:\Users\B00830189\AppData\Local\anaconda3\envs\flower_tutorial\python.exe C:\Users\B00830189\AppDat
12024	0.32GiB	python main.py num_rounds=5
7504	0.25GiB	C:\Users\B00830189\AppData\Local\anaconda3\envs\flower_tutorial\python.exe C:\Users\B00830189\AppDat
4132	0.25GiB	C:\Users\B00830189\AppData\Local\anaconda3\envs\flower_tutorial\python.exe -c from multiprocessing.s
17000	0.25GiB	C:\Users\B00830189\AppData\Local\anaconda3\envs\flower_tutorial\python.exe -c from multiprocessing.s
8416	0.16GiB	C:\Users\B00830189\AppData\Local\anaconda3\envs\flower_tutorial\python.exe C:\Users\B00830189\AppDat
3212	0.13GiB	C:\Users\B00830189\AppData\Local\Programs\Microsoft VS Code\Code.exe c:\Users\B00830189\.vscode\exte
7628	0.13GiB	C:\Users\B00830189\AppData\Local\Programs\Microsoft VS Code\Code.exe --type=renderer --user-data-dir

In addition, up to 0.0 GiB of shared memory is currently being used by the Ray object store.
---
--- Tip: Use the `ray memory` command to list active objects in the cluster.
--- To disable OOM exceptions, set RAY_DISABLE_MEMORY_MONITOR=1.
---
[2024-05-24 16:05:31,695][flwr][ERROR] - [36mray::launch_and_fit()[39m (pid=11220, ip=127.0.0.1)
  File "C:\Users\B00830189\AppData\Local\anaconda3\envs\flower_tutorial\lib\multiprocessing\queues.py", line 108, in get
    raise Empty
_queue.Empty

The above exception was the direct cause of the following exception:

[36mray::launch_and_fit()[39m (pid=11220, ip=127.0.0.1)
  File "python\ray\_raylet.pyx", line 633, in ray._raylet.execute_task
  File "python\ray\_raylet.pyx", line 674, in ray._raylet.execute_task
  File "python\ray\_raylet.pyx", line 640, in ray._raylet.execute_task
  File "python\ray\_raylet.pyx", line 644, in ray._raylet.execute_task
  File "C:\Users\B00830189\AppData\Local\anaconda3\envs\flower_tutorial\lib\site-packages\flwr\simulation\ray_transport\ray_client_proxy.py", line 148, in launch_and_fit
    return maybe_call_fit(
  File "C:\Users\B00830189\AppData\Local\anaconda3\envs\flower_tutorial\lib\site-packages\flwr\client\client.py", line 184, in maybe_call_fit
    return client.fit(fit_ins)
  File "C:\Users\B00830189\AppData\Local\anaconda3\envs\flower_tutorial\lib\site-packages\flwr\client\app.py", line 297, in _fit
    results = self.numpy_client.fit(parameters, ins.config)  # type: ignore
  File "C:\Users\B00830189\OneDrive - Ulster University\phd\Code\Demos\Flower\FlowerTutorial\client.py", line 48, in fit
    train(self.model, self.trainload, optim, epochs, self.device) # Model no longer has weights sent my the server
  File "C:\Users\B00830189\OneDrive - Ulster University\phd\Code\Demos\Flower\FlowerTutorial\model.py", line 45, in train
    for images, labels in trainloader:
  File "C:\Users\B00830189\AppData\Local\anaconda3\envs\flower_tutorial\lib\site-packages\torch\utils\data\dataloader.py", line 628, in __next__
    data = self._next_data()
  File "C:\Users\B00830189\AppData\Local\anaconda3\envs\flower_tutorial\lib\site-packages\torch\utils\data\dataloader.py", line 1316, in _next_data
    idx, data = self._get_data()
  File "C:\Users\B00830189\AppData\Local\anaconda3\envs\flower_tutorial\lib\site-packages\torch\utils\data\dataloader.py", line 1282, in _get_data
    success, data = self._try_get_data()
  File "C:\Users\B00830189\AppData\Local\anaconda3\envs\flower_tutorial\lib\site-packages\torch\utils\data\dataloader.py", line 1133, in _try_get_data
    raise RuntimeError('DataLoader worker (pid(s) {}) exited unexpectedly'.format(pids_str)) from e
RuntimeError: DataLoader worker (pid(s) 16072) exited unexpectedly
[2024-05-24 16:05:31,696][flwr][ERROR] - [36mray::launch_and_fit()[39m (pid=8948, ip=127.0.0.1)
  File "C:\Users\B00830189\AppData\Local\anaconda3\envs\flower_tutorial\lib\multiprocessing\queues.py", line 108, in get
    raise Empty
_queue.Empty

The above exception was the direct cause of the following exception:

[36mray::launch_and_fit()[39m (pid=8948, ip=127.0.0.1)
  File "python\ray\_raylet.pyx", line 633, in ray._raylet.execute_task
  File "python\ray\_raylet.pyx", line 674, in ray._raylet.execute_task
  File "python\ray\_raylet.pyx", line 640, in ray._raylet.execute_task
  File "python\ray\_raylet.pyx", line 644, in ray._raylet.execute_task
  File "C:\Users\B00830189\AppData\Local\anaconda3\envs\flower_tutorial\lib\site-packages\flwr\simulation\ray_transport\ray_client_proxy.py", line 148, in launch_and_fit
    return maybe_call_fit(
  File "C:\Users\B00830189\AppData\Local\anaconda3\envs\flower_tutorial\lib\site-packages\flwr\client\client.py", line 184, in maybe_call_fit
    return client.fit(fit_ins)
  File "C:\Users\B00830189\AppData\Local\anaconda3\envs\flower_tutorial\lib\site-packages\flwr\client\app.py", line 297, in _fit
    results = self.numpy_client.fit(parameters, ins.config)  # type: ignore
  File "C:\Users\B00830189\OneDrive - Ulster University\phd\Code\Demos\Flower\FlowerTutorial\client.py", line 48, in fit
    train(self.model, self.trainload, optim, epochs, self.device) # Model no longer has weights sent my the server
  File "C:\Users\B00830189\OneDrive - Ulster University\phd\Code\Demos\Flower\FlowerTutorial\model.py", line 45, in train
    for images, labels in trainloader:
  File "C:\Users\B00830189\AppData\Local\anaconda3\envs\flower_tutorial\lib\site-packages\torch\utils\data\dataloader.py", line 628, in __next__
    data = self._next_data()
  File "C:\Users\B00830189\AppData\Local\anaconda3\envs\flower_tutorial\lib\site-packages\torch\utils\data\dataloader.py", line 1316, in _next_data
    idx, data = self._get_data()
  File "C:\Users\B00830189\AppData\Local\anaconda3\envs\flower_tutorial\lib\site-packages\torch\utils\data\dataloader.py", line 1282, in _get_data
    success, data = self._try_get_data()
  File "C:\Users\B00830189\AppData\Local\anaconda3\envs\flower_tutorial\lib\site-packages\torch\utils\data\dataloader.py", line 1133, in _try_get_data
    raise RuntimeError('DataLoader worker (pid(s) {}) exited unexpectedly'.format(pids_str)) from e
RuntimeError: DataLoader worker (pid(s) 8816) exited unexpectedly
[2024-05-24 16:05:31,702][flwr][DEBUG] - fit_round 1 received 0 results and 10 failures
[2024-05-24 16:05:34,520][flwr][INFO] - fit progress: (1, 182.40915274620056, {'accuracy': 0.1068}, 27.563688)
[2024-05-24 16:05:34,521][flwr][DEBUG] - evaluate_round 1: strategy sampled 25 clients (out of 100)
[2024-05-24 16:05:40,984][flwr][ERROR] - [36mray::launch_and_evaluate()[39m (pid=8948, ip=127.0.0.1)
  File "C:\Users\B00830189\AppData\Local\anaconda3\envs\flower_tutorial\lib\multiprocessing\queues.py", line 108, in get
    raise Empty
_queue.Empty

The above exception was the direct cause of the following exception:

[36mray::launch_and_evaluate()[39m (pid=8948, ip=127.0.0.1)
  File "python\ray\_raylet.pyx", line 633, in ray._raylet.execute_task
  File "python\ray\_raylet.pyx", line 674, in ray._raylet.execute_task
  File "python\ray\_raylet.pyx", line 640, in ray._raylet.execute_task
  File "python\ray\_raylet.pyx", line 644, in ray._raylet.execute_task
  File "C:\Users\B00830189\AppData\Local\anaconda3\envs\flower_tutorial\lib\site-packages\flwr\simulation\ray_transport\ray_client_proxy.py", line 160, in launch_and_evaluate
    return maybe_call_evaluate(
  File "C:\Users\B00830189\AppData\Local\anaconda3\envs\flower_tutorial\lib\site-packages\flwr\client\client.py", line 205, in maybe_call_evaluate
    return client.evaluate(evaluate_ins)
  File "C:\Users\B00830189\AppData\Local\anaconda3\envs\flower_tutorial\lib\site-packages\flwr\client\app.py", line 321, in _evaluate
    results = self.numpy_client.evaluate(parameters, ins.config)  # type: ignore
  File "C:\Users\B00830189\OneDrive - Ulster University\phd\Code\Demos\Flower\FlowerTutorial\client.py", line 55, in evaluate
    loss, accuracy = test(self.model, self.valloader, self.device)
  File "C:\Users\B00830189\OneDrive - Ulster University\phd\Code\Demos\Flower\FlowerTutorial\model.py", line 63, in test
    for data in testloader:
  File "C:\Users\B00830189\AppData\Local\anaconda3\envs\flower_tutorial\lib\site-packages\torch\utils\data\dataloader.py", line 628, in __next__
    data = self._next_data()
  File "C:\Users\B00830189\AppData\Local\anaconda3\envs\flower_tutorial\lib\site-packages\torch\utils\data\dataloader.py", line 1316, in _next_data
    idx, data = self._get_data()
  File "C:\Users\B00830189\AppData\Local\anaconda3\envs\flower_tutorial\lib\site-packages\torch\utils\data\dataloader.py", line 1282, in _get_data
    success, data = self._try_get_data()
  File "C:\Users\B00830189\AppData\Local\anaconda3\envs\flower_tutorial\lib\site-packages\torch\utils\data\dataloader.py", line 1133, in _try_get_data
    raise RuntimeError('DataLoader worker (pid(s) {}) exited unexpectedly'.format(pids_str)) from e
RuntimeError: DataLoader worker (pid(s) 456, 11784) exited unexpectedly
[2024-05-24 16:05:40,984][flwr][ERROR] - [36mray::launch_and_evaluate()[39m (pid=11220, ip=127.0.0.1)
  File "C:\Users\B00830189\AppData\Local\anaconda3\envs\flower_tutorial\lib\multiprocessing\queues.py", line 108, in get
    raise Empty
_queue.Empty

The above exception was the direct cause of the following exception:

[36mray::launch_and_evaluate()[39m (pid=11220, ip=127.0.0.1)
  File "python\ray\_raylet.pyx", line 633, in ray._raylet.execute_task
  File "python\ray\_raylet.pyx", line 674, in ray._raylet.execute_task
  File "python\ray\_raylet.pyx", line 640, in ray._raylet.execute_task
  File "python\ray\_raylet.pyx", line 644, in ray._raylet.execute_task
  File "C:\Users\B00830189\AppData\Local\anaconda3\envs\flower_tutorial\lib\site-packages\flwr\simulation\ray_transport\ray_client_proxy.py", line 160, in launch_and_evaluate
    return maybe_call_evaluate(
  File "C:\Users\B00830189\AppData\Local\anaconda3\envs\flower_tutorial\lib\site-packages\flwr\client\client.py", line 205, in maybe_call_evaluate
    return client.evaluate(evaluate_ins)
  File "C:\Users\B00830189\AppData\Local\anaconda3\envs\flower_tutorial\lib\site-packages\flwr\client\app.py", line 321, in _evaluate
    results = self.numpy_client.evaluate(parameters, ins.config)  # type: ignore
  File "C:\Users\B00830189\OneDrive - Ulster University\phd\Code\Demos\Flower\FlowerTutorial\client.py", line 55, in evaluate
    loss, accuracy = test(self.model, self.valloader, self.device)
  File "C:\Users\B00830189\OneDrive - Ulster University\phd\Code\Demos\Flower\FlowerTutorial\model.py", line 63, in test
    for data in testloader:
  File "C:\Users\B00830189\AppData\Local\anaconda3\envs\flower_tutorial\lib\site-packages\torch\utils\data\dataloader.py", line 628, in __next__
    data = self._next_data()
  File "C:\Users\B00830189\AppData\Local\anaconda3\envs\flower_tutorial\lib\site-packages\torch\utils\data\dataloader.py", line 1316, in _next_data
    idx, data = self._get_data()
  File "C:\Users\B00830189\AppData\Local\anaconda3\envs\flower_tutorial\lib\site-packages\torch\utils\data\dataloader.py", line 1282, in _get_data
    success, data = self._try_get_data()
  File "C:\Users\B00830189\AppData\Local\anaconda3\envs\flower_tutorial\lib\site-packages\torch\utils\data\dataloader.py", line 1133, in _try_get_data
    raise RuntimeError('DataLoader worker (pid(s) {}) exited unexpectedly'.format(pids_str)) from e
RuntimeError: DataLoader worker (pid(s) 752, 15304) exited unexpectedly
[2024-05-24 16:05:41,345][flwr][ERROR] - [36mray::launch_and_evaluate()[39m (pid=7840, ip=127.0.0.1)
  File "C:\Users\B00830189\AppData\Local\anaconda3\envs\flower_tutorial\lib\multiprocessing\queues.py", line 108, in get
    raise Empty
_queue.Empty

The above exception was the direct cause of the following exception:

[36mray::launch_and_evaluate()[39m (pid=7840, ip=127.0.0.1)
  File "python\ray\_raylet.pyx", line 633, in ray._raylet.execute_task
  File "python\ray\_raylet.pyx", line 674, in ray._raylet.execute_task
  File "python\ray\_raylet.pyx", line 640, in ray._raylet.execute_task
  File "python\ray\_raylet.pyx", line 644, in ray._raylet.execute_task
  File "C:\Users\B00830189\AppData\Local\anaconda3\envs\flower_tutorial\lib\site-packages\flwr\simulation\ray_transport\ray_client_proxy.py", line 160, in launch_and_evaluate
    return maybe_call_evaluate(
  File "C:\Users\B00830189\AppData\Local\anaconda3\envs\flower_tutorial\lib\site-packages\flwr\client\client.py", line 205, in maybe_call_evaluate
    return client.evaluate(evaluate_ins)
  File "C:\Users\B00830189\AppData\Local\anaconda3\envs\flower_tutorial\lib\site-packages\flwr\client\app.py", line 321, in _evaluate
    results = self.numpy_client.evaluate(parameters, ins.config)  # type: ignore
  File "C:\Users\B00830189\OneDrive - Ulster University\phd\Code\Demos\Flower\FlowerTutorial\client.py", line 55, in evaluate
    loss, accuracy = test(self.model, self.valloader, self.device)
  File "C:\Users\B00830189\OneDrive - Ulster University\phd\Code\Demos\Flower\FlowerTutorial\model.py", line 63, in test
    for data in testloader:
  File "C:\Users\B00830189\AppData\Local\anaconda3\envs\flower_tutorial\lib\site-packages\torch\utils\data\dataloader.py", line 628, in __next__
    data = self._next_data()
  File "C:\Users\B00830189\AppData\Local\anaconda3\envs\flower_tutorial\lib\site-packages\torch\utils\data\dataloader.py", line 1316, in _next_data
    idx, data = self._get_data()
  File "C:\Users\B00830189\AppData\Local\anaconda3\envs\flower_tutorial\lib\site-packages\torch\utils\data\dataloader.py", line 1282, in _get_data
    success, data = self._try_get_data()
  File "C:\Users\B00830189\AppData\Local\anaconda3\envs\flower_tutorial\lib\site-packages\torch\utils\data\dataloader.py", line 1133, in _try_get_data
    raise RuntimeError('DataLoader worker (pid(s) {}) exited unexpectedly'.format(pids_str)) from e
RuntimeError: DataLoader worker (pid(s) 14820, 16544) exited unexpectedly
[2024-05-24 16:05:47,200][flwr][ERROR] - [36mray::launch_and_evaluate()[39m (pid=7840, ip=127.0.0.1)
  File "C:\Users\B00830189\AppData\Local\anaconda3\envs\flower_tutorial\lib\multiprocessing\queues.py", line 108, in get
    raise Empty
_queue.Empty

The above exception was the direct cause of the following exception:

[36mray::launch_and_evaluate()[39m (pid=7840, ip=127.0.0.1)
  File "python\ray\_raylet.pyx", line 633, in ray._raylet.execute_task
  File "python\ray\_raylet.pyx", line 674, in ray._raylet.execute_task
  File "python\ray\_raylet.pyx", line 640, in ray._raylet.execute_task
  File "python\ray\_raylet.pyx", line 644, in ray._raylet.execute_task
  File "C:\Users\B00830189\AppData\Local\anaconda3\envs\flower_tutorial\lib\site-packages\flwr\simulation\ray_transport\ray_client_proxy.py", line 160, in launch_and_evaluate
    return maybe_call_evaluate(
  File "C:\Users\B00830189\AppData\Local\anaconda3\envs\flower_tutorial\lib\site-packages\flwr\client\client.py", line 205, in maybe_call_evaluate
    return client.evaluate(evaluate_ins)
  File "C:\Users\B00830189\AppData\Local\anaconda3\envs\flower_tutorial\lib\site-packages\flwr\client\app.py", line 321, in _evaluate
    results = self.numpy_client.evaluate(parameters, ins.config)  # type: ignore
  File "C:\Users\B00830189\OneDrive - Ulster University\phd\Code\Demos\Flower\FlowerTutorial\client.py", line 55, in evaluate
    loss, accuracy = test(self.model, self.valloader, self.device)
  File "C:\Users\B00830189\OneDrive - Ulster University\phd\Code\Demos\Flower\FlowerTutorial\model.py", line 63, in test
    for data in testloader:
  File "C:\Users\B00830189\AppData\Local\anaconda3\envs\flower_tutorial\lib\site-packages\torch\utils\data\dataloader.py", line 628, in __next__
    data = self._next_data()
  File "C:\Users\B00830189\AppData\Local\anaconda3\envs\flower_tutorial\lib\site-packages\torch\utils\data\dataloader.py", line 1316, in _next_data
    idx, data = self._get_data()
  File "C:\Users\B00830189\AppData\Local\anaconda3\envs\flower_tutorial\lib\site-packages\torch\utils\data\dataloader.py", line 1282, in _get_data
    success, data = self._try_get_data()
  File "C:\Users\B00830189\AppData\Local\anaconda3\envs\flower_tutorial\lib\site-packages\torch\utils\data\dataloader.py", line 1133, in _try_get_data
    raise RuntimeError('DataLoader worker (pid(s) {}) exited unexpectedly'.format(pids_str)) from e
RuntimeError: DataLoader worker (pid(s) 12104, 5260) exited unexpectedly
[2024-05-24 16:05:47,360][flwr][ERROR] - [36mray::launch_and_evaluate()[39m (pid=7840, ip=127.0.0.1)
  File "python\ray\_raylet.pyx", line 602, in ray._raylet.execute_task
  File "python\ray\_raylet.pyx", line 624, in ray._raylet.execute_task
  File "python\ray\_raylet.pyx", line 456, in ray._raylet.raise_if_dependency_failed
ray.exceptions.RaySystemError: System error: [enforce fail at C:\cb\pytorch_1000000000000\work\c10\core\impl\alloc_cpu.cpp:72] data. DefaultCPUAllocator: not enough memory: you tried to allocate 47040000 bytes.
traceback: Traceback (most recent call last):
  File "C:\Users\B00830189\AppData\Local\anaconda3\envs\flower_tutorial\lib\site-packages\ray\serialization.py", line 309, in deserialize_objects
    obj = self._deserialize_object(data, metadata, object_ref)
  File "C:\Users\B00830189\AppData\Local\anaconda3\envs\flower_tutorial\lib\site-packages\ray\serialization.py", line 215, in _deserialize_object
    return self._deserialize_msgpack_data(data, metadata_fields)
  File "C:\Users\B00830189\AppData\Local\anaconda3\envs\flower_tutorial\lib\site-packages\ray\serialization.py", line 174, in _deserialize_msgpack_data
    python_objects = self._deserialize_pickle5_data(pickle5_data)
  File "C:\Users\B00830189\AppData\Local\anaconda3\envs\flower_tutorial\lib\site-packages\ray\serialization.py", line 164, in _deserialize_pickle5_data
    obj = pickle.loads(in_band)
  File "C:\Users\B00830189\AppData\Local\anaconda3\envs\flower_tutorial\lib\site-packages\torch\storage.py", line 240, in _load_from_bytes
    return torch.load(io.BytesIO(b))
  File "C:\Users\B00830189\AppData\Local\anaconda3\envs\flower_tutorial\lib\site-packages\torch\serialization.py", line 795, in load
    return _legacy_load(opened_file, map_location, pickle_module, **pickle_load_args)
  File "C:\Users\B00830189\AppData\Local\anaconda3\envs\flower_tutorial\lib\site-packages\torch\serialization.py", line 1012, in _legacy_load
    result = unpickler.load()
  File "C:\Users\B00830189\AppData\Local\anaconda3\envs\flower_tutorial\lib\site-packages\torch\serialization.py", line 953, in persistent_load
    obj = cast(Storage, torch.UntypedStorage(nbytes))
RuntimeError: [enforce fail at C:\cb\pytorch_1000000000000\work\c10\core\impl\alloc_cpu.cpp:72] data. DefaultCPUAllocator: not enough memory: you tried to allocate 47040000 bytes.
[2024-05-24 16:05:47,428][flwr][ERROR] - [36mray::launch_and_evaluate()[39m (pid=7840, ip=127.0.0.1)
  File "python\ray\_raylet.pyx", line 602, in ray._raylet.execute_task
  File "python\ray\_raylet.pyx", line 624, in ray._raylet.execute_task
  File "python\ray\_raylet.pyx", line 456, in ray._raylet.raise_if_dependency_failed
ray.exceptions.RaySystemError: System error: [enforce fail at C:\cb\pytorch_1000000000000\work\c10\core\impl\alloc_cpu.cpp:72] data. DefaultCPUAllocator: not enough memory: you tried to allocate 47040000 bytes.
traceback: Traceback (most recent call last):
  File "C:\Users\B00830189\AppData\Local\anaconda3\envs\flower_tutorial\lib\site-packages\ray\serialization.py", line 309, in deserialize_objects
    obj = self._deserialize_object(data, metadata, object_ref)
  File "C:\Users\B00830189\AppData\Local\anaconda3\envs\flower_tutorial\lib\site-packages\ray\serialization.py", line 215, in _deserialize_object
    return self._deserialize_msgpack_data(data, metadata_fields)
  File "C:\Users\B00830189\AppData\Local\anaconda3\envs\flower_tutorial\lib\site-packages\ray\serialization.py", line 174, in _deserialize_msgpack_data
    python_objects = self._deserialize_pickle5_data(pickle5_data)
  File "C:\Users\B00830189\AppData\Local\anaconda3\envs\flower_tutorial\lib\site-packages\ray\serialization.py", line 164, in _deserialize_pickle5_data
    obj = pickle.loads(in_band)
  File "C:\Users\B00830189\AppData\Local\anaconda3\envs\flower_tutorial\lib\site-packages\torch\storage.py", line 240, in _load_from_bytes
    return torch.load(io.BytesIO(b))
  File "C:\Users\B00830189\AppData\Local\anaconda3\envs\flower_tutorial\lib\site-packages\torch\serialization.py", line 795, in load
    return _legacy_load(opened_file, map_location, pickle_module, **pickle_load_args)
  File "C:\Users\B00830189\AppData\Local\anaconda3\envs\flower_tutorial\lib\site-packages\torch\serialization.py", line 1012, in _legacy_load
    result = unpickler.load()
  File "C:\Users\B00830189\AppData\Local\anaconda3\envs\flower_tutorial\lib\site-packages\torch\serialization.py", line 953, in persistent_load
    obj = cast(Storage, torch.UntypedStorage(nbytes))
RuntimeError: [enforce fail at C:\cb\pytorch_1000000000000\work\c10\core\impl\alloc_cpu.cpp:72] data. DefaultCPUAllocator: not enough memory: you tried to allocate 47040000 bytes.
[2024-05-24 16:05:47,430][flwr][ERROR] - [36mray::launch_and_evaluate()[39m (pid=7840, ip=127.0.0.1)
  File "python\ray\_raylet.pyx", line 602, in ray._raylet.execute_task
  File "python\ray\_raylet.pyx", line 624, in ray._raylet.execute_task
  File "python\ray\_raylet.pyx", line 456, in ray._raylet.raise_if_dependency_failed
ray.exceptions.RaySystemError: System error: 
traceback: Traceback (most recent call last):
  File "C:\Users\B00830189\AppData\Local\anaconda3\envs\flower_tutorial\lib\site-packages\ray\serialization.py", line 309, in deserialize_objects
    obj = self._deserialize_object(data, metadata, object_ref)
  File "C:\Users\B00830189\AppData\Local\anaconda3\envs\flower_tutorial\lib\site-packages\ray\serialization.py", line 215, in _deserialize_object
    return self._deserialize_msgpack_data(data, metadata_fields)
  File "C:\Users\B00830189\AppData\Local\anaconda3\envs\flower_tutorial\lib\site-packages\ray\serialization.py", line 174, in _deserialize_msgpack_data
    python_objects = self._deserialize_pickle5_data(pickle5_data)
  File "C:\Users\B00830189\AppData\Local\anaconda3\envs\flower_tutorial\lib\site-packages\ray\serialization.py", line 164, in _deserialize_pickle5_data
    obj = pickle.loads(in_band)
MemoryError
[2024-05-24 16:05:48,230][flwr][ERROR] - [36mray::launch_and_evaluate()[39m (pid=11220, ip=127.0.0.1)
  File "C:\Users\B00830189\AppData\Local\anaconda3\envs\flower_tutorial\lib\multiprocessing\queues.py", line 108, in get
    raise Empty
_queue.Empty

The above exception was the direct cause of the following exception:

[36mray::launch_and_evaluate()[39m (pid=11220, ip=127.0.0.1)
  File "python\ray\_raylet.pyx", line 633, in ray._raylet.execute_task
  File "python\ray\_raylet.pyx", line 674, in ray._raylet.execute_task
  File "python\ray\_raylet.pyx", line 640, in ray._raylet.execute_task
  File "python\ray\_raylet.pyx", line 644, in ray._raylet.execute_task
  File "C:\Users\B00830189\AppData\Local\anaconda3\envs\flower_tutorial\lib\site-packages\flwr\simulation\ray_transport\ray_client_proxy.py", line 160, in launch_and_evaluate
    return maybe_call_evaluate(
  File "C:\Users\B00830189\AppData\Local\anaconda3\envs\flower_tutorial\lib\site-packages\flwr\client\client.py", line 205, in maybe_call_evaluate
    return client.evaluate(evaluate_ins)
  File "C:\Users\B00830189\AppData\Local\anaconda3\envs\flower_tutorial\lib\site-packages\flwr\client\app.py", line 321, in _evaluate
    results = self.numpy_client.evaluate(parameters, ins.config)  # type: ignore
  File "C:\Users\B00830189\OneDrive - Ulster University\phd\Code\Demos\Flower\FlowerTutorial\client.py", line 55, in evaluate
    loss, accuracy = test(self.model, self.valloader, self.device)
  File "C:\Users\B00830189\OneDrive - Ulster University\phd\Code\Demos\Flower\FlowerTutorial\model.py", line 63, in test
    for data in testloader:
  File "C:\Users\B00830189\AppData\Local\anaconda3\envs\flower_tutorial\lib\site-packages\torch\utils\data\dataloader.py", line 628, in __next__
    data = self._next_data()
  File "C:\Users\B00830189\AppData\Local\anaconda3\envs\flower_tutorial\lib\site-packages\torch\utils\data\dataloader.py", line 1316, in _next_data
    idx, data = self._get_data()
  File "C:\Users\B00830189\AppData\Local\anaconda3\envs\flower_tutorial\lib\site-packages\torch\utils\data\dataloader.py", line 1282, in _get_data
    success, data = self._try_get_data()
  File "C:\Users\B00830189\AppData\Local\anaconda3\envs\flower_tutorial\lib\site-packages\torch\utils\data\dataloader.py", line 1133, in _try_get_data
    raise RuntimeError('DataLoader worker (pid(s) {}) exited unexpectedly'.format(pids_str)) from e
RuntimeError: DataLoader worker (pid(s) 3008) exited unexpectedly
[2024-05-24 16:05:48,231][flwr][ERROR] - [36mray::launch_and_evaluate()[39m (pid=8948, ip=127.0.0.1)
  File "C:\Users\B00830189\AppData\Local\anaconda3\envs\flower_tutorial\lib\multiprocessing\queues.py", line 108, in get
    raise Empty
_queue.Empty

The above exception was the direct cause of the following exception:

[36mray::launch_and_evaluate()[39m (pid=8948, ip=127.0.0.1)
  File "python\ray\_raylet.pyx", line 633, in ray._raylet.execute_task
  File "python\ray\_raylet.pyx", line 674, in ray._raylet.execute_task
  File "python\ray\_raylet.pyx", line 640, in ray._raylet.execute_task
  File "python\ray\_raylet.pyx", line 644, in ray._raylet.execute_task
  File "C:\Users\B00830189\AppData\Local\anaconda3\envs\flower_tutorial\lib\site-packages\flwr\simulation\ray_transport\ray_client_proxy.py", line 160, in launch_and_evaluate
    return maybe_call_evaluate(
  File "C:\Users\B00830189\AppData\Local\anaconda3\envs\flower_tutorial\lib\site-packages\flwr\client\client.py", line 205, in maybe_call_evaluate
    return client.evaluate(evaluate_ins)
  File "C:\Users\B00830189\AppData\Local\anaconda3\envs\flower_tutorial\lib\site-packages\flwr\client\app.py", line 321, in _evaluate
    results = self.numpy_client.evaluate(parameters, ins.config)  # type: ignore
  File "C:\Users\B00830189\OneDrive - Ulster University\phd\Code\Demos\Flower\FlowerTutorial\client.py", line 55, in evaluate
    loss, accuracy = test(self.model, self.valloader, self.device)
  File "C:\Users\B00830189\OneDrive - Ulster University\phd\Code\Demos\Flower\FlowerTutorial\model.py", line 63, in test
    for data in testloader:
  File "C:\Users\B00830189\AppData\Local\anaconda3\envs\flower_tutorial\lib\site-packages\torch\utils\data\dataloader.py", line 628, in __next__
    data = self._next_data()
  File "C:\Users\B00830189\AppData\Local\anaconda3\envs\flower_tutorial\lib\site-packages\torch\utils\data\dataloader.py", line 1316, in _next_data
    idx, data = self._get_data()
  File "C:\Users\B00830189\AppData\Local\anaconda3\envs\flower_tutorial\lib\site-packages\torch\utils\data\dataloader.py", line 1282, in _get_data
    success, data = self._try_get_data()
  File "C:\Users\B00830189\AppData\Local\anaconda3\envs\flower_tutorial\lib\site-packages\torch\utils\data\dataloader.py", line 1133, in _try_get_data
    raise RuntimeError('DataLoader worker (pid(s) {}) exited unexpectedly'.format(pids_str)) from e
RuntimeError: DataLoader worker (pid(s) 11436) exited unexpectedly
[2024-05-24 16:05:53,949][flwr][ERROR] - [36mray::launch_and_evaluate()[39m (pid=11220, ip=127.0.0.1)
  File "C:\Users\B00830189\AppData\Local\anaconda3\envs\flower_tutorial\lib\multiprocessing\queues.py", line 108, in get
    raise Empty
_queue.Empty

The above exception was the direct cause of the following exception:

[36mray::launch_and_evaluate()[39m (pid=11220, ip=127.0.0.1)
  File "python\ray\_raylet.pyx", line 633, in ray._raylet.execute_task
  File "python\ray\_raylet.pyx", line 674, in ray._raylet.execute_task
  File "python\ray\_raylet.pyx", line 640, in ray._raylet.execute_task
  File "python\ray\_raylet.pyx", line 644, in ray._raylet.execute_task
  File "C:\Users\B00830189\AppData\Local\anaconda3\envs\flower_tutorial\lib\site-packages\flwr\simulation\ray_transport\ray_client_proxy.py", line 160, in launch_and_evaluate
    return maybe_call_evaluate(
  File "C:\Users\B00830189\AppData\Local\anaconda3\envs\flower_tutorial\lib\site-packages\flwr\client\client.py", line 205, in maybe_call_evaluate
    return client.evaluate(evaluate_ins)
  File "C:\Users\B00830189\AppData\Local\anaconda3\envs\flower_tutorial\lib\site-packages\flwr\client\app.py", line 321, in _evaluate
    results = self.numpy_client.evaluate(parameters, ins.config)  # type: ignore
  File "C:\Users\B00830189\OneDrive - Ulster University\phd\Code\Demos\Flower\FlowerTutorial\client.py", line 55, in evaluate
    loss, accuracy = test(self.model, self.valloader, self.device)
  File "C:\Users\B00830189\OneDrive - Ulster University\phd\Code\Demos\Flower\FlowerTutorial\model.py", line 63, in test
    for data in testloader:
  File "C:\Users\B00830189\AppData\Local\anaconda3\envs\flower_tutorial\lib\site-packages\torch\utils\data\dataloader.py", line 628, in __next__
    data = self._next_data()
  File "C:\Users\B00830189\AppData\Local\anaconda3\envs\flower_tutorial\lib\site-packages\torch\utils\data\dataloader.py", line 1316, in _next_data
    idx, data = self._get_data()
  File "C:\Users\B00830189\AppData\Local\anaconda3\envs\flower_tutorial\lib\site-packages\torch\utils\data\dataloader.py", line 1282, in _get_data
    success, data = self._try_get_data()
  File "C:\Users\B00830189\AppData\Local\anaconda3\envs\flower_tutorial\lib\site-packages\torch\utils\data\dataloader.py", line 1133, in _try_get_data
    raise RuntimeError('DataLoader worker (pid(s) {}) exited unexpectedly'.format(pids_str)) from e
RuntimeError: DataLoader worker (pid(s) 17564, 4396) exited unexpectedly
[2024-05-24 16:05:53,958][flwr][ERROR] - [36mray::launch_and_evaluate()[39m (pid=11220, ip=127.0.0.1)
  File "python\ray\_raylet.pyx", line 602, in ray._raylet.execute_task
  File "python\ray\_raylet.pyx", line 624, in ray._raylet.execute_task
  File "python\ray\_raylet.pyx", line 456, in ray._raylet.raise_if_dependency_failed
ray.exceptions.RaySystemError: System error: 
traceback: Traceback (most recent call last):
  File "C:\Users\B00830189\AppData\Local\anaconda3\envs\flower_tutorial\lib\site-packages\ray\serialization.py", line 309, in deserialize_objects
    obj = self._deserialize_object(data, metadata, object_ref)
  File "C:\Users\B00830189\AppData\Local\anaconda3\envs\flower_tutorial\lib\site-packages\ray\serialization.py", line 215, in _deserialize_object
    return self._deserialize_msgpack_data(data, metadata_fields)
  File "C:\Users\B00830189\AppData\Local\anaconda3\envs\flower_tutorial\lib\site-packages\ray\serialization.py", line 174, in _deserialize_msgpack_data
    python_objects = self._deserialize_pickle5_data(pickle5_data)
  File "C:\Users\B00830189\AppData\Local\anaconda3\envs\flower_tutorial\lib\site-packages\ray\serialization.py", line 164, in _deserialize_pickle5_data
    obj = pickle.loads(in_band)
MemoryError
[2024-05-24 16:05:53,973][flwr][ERROR] - [36mray::launch_and_evaluate()[39m (pid=11220, ip=127.0.0.1)
  File "python\ray\_raylet.pyx", line 602, in ray._raylet.execute_task
  File "python\ray\_raylet.pyx", line 624, in ray._raylet.execute_task
  File "python\ray\_raylet.pyx", line 456, in ray._raylet.raise_if_dependency_failed
ray.exceptions.RaySystemError: System error: 
traceback: Traceback (most recent call last):
  File "C:\Users\B00830189\AppData\Local\anaconda3\envs\flower_tutorial\lib\site-packages\ray\serialization.py", line 309, in deserialize_objects
    obj = self._deserialize_object(data, metadata, object_ref)
  File "C:\Users\B00830189\AppData\Local\anaconda3\envs\flower_tutorial\lib\site-packages\ray\serialization.py", line 215, in _deserialize_object
    return self._deserialize_msgpack_data(data, metadata_fields)
  File "C:\Users\B00830189\AppData\Local\anaconda3\envs\flower_tutorial\lib\site-packages\ray\serialization.py", line 174, in _deserialize_msgpack_data
    python_objects = self._deserialize_pickle5_data(pickle5_data)
  File "C:\Users\B00830189\AppData\Local\anaconda3\envs\flower_tutorial\lib\site-packages\ray\serialization.py", line 164, in _deserialize_pickle5_data
    obj = pickle.loads(in_band)
MemoryError
[2024-05-24 16:05:54,047][flwr][ERROR] - [36mray::launch_and_evaluate()[39m (pid=11220, ip=127.0.0.1)
  File "python\ray\_raylet.pyx", line 602, in ray._raylet.execute_task
  File "python\ray\_raylet.pyx", line 624, in ray._raylet.execute_task
  File "python\ray\_raylet.pyx", line 456, in ray._raylet.raise_if_dependency_failed
ray.exceptions.RaySystemError: System error: 
traceback: Traceback (most recent call last):
  File "C:\Users\B00830189\AppData\Local\anaconda3\envs\flower_tutorial\lib\site-packages\ray\serialization.py", line 309, in deserialize_objects
    obj = self._deserialize_object(data, metadata, object_ref)
  File "C:\Users\B00830189\AppData\Local\anaconda3\envs\flower_tutorial\lib\site-packages\ray\serialization.py", line 215, in _deserialize_object
    return self._deserialize_msgpack_data(data, metadata_fields)
  File "C:\Users\B00830189\AppData\Local\anaconda3\envs\flower_tutorial\lib\site-packages\ray\serialization.py", line 174, in _deserialize_msgpack_data
    python_objects = self._deserialize_pickle5_data(pickle5_data)
  File "C:\Users\B00830189\AppData\Local\anaconda3\envs\flower_tutorial\lib\site-packages\ray\serialization.py", line 164, in _deserialize_pickle5_data
    obj = pickle.loads(in_band)
MemoryError
[2024-05-24 16:05:54,120][flwr][ERROR] - [36mray::launch_and_evaluate()[39m (pid=11220, ip=127.0.0.1)
  File "python\ray\_raylet.pyx", line 602, in ray._raylet.execute_task
  File "python\ray\_raylet.pyx", line 624, in ray._raylet.execute_task
  File "python\ray\_raylet.pyx", line 456, in ray._raylet.raise_if_dependency_failed
ray.exceptions.RaySystemError: System error: 
traceback: Traceback (most recent call last):
  File "C:\Users\B00830189\AppData\Local\anaconda3\envs\flower_tutorial\lib\site-packages\ray\serialization.py", line 309, in deserialize_objects
    obj = self._deserialize_object(data, metadata, object_ref)
  File "C:\Users\B00830189\AppData\Local\anaconda3\envs\flower_tutorial\lib\site-packages\ray\serialization.py", line 215, in _deserialize_object
    return self._deserialize_msgpack_data(data, metadata_fields)
  File "C:\Users\B00830189\AppData\Local\anaconda3\envs\flower_tutorial\lib\site-packages\ray\serialization.py", line 174, in _deserialize_msgpack_data
    python_objects = self._deserialize_pickle5_data(pickle5_data)
  File "C:\Users\B00830189\AppData\Local\anaconda3\envs\flower_tutorial\lib\site-packages\ray\serialization.py", line 164, in _deserialize_pickle5_data
    obj = pickle.loads(in_band)
MemoryError
[2024-05-24 16:05:56,145][flwr][ERROR] - [36mray::launch_and_evaluate()[39m (pid=7840, ip=127.0.0.1)
  File "C:\Users\B00830189\AppData\Local\anaconda3\envs\flower_tutorial\lib\multiprocessing\queues.py", line 108, in get
    raise Empty
_queue.Empty

The above exception was the direct cause of the following exception:

[36mray::launch_and_evaluate()[39m (pid=7840, ip=127.0.0.1)
  File "python\ray\_raylet.pyx", line 633, in ray._raylet.execute_task
  File "python\ray\_raylet.pyx", line 674, in ray._raylet.execute_task
  File "python\ray\_raylet.pyx", line 640, in ray._raylet.execute_task
  File "python\ray\_raylet.pyx", line 644, in ray._raylet.execute_task
  File "C:\Users\B00830189\AppData\Local\anaconda3\envs\flower_tutorial\lib\site-packages\flwr\simulation\ray_transport\ray_client_proxy.py", line 160, in launch_and_evaluate
    return maybe_call_evaluate(
  File "C:\Users\B00830189\AppData\Local\anaconda3\envs\flower_tutorial\lib\site-packages\flwr\client\client.py", line 205, in maybe_call_evaluate
    return client.evaluate(evaluate_ins)
  File "C:\Users\B00830189\AppData\Local\anaconda3\envs\flower_tutorial\lib\site-packages\flwr\client\app.py", line 321, in _evaluate
    results = self.numpy_client.evaluate(parameters, ins.config)  # type: ignore
  File "C:\Users\B00830189\OneDrive - Ulster University\phd\Code\Demos\Flower\FlowerTutorial\client.py", line 55, in evaluate
    loss, accuracy = test(self.model, self.valloader, self.device)
  File "C:\Users\B00830189\OneDrive - Ulster University\phd\Code\Demos\Flower\FlowerTutorial\model.py", line 63, in test
    for data in testloader:
  File "C:\Users\B00830189\AppData\Local\anaconda3\envs\flower_tutorial\lib\site-packages\torch\utils\data\dataloader.py", line 628, in __next__
    data = self._next_data()
  File "C:\Users\B00830189\AppData\Local\anaconda3\envs\flower_tutorial\lib\site-packages\torch\utils\data\dataloader.py", line 1316, in _next_data
    idx, data = self._get_data()
  File "C:\Users\B00830189\AppData\Local\anaconda3\envs\flower_tutorial\lib\site-packages\torch\utils\data\dataloader.py", line 1282, in _get_data
    success, data = self._try_get_data()
  File "C:\Users\B00830189\AppData\Local\anaconda3\envs\flower_tutorial\lib\site-packages\torch\utils\data\dataloader.py", line 1133, in _try_get_data
    raise RuntimeError('DataLoader worker (pid(s) {}) exited unexpectedly'.format(pids_str)) from e
RuntimeError: DataLoader worker (pid(s) 2640, 14636) exited unexpectedly
[2024-05-24 16:05:58,636][flwr][ERROR] - [36mray::launch_and_evaluate()[39m (pid=8948, ip=127.0.0.1)
  File "C:\Users\B00830189\AppData\Local\anaconda3\envs\flower_tutorial\lib\multiprocessing\queues.py", line 108, in get
    raise Empty
_queue.Empty

The above exception was the direct cause of the following exception:

[36mray::launch_and_evaluate()[39m (pid=8948, ip=127.0.0.1)
  File "python\ray\_raylet.pyx", line 633, in ray._raylet.execute_task
  File "python\ray\_raylet.pyx", line 674, in ray._raylet.execute_task
  File "python\ray\_raylet.pyx", line 640, in ray._raylet.execute_task
  File "python\ray\_raylet.pyx", line 644, in ray._raylet.execute_task
  File "C:\Users\B00830189\AppData\Local\anaconda3\envs\flower_tutorial\lib\site-packages\flwr\simulation\ray_transport\ray_client_proxy.py", line 160, in launch_and_evaluate
    return maybe_call_evaluate(
  File "C:\Users\B00830189\AppData\Local\anaconda3\envs\flower_tutorial\lib\site-packages\flwr\client\client.py", line 205, in maybe_call_evaluate
    return client.evaluate(evaluate_ins)
  File "C:\Users\B00830189\AppData\Local\anaconda3\envs\flower_tutorial\lib\site-packages\flwr\client\app.py", line 321, in _evaluate
    results = self.numpy_client.evaluate(parameters, ins.config)  # type: ignore
  File "C:\Users\B00830189\OneDrive - Ulster University\phd\Code\Demos\Flower\FlowerTutorial\client.py", line 55, in evaluate
    loss, accuracy = test(self.model, self.valloader, self.device)
  File "C:\Users\B00830189\OneDrive - Ulster University\phd\Code\Demos\Flower\FlowerTutorial\model.py", line 63, in test
    for data in testloader:
  File "C:\Users\B00830189\AppData\Local\anaconda3\envs\flower_tutorial\lib\site-packages\torch\utils\data\dataloader.py", line 628, in __next__
    data = self._next_data()
  File "C:\Users\B00830189\AppData\Local\anaconda3\envs\flower_tutorial\lib\site-packages\torch\utils\data\dataloader.py", line 1316, in _next_data
    idx, data = self._get_data()
  File "C:\Users\B00830189\AppData\Local\anaconda3\envs\flower_tutorial\lib\site-packages\torch\utils\data\dataloader.py", line 1282, in _get_data
    success, data = self._try_get_data()
  File "C:\Users\B00830189\AppData\Local\anaconda3\envs\flower_tutorial\lib\site-packages\torch\utils\data\dataloader.py", line 1133, in _try_get_data
    raise RuntimeError('DataLoader worker (pid(s) {}) exited unexpectedly'.format(pids_str)) from e
RuntimeError: DataLoader worker (pid(s) 15776) exited unexpectedly
[2024-05-24 16:05:58,640][flwr][DEBUG] - evaluate_round 1 received 0 results and 25 failures
[2024-05-24 16:05:58,653][flwr][DEBUG] - fit_round 2: strategy sampled 10 clients (out of 100)
[2024-05-24 16:06:04,766][flwr][ERROR] - [36mray::launch_and_fit()[39m (pid=7840, ip=127.0.0.1)
  File "C:\Users\B00830189\AppData\Local\anaconda3\envs\flower_tutorial\lib\multiprocessing\queues.py", line 108, in get
    raise Empty
_queue.Empty

The above exception was the direct cause of the following exception:

[36mray::launch_and_fit()[39m (pid=7840, ip=127.0.0.1)
  File "python\ray\_raylet.pyx", line 633, in ray._raylet.execute_task
  File "python\ray\_raylet.pyx", line 674, in ray._raylet.execute_task
  File "python\ray\_raylet.pyx", line 640, in ray._raylet.execute_task
  File "python\ray\_raylet.pyx", line 644, in ray._raylet.execute_task
  File "C:\Users\B00830189\AppData\Local\anaconda3\envs\flower_tutorial\lib\site-packages\flwr\simulation\ray_transport\ray_client_proxy.py", line 148, in launch_and_fit
    return maybe_call_fit(
  File "C:\Users\B00830189\AppData\Local\anaconda3\envs\flower_tutorial\lib\site-packages\flwr\client\client.py", line 184, in maybe_call_fit
    return client.fit(fit_ins)
  File "C:\Users\B00830189\AppData\Local\anaconda3\envs\flower_tutorial\lib\site-packages\flwr\client\app.py", line 297, in _fit
    results = self.numpy_client.fit(parameters, ins.config)  # type: ignore
  File "C:\Users\B00830189\OneDrive - Ulster University\phd\Code\Demos\Flower\FlowerTutorial\client.py", line 48, in fit
    train(self.model, self.trainload, optim, epochs, self.device) # Model no longer has weights sent my the server
  File "C:\Users\B00830189\OneDrive - Ulster University\phd\Code\Demos\Flower\FlowerTutorial\model.py", line 45, in train
    for images, labels in trainloader:
  File "C:\Users\B00830189\AppData\Local\anaconda3\envs\flower_tutorial\lib\site-packages\torch\utils\data\dataloader.py", line 628, in __next__
    data = self._next_data()
  File "C:\Users\B00830189\AppData\Local\anaconda3\envs\flower_tutorial\lib\site-packages\torch\utils\data\dataloader.py", line 1316, in _next_data
    idx, data = self._get_data()
  File "C:\Users\B00830189\AppData\Local\anaconda3\envs\flower_tutorial\lib\site-packages\torch\utils\data\dataloader.py", line 1282, in _get_data
    success, data = self._try_get_data()
  File "C:\Users\B00830189\AppData\Local\anaconda3\envs\flower_tutorial\lib\site-packages\torch\utils\data\dataloader.py", line 1133, in _try_get_data
    raise RuntimeError('DataLoader worker (pid(s) {}) exited unexpectedly'.format(pids_str)) from e
RuntimeError: DataLoader worker (pid(s) 10860, 2088) exited unexpectedly
[2024-05-24 16:06:04,930][flwr][ERROR] - [36mray::launch_and_fit()[39m (pid=11220, ip=127.0.0.1)
  File "C:\Users\B00830189\AppData\Local\anaconda3\envs\flower_tutorial\lib\multiprocessing\queues.py", line 108, in get
    raise Empty
_queue.Empty

The above exception was the direct cause of the following exception:

[36mray::launch_and_fit()[39m (pid=11220, ip=127.0.0.1)
  File "python\ray\_raylet.pyx", line 633, in ray._raylet.execute_task
  File "python\ray\_raylet.pyx", line 674, in ray._raylet.execute_task
  File "python\ray\_raylet.pyx", line 640, in ray._raylet.execute_task
  File "python\ray\_raylet.pyx", line 644, in ray._raylet.execute_task
  File "C:\Users\B00830189\AppData\Local\anaconda3\envs\flower_tutorial\lib\site-packages\flwr\simulation\ray_transport\ray_client_proxy.py", line 148, in launch_and_fit
    return maybe_call_fit(
  File "C:\Users\B00830189\AppData\Local\anaconda3\envs\flower_tutorial\lib\site-packages\flwr\client\client.py", line 184, in maybe_call_fit
    return client.fit(fit_ins)
  File "C:\Users\B00830189\AppData\Local\anaconda3\envs\flower_tutorial\lib\site-packages\flwr\client\app.py", line 297, in _fit
    results = self.numpy_client.fit(parameters, ins.config)  # type: ignore
  File "C:\Users\B00830189\OneDrive - Ulster University\phd\Code\Demos\Flower\FlowerTutorial\client.py", line 48, in fit
    train(self.model, self.trainload, optim, epochs, self.device) # Model no longer has weights sent my the server
  File "C:\Users\B00830189\OneDrive - Ulster University\phd\Code\Demos\Flower\FlowerTutorial\model.py", line 45, in train
    for images, labels in trainloader:
  File "C:\Users\B00830189\AppData\Local\anaconda3\envs\flower_tutorial\lib\site-packages\torch\utils\data\dataloader.py", line 628, in __next__
    data = self._next_data()
  File "C:\Users\B00830189\AppData\Local\anaconda3\envs\flower_tutorial\lib\site-packages\torch\utils\data\dataloader.py", line 1316, in _next_data
    idx, data = self._get_data()
  File "C:\Users\B00830189\AppData\Local\anaconda3\envs\flower_tutorial\lib\site-packages\torch\utils\data\dataloader.py", line 1282, in _get_data
    success, data = self._try_get_data()
  File "C:\Users\B00830189\AppData\Local\anaconda3\envs\flower_tutorial\lib\site-packages\torch\utils\data\dataloader.py", line 1133, in _try_get_data
    raise RuntimeError('DataLoader worker (pid(s) {}) exited unexpectedly'.format(pids_str)) from e
RuntimeError: DataLoader worker (pid(s) 15036, 584) exited unexpectedly
[2024-05-24 16:06:09,950][flwr][ERROR] - [36mray::launch_and_fit()[39m (pid=8948, ip=127.0.0.1)
  File "C:\Users\B00830189\AppData\Local\anaconda3\envs\flower_tutorial\lib\multiprocessing\queues.py", line 108, in get
    raise Empty
_queue.Empty

The above exception was the direct cause of the following exception:

[36mray::launch_and_fit()[39m (pid=8948, ip=127.0.0.1)
  File "python\ray\_raylet.pyx", line 633, in ray._raylet.execute_task
  File "python\ray\_raylet.pyx", line 674, in ray._raylet.execute_task
  File "python\ray\_raylet.pyx", line 640, in ray._raylet.execute_task
  File "python\ray\_raylet.pyx", line 644, in ray._raylet.execute_task
  File "C:\Users\B00830189\AppData\Local\anaconda3\envs\flower_tutorial\lib\site-packages\flwr\simulation\ray_transport\ray_client_proxy.py", line 148, in launch_and_fit
    return maybe_call_fit(
  File "C:\Users\B00830189\AppData\Local\anaconda3\envs\flower_tutorial\lib\site-packages\flwr\client\client.py", line 184, in maybe_call_fit
    return client.fit(fit_ins)
  File "C:\Users\B00830189\AppData\Local\anaconda3\envs\flower_tutorial\lib\site-packages\flwr\client\app.py", line 297, in _fit
    results = self.numpy_client.fit(parameters, ins.config)  # type: ignore
  File "C:\Users\B00830189\OneDrive - Ulster University\phd\Code\Demos\Flower\FlowerTutorial\client.py", line 48, in fit
    train(self.model, self.trainload, optim, epochs, self.device) # Model no longer has weights sent my the server
  File "C:\Users\B00830189\OneDrive - Ulster University\phd\Code\Demos\Flower\FlowerTutorial\model.py", line 45, in train
    for images, labels in trainloader:
  File "C:\Users\B00830189\AppData\Local\anaconda3\envs\flower_tutorial\lib\site-packages\torch\utils\data\dataloader.py", line 628, in __next__
    data = self._next_data()
  File "C:\Users\B00830189\AppData\Local\anaconda3\envs\flower_tutorial\lib\site-packages\torch\utils\data\dataloader.py", line 1316, in _next_data
    idx, data = self._get_data()
  File "C:\Users\B00830189\AppData\Local\anaconda3\envs\flower_tutorial\lib\site-packages\torch\utils\data\dataloader.py", line 1282, in _get_data
    success, data = self._try_get_data()
  File "C:\Users\B00830189\AppData\Local\anaconda3\envs\flower_tutorial\lib\site-packages\torch\utils\data\dataloader.py", line 1133, in _try_get_data
    raise RuntimeError('DataLoader worker (pid(s) {}) exited unexpectedly'.format(pids_str)) from e
RuntimeError: DataLoader worker (pid(s) 15476) exited unexpectedly
[2024-05-24 16:06:10,187][flwr][ERROR] - [36mray::launch_and_fit()[39m (pid=7840, ip=127.0.0.1)
  File "C:\Users\B00830189\AppData\Local\anaconda3\envs\flower_tutorial\lib\multiprocessing\queues.py", line 108, in get
    raise Empty
_queue.Empty

The above exception was the direct cause of the following exception:

[36mray::launch_and_fit()[39m (pid=7840, ip=127.0.0.1)
  File "python\ray\_raylet.pyx", line 633, in ray._raylet.execute_task
  File "python\ray\_raylet.pyx", line 674, in ray._raylet.execute_task
  File "python\ray\_raylet.pyx", line 640, in ray._raylet.execute_task
  File "python\ray\_raylet.pyx", line 644, in ray._raylet.execute_task
  File "C:\Users\B00830189\AppData\Local\anaconda3\envs\flower_tutorial\lib\site-packages\flwr\simulation\ray_transport\ray_client_proxy.py", line 148, in launch_and_fit
    return maybe_call_fit(
  File "C:\Users\B00830189\AppData\Local\anaconda3\envs\flower_tutorial\lib\site-packages\flwr\client\client.py", line 184, in maybe_call_fit
    return client.fit(fit_ins)
  File "C:\Users\B00830189\AppData\Local\anaconda3\envs\flower_tutorial\lib\site-packages\flwr\client\app.py", line 297, in _fit
    results = self.numpy_client.fit(parameters, ins.config)  # type: ignore
  File "C:\Users\B00830189\OneDrive - Ulster University\phd\Code\Demos\Flower\FlowerTutorial\client.py", line 48, in fit
    train(self.model, self.trainload, optim, epochs, self.device) # Model no longer has weights sent my the server
  File "C:\Users\B00830189\OneDrive - Ulster University\phd\Code\Demos\Flower\FlowerTutorial\model.py", line 45, in train
    for images, labels in trainloader:
  File "C:\Users\B00830189\AppData\Local\anaconda3\envs\flower_tutorial\lib\site-packages\torch\utils\data\dataloader.py", line 628, in __next__
    data = self._next_data()
  File "C:\Users\B00830189\AppData\Local\anaconda3\envs\flower_tutorial\lib\site-packages\torch\utils\data\dataloader.py", line 1316, in _next_data
    idx, data = self._get_data()
  File "C:\Users\B00830189\AppData\Local\anaconda3\envs\flower_tutorial\lib\site-packages\torch\utils\data\dataloader.py", line 1282, in _get_data
    success, data = self._try_get_data()
  File "C:\Users\B00830189\AppData\Local\anaconda3\envs\flower_tutorial\lib\site-packages\torch\utils\data\dataloader.py", line 1133, in _try_get_data
    raise RuntimeError('DataLoader worker (pid(s) {}) exited unexpectedly'.format(pids_str)) from e
RuntimeError: DataLoader worker (pid(s) 18556, 16236) exited unexpectedly
[2024-05-24 16:06:10,382][flwr][ERROR] - [36mray::launch_and_fit()[39m (pid=11220, ip=127.0.0.1)
  File "C:\Users\B00830189\AppData\Local\anaconda3\envs\flower_tutorial\lib\multiprocessing\queues.py", line 108, in get
    raise Empty
_queue.Empty

The above exception was the direct cause of the following exception:

[36mray::launch_and_fit()[39m (pid=11220, ip=127.0.0.1)
  File "python\ray\_raylet.pyx", line 633, in ray._raylet.execute_task
  File "python\ray\_raylet.pyx", line 674, in ray._raylet.execute_task
  File "python\ray\_raylet.pyx", line 640, in ray._raylet.execute_task
  File "python\ray\_raylet.pyx", line 644, in ray._raylet.execute_task
  File "C:\Users\B00830189\AppData\Local\anaconda3\envs\flower_tutorial\lib\site-packages\flwr\simulation\ray_transport\ray_client_proxy.py", line 148, in launch_and_fit
    return maybe_call_fit(
  File "C:\Users\B00830189\AppData\Local\anaconda3\envs\flower_tutorial\lib\site-packages\flwr\client\client.py", line 184, in maybe_call_fit
    return client.fit(fit_ins)
  File "C:\Users\B00830189\AppData\Local\anaconda3\envs\flower_tutorial\lib\site-packages\flwr\client\app.py", line 297, in _fit
    results = self.numpy_client.fit(parameters, ins.config)  # type: ignore
  File "C:\Users\B00830189\OneDrive - Ulster University\phd\Code\Demos\Flower\FlowerTutorial\client.py", line 48, in fit
    train(self.model, self.trainload, optim, epochs, self.device) # Model no longer has weights sent my the server
  File "C:\Users\B00830189\OneDrive - Ulster University\phd\Code\Demos\Flower\FlowerTutorial\model.py", line 45, in train
    for images, labels in trainloader:
  File "C:\Users\B00830189\AppData\Local\anaconda3\envs\flower_tutorial\lib\site-packages\torch\utils\data\dataloader.py", line 628, in __next__
    data = self._next_data()
  File "C:\Users\B00830189\AppData\Local\anaconda3\envs\flower_tutorial\lib\site-packages\torch\utils\data\dataloader.py", line 1316, in _next_data
    idx, data = self._get_data()
  File "C:\Users\B00830189\AppData\Local\anaconda3\envs\flower_tutorial\lib\site-packages\torch\utils\data\dataloader.py", line 1282, in _get_data
    success, data = self._try_get_data()
  File "C:\Users\B00830189\AppData\Local\anaconda3\envs\flower_tutorial\lib\site-packages\torch\utils\data\dataloader.py", line 1133, in _try_get_data
    raise RuntimeError('DataLoader worker (pid(s) {}) exited unexpectedly'.format(pids_str)) from e
RuntimeError: DataLoader worker (pid(s) 3556, 16420) exited unexpectedly
[2024-05-24 16:06:15,856][flwr][ERROR] - [36mray::launch_and_fit()[39m (pid=7840, ip=127.0.0.1)
  File "C:\Users\B00830189\AppData\Local\anaconda3\envs\flower_tutorial\lib\multiprocessing\queues.py", line 108, in get
    raise Empty
_queue.Empty

The above exception was the direct cause of the following exception:

[36mray::launch_and_fit()[39m (pid=7840, ip=127.0.0.1)
  File "python\ray\_raylet.pyx", line 633, in ray._raylet.execute_task
  File "python\ray\_raylet.pyx", line 674, in ray._raylet.execute_task
  File "python\ray\_raylet.pyx", line 640, in ray._raylet.execute_task
  File "python\ray\_raylet.pyx", line 644, in ray._raylet.execute_task
  File "C:\Users\B00830189\AppData\Local\anaconda3\envs\flower_tutorial\lib\site-packages\flwr\simulation\ray_transport\ray_client_proxy.py", line 148, in launch_and_fit
    return maybe_call_fit(
  File "C:\Users\B00830189\AppData\Local\anaconda3\envs\flower_tutorial\lib\site-packages\flwr\client\client.py", line 184, in maybe_call_fit
    return client.fit(fit_ins)
  File "C:\Users\B00830189\AppData\Local\anaconda3\envs\flower_tutorial\lib\site-packages\flwr\client\app.py", line 297, in _fit
    results = self.numpy_client.fit(parameters, ins.config)  # type: ignore
  File "C:\Users\B00830189\OneDrive - Ulster University\phd\Code\Demos\Flower\FlowerTutorial\client.py", line 48, in fit
    train(self.model, self.trainload, optim, epochs, self.device) # Model no longer has weights sent my the server
  File "C:\Users\B00830189\OneDrive - Ulster University\phd\Code\Demos\Flower\FlowerTutorial\model.py", line 45, in train
    for images, labels in trainloader:
  File "C:\Users\B00830189\AppData\Local\anaconda3\envs\flower_tutorial\lib\site-packages\torch\utils\data\dataloader.py", line 628, in __next__
    data = self._next_data()
  File "C:\Users\B00830189\AppData\Local\anaconda3\envs\flower_tutorial\lib\site-packages\torch\utils\data\dataloader.py", line 1316, in _next_data
    idx, data = self._get_data()
  File "C:\Users\B00830189\AppData\Local\anaconda3\envs\flower_tutorial\lib\site-packages\torch\utils\data\dataloader.py", line 1282, in _get_data
    success, data = self._try_get_data()
  File "C:\Users\B00830189\AppData\Local\anaconda3\envs\flower_tutorial\lib\site-packages\torch\utils\data\dataloader.py", line 1133, in _try_get_data
    raise RuntimeError('DataLoader worker (pid(s) {}) exited unexpectedly'.format(pids_str)) from e
RuntimeError: DataLoader worker (pid(s) 10676, 16072) exited unexpectedly
[2024-05-24 16:06:16,029][flwr][ERROR] - [36mray::launch_and_fit()[39m (pid=11220, ip=127.0.0.1)
  File "C:\Users\B00830189\AppData\Local\anaconda3\envs\flower_tutorial\lib\multiprocessing\queues.py", line 108, in get
    raise Empty
_queue.Empty

The above exception was the direct cause of the following exception:

[36mray::launch_and_fit()[39m (pid=11220, ip=127.0.0.1)
  File "python\ray\_raylet.pyx", line 633, in ray._raylet.execute_task
  File "python\ray\_raylet.pyx", line 674, in ray._raylet.execute_task
  File "python\ray\_raylet.pyx", line 640, in ray._raylet.execute_task
  File "python\ray\_raylet.pyx", line 644, in ray._raylet.execute_task
  File "C:\Users\B00830189\AppData\Local\anaconda3\envs\flower_tutorial\lib\site-packages\flwr\simulation\ray_transport\ray_client_proxy.py", line 148, in launch_and_fit
    return maybe_call_fit(
  File "C:\Users\B00830189\AppData\Local\anaconda3\envs\flower_tutorial\lib\site-packages\flwr\client\client.py", line 184, in maybe_call_fit
    return client.fit(fit_ins)
  File "C:\Users\B00830189\AppData\Local\anaconda3\envs\flower_tutorial\lib\site-packages\flwr\client\app.py", line 297, in _fit
    results = self.numpy_client.fit(parameters, ins.config)  # type: ignore
  File "C:\Users\B00830189\OneDrive - Ulster University\phd\Code\Demos\Flower\FlowerTutorial\client.py", line 48, in fit
    train(self.model, self.trainload, optim, epochs, self.device) # Model no longer has weights sent my the server
  File "C:\Users\B00830189\OneDrive - Ulster University\phd\Code\Demos\Flower\FlowerTutorial\model.py", line 45, in train
    for images, labels in trainloader:
  File "C:\Users\B00830189\AppData\Local\anaconda3\envs\flower_tutorial\lib\site-packages\torch\utils\data\dataloader.py", line 628, in __next__
    data = self._next_data()
  File "C:\Users\B00830189\AppData\Local\anaconda3\envs\flower_tutorial\lib\site-packages\torch\utils\data\dataloader.py", line 1316, in _next_data
    idx, data = self._get_data()
  File "C:\Users\B00830189\AppData\Local\anaconda3\envs\flower_tutorial\lib\site-packages\torch\utils\data\dataloader.py", line 1282, in _get_data
    success, data = self._try_get_data()
  File "C:\Users\B00830189\AppData\Local\anaconda3\envs\flower_tutorial\lib\site-packages\torch\utils\data\dataloader.py", line 1133, in _try_get_data
    raise RuntimeError('DataLoader worker (pid(s) {}) exited unexpectedly'.format(pids_str)) from e
RuntimeError: DataLoader worker (pid(s) 6672, 15848) exited unexpectedly
[2024-05-24 16:06:17,091][flwr][ERROR] - [36mray::launch_and_fit()[39m (pid=8948, ip=127.0.0.1)
  File "C:\Users\B00830189\AppData\Local\anaconda3\envs\flower_tutorial\lib\multiprocessing\queues.py", line 108, in get
    raise Empty
_queue.Empty

The above exception was the direct cause of the following exception:

[36mray::launch_and_fit()[39m (pid=8948, ip=127.0.0.1)
  File "python\ray\_raylet.pyx", line 633, in ray._raylet.execute_task
  File "python\ray\_raylet.pyx", line 674, in ray._raylet.execute_task
  File "python\ray\_raylet.pyx", line 640, in ray._raylet.execute_task
  File "python\ray\_raylet.pyx", line 644, in ray._raylet.execute_task
  File "C:\Users\B00830189\AppData\Local\anaconda3\envs\flower_tutorial\lib\site-packages\flwr\simulation\ray_transport\ray_client_proxy.py", line 148, in launch_and_fit
    return maybe_call_fit(
  File "C:\Users\B00830189\AppData\Local\anaconda3\envs\flower_tutorial\lib\site-packages\flwr\client\client.py", line 184, in maybe_call_fit
    return client.fit(fit_ins)
  File "C:\Users\B00830189\AppData\Local\anaconda3\envs\flower_tutorial\lib\site-packages\flwr\client\app.py", line 297, in _fit
    results = self.numpy_client.fit(parameters, ins.config)  # type: ignore
  File "C:\Users\B00830189\OneDrive - Ulster University\phd\Code\Demos\Flower\FlowerTutorial\client.py", line 48, in fit
    train(self.model, self.trainload, optim, epochs, self.device) # Model no longer has weights sent my the server
  File "C:\Users\B00830189\OneDrive - Ulster University\phd\Code\Demos\Flower\FlowerTutorial\model.py", line 45, in train
    for images, labels in trainloader:
  File "C:\Users\B00830189\AppData\Local\anaconda3\envs\flower_tutorial\lib\site-packages\torch\utils\data\dataloader.py", line 628, in __next__
    data = self._next_data()
  File "C:\Users\B00830189\AppData\Local\anaconda3\envs\flower_tutorial\lib\site-packages\torch\utils\data\dataloader.py", line 1316, in _next_data
    idx, data = self._get_data()
  File "C:\Users\B00830189\AppData\Local\anaconda3\envs\flower_tutorial\lib\site-packages\torch\utils\data\dataloader.py", line 1282, in _get_data
    success, data = self._try_get_data()
  File "C:\Users\B00830189\AppData\Local\anaconda3\envs\flower_tutorial\lib\site-packages\torch\utils\data\dataloader.py", line 1133, in _try_get_data
    raise RuntimeError('DataLoader worker (pid(s) {}) exited unexpectedly'.format(pids_str)) from e
RuntimeError: DataLoader worker (pid(s) 12496) exited unexpectedly
[2024-05-24 16:06:21,567][flwr][ERROR] - [36mray::launch_and_fit()[39m (pid=11220, ip=127.0.0.1)
  File "C:\Users\B00830189\AppData\Local\anaconda3\envs\flower_tutorial\lib\multiprocessing\queues.py", line 108, in get
    raise Empty
_queue.Empty

The above exception was the direct cause of the following exception:

[36mray::launch_and_fit()[39m (pid=11220, ip=127.0.0.1)
  File "python\ray\_raylet.pyx", line 633, in ray._raylet.execute_task
  File "python\ray\_raylet.pyx", line 674, in ray._raylet.execute_task
  File "python\ray\_raylet.pyx", line 640, in ray._raylet.execute_task
  File "python\ray\_raylet.pyx", line 644, in ray._raylet.execute_task
  File "C:\Users\B00830189\AppData\Local\anaconda3\envs\flower_tutorial\lib\site-packages\flwr\simulation\ray_transport\ray_client_proxy.py", line 148, in launch_and_fit
    return maybe_call_fit(
  File "C:\Users\B00830189\AppData\Local\anaconda3\envs\flower_tutorial\lib\site-packages\flwr\client\client.py", line 184, in maybe_call_fit
    return client.fit(fit_ins)
  File "C:\Users\B00830189\AppData\Local\anaconda3\envs\flower_tutorial\lib\site-packages\flwr\client\app.py", line 297, in _fit
    results = self.numpy_client.fit(parameters, ins.config)  # type: ignore
  File "C:\Users\B00830189\OneDrive - Ulster University\phd\Code\Demos\Flower\FlowerTutorial\client.py", line 48, in fit
    train(self.model, self.trainload, optim, epochs, self.device) # Model no longer has weights sent my the server
  File "C:\Users\B00830189\OneDrive - Ulster University\phd\Code\Demos\Flower\FlowerTutorial\model.py", line 45, in train
    for images, labels in trainloader:
  File "C:\Users\B00830189\AppData\Local\anaconda3\envs\flower_tutorial\lib\site-packages\torch\utils\data\dataloader.py", line 628, in __next__
    data = self._next_data()
  File "C:\Users\B00830189\AppData\Local\anaconda3\envs\flower_tutorial\lib\site-packages\torch\utils\data\dataloader.py", line 1316, in _next_data
    idx, data = self._get_data()
  File "C:\Users\B00830189\AppData\Local\anaconda3\envs\flower_tutorial\lib\site-packages\torch\utils\data\dataloader.py", line 1282, in _get_data
    success, data = self._try_get_data()
  File "C:\Users\B00830189\AppData\Local\anaconda3\envs\flower_tutorial\lib\site-packages\torch\utils\data\dataloader.py", line 1133, in _try_get_data
    raise RuntimeError('DataLoader worker (pid(s) {}) exited unexpectedly'.format(pids_str)) from e
RuntimeError: DataLoader worker (pid(s) 5336, 7068) exited unexpectedly
[2024-05-24 16:06:25,382][flwr][ERROR] - [36mray::launch_and_fit()[39m (pid=7840, ip=127.0.0.1)
  File "C:\Users\B00830189\AppData\Local\anaconda3\envs\flower_tutorial\lib\multiprocessing\queues.py", line 108, in get
    raise Empty
_queue.Empty

The above exception was the direct cause of the following exception:

[36mray::launch_and_fit()[39m (pid=7840, ip=127.0.0.1)
  File "python\ray\_raylet.pyx", line 633, in ray._raylet.execute_task
  File "python\ray\_raylet.pyx", line 674, in ray._raylet.execute_task
  File "python\ray\_raylet.pyx", line 640, in ray._raylet.execute_task
  File "python\ray\_raylet.pyx", line 644, in ray._raylet.execute_task
  File "C:\Users\B00830189\AppData\Local\anaconda3\envs\flower_tutorial\lib\site-packages\flwr\simulation\ray_transport\ray_client_proxy.py", line 148, in launch_and_fit
    return maybe_call_fit(
  File "C:\Users\B00830189\AppData\Local\anaconda3\envs\flower_tutorial\lib\site-packages\flwr\client\client.py", line 184, in maybe_call_fit
    return client.fit(fit_ins)
  File "C:\Users\B00830189\AppData\Local\anaconda3\envs\flower_tutorial\lib\site-packages\flwr\client\app.py", line 297, in _fit
    results = self.numpy_client.fit(parameters, ins.config)  # type: ignore
  File "C:\Users\B00830189\OneDrive - Ulster University\phd\Code\Demos\Flower\FlowerTutorial\client.py", line 48, in fit
    train(self.model, self.trainload, optim, epochs, self.device) # Model no longer has weights sent my the server
  File "C:\Users\B00830189\OneDrive - Ulster University\phd\Code\Demos\Flower\FlowerTutorial\model.py", line 45, in train
    for images, labels in trainloader:
  File "C:\Users\B00830189\AppData\Local\anaconda3\envs\flower_tutorial\lib\site-packages\torch\utils\data\dataloader.py", line 628, in __next__
    data = self._next_data()
  File "C:\Users\B00830189\AppData\Local\anaconda3\envs\flower_tutorial\lib\site-packages\torch\utils\data\dataloader.py", line 1316, in _next_data
    idx, data = self._get_data()
  File "C:\Users\B00830189\AppData\Local\anaconda3\envs\flower_tutorial\lib\site-packages\torch\utils\data\dataloader.py", line 1282, in _get_data
    success, data = self._try_get_data()
  File "C:\Users\B00830189\AppData\Local\anaconda3\envs\flower_tutorial\lib\site-packages\torch\utils\data\dataloader.py", line 1133, in _try_get_data
    raise RuntimeError('DataLoader worker (pid(s) {}) exited unexpectedly'.format(pids_str)) from e
RuntimeError: DataLoader worker (pid(s) 7148) exited unexpectedly
[2024-05-24 16:06:25,386][flwr][DEBUG] - fit_round 2 received 0 results and 10 failures
[2024-05-24 16:06:28,116][flwr][INFO] - fit progress: (2, 182.40915274620056, {'accuracy': 0.1068}, 81.1632337)
[2024-05-24 16:06:28,120][flwr][DEBUG] - evaluate_round 2: strategy sampled 25 clients (out of 100)
[2024-05-24 16:06:34,502][flwr][ERROR] - [36mray::launch_and_evaluate()[39m (pid=11220, ip=127.0.0.1)
  File "C:\Users\B00830189\AppData\Local\anaconda3\envs\flower_tutorial\lib\multiprocessing\queues.py", line 108, in get
    raise Empty
_queue.Empty

The above exception was the direct cause of the following exception:

[36mray::launch_and_evaluate()[39m (pid=11220, ip=127.0.0.1)
  File "python\ray\_raylet.pyx", line 633, in ray._raylet.execute_task
  File "python\ray\_raylet.pyx", line 674, in ray._raylet.execute_task
  File "python\ray\_raylet.pyx", line 640, in ray._raylet.execute_task
  File "python\ray\_raylet.pyx", line 644, in ray._raylet.execute_task
  File "C:\Users\B00830189\AppData\Local\anaconda3\envs\flower_tutorial\lib\site-packages\flwr\simulation\ray_transport\ray_client_proxy.py", line 160, in launch_and_evaluate
    return maybe_call_evaluate(
  File "C:\Users\B00830189\AppData\Local\anaconda3\envs\flower_tutorial\lib\site-packages\flwr\client\client.py", line 205, in maybe_call_evaluate
    return client.evaluate(evaluate_ins)
  File "C:\Users\B00830189\AppData\Local\anaconda3\envs\flower_tutorial\lib\site-packages\flwr\client\app.py", line 321, in _evaluate
    results = self.numpy_client.evaluate(parameters, ins.config)  # type: ignore
  File "C:\Users\B00830189\OneDrive - Ulster University\phd\Code\Demos\Flower\FlowerTutorial\client.py", line 55, in evaluate
    loss, accuracy = test(self.model, self.valloader, self.device)
  File "C:\Users\B00830189\OneDrive - Ulster University\phd\Code\Demos\Flower\FlowerTutorial\model.py", line 63, in test
    for data in testloader:
  File "C:\Users\B00830189\AppData\Local\anaconda3\envs\flower_tutorial\lib\site-packages\torch\utils\data\dataloader.py", line 628, in __next__
    data = self._next_data()
  File "C:\Users\B00830189\AppData\Local\anaconda3\envs\flower_tutorial\lib\site-packages\torch\utils\data\dataloader.py", line 1316, in _next_data
    idx, data = self._get_data()
  File "C:\Users\B00830189\AppData\Local\anaconda3\envs\flower_tutorial\lib\site-packages\torch\utils\data\dataloader.py", line 1282, in _get_data
    success, data = self._try_get_data()
  File "C:\Users\B00830189\AppData\Local\anaconda3\envs\flower_tutorial\lib\site-packages\torch\utils\data\dataloader.py", line 1133, in _try_get_data
    raise RuntimeError('DataLoader worker (pid(s) {}) exited unexpectedly'.format(pids_str)) from e
RuntimeError: DataLoader worker (pid(s) 11524, 12384) exited unexpectedly
[2024-05-24 16:06:34,699][flwr][ERROR] - [36mray::launch_and_evaluate()[39m (pid=8948, ip=127.0.0.1)
  File "C:\Users\B00830189\AppData\Local\anaconda3\envs\flower_tutorial\lib\multiprocessing\queues.py", line 108, in get
    raise Empty
_queue.Empty

The above exception was the direct cause of the following exception:

[36mray::launch_and_evaluate()[39m (pid=8948, ip=127.0.0.1)
  File "python\ray\_raylet.pyx", line 633, in ray._raylet.execute_task
  File "python\ray\_raylet.pyx", line 674, in ray._raylet.execute_task
  File "python\ray\_raylet.pyx", line 640, in ray._raylet.execute_task
  File "python\ray\_raylet.pyx", line 644, in ray._raylet.execute_task
  File "C:\Users\B00830189\AppData\Local\anaconda3\envs\flower_tutorial\lib\site-packages\flwr\simulation\ray_transport\ray_client_proxy.py", line 160, in launch_and_evaluate
    return maybe_call_evaluate(
  File "C:\Users\B00830189\AppData\Local\anaconda3\envs\flower_tutorial\lib\site-packages\flwr\client\client.py", line 205, in maybe_call_evaluate
    return client.evaluate(evaluate_ins)
  File "C:\Users\B00830189\AppData\Local\anaconda3\envs\flower_tutorial\lib\site-packages\flwr\client\app.py", line 321, in _evaluate
    results = self.numpy_client.evaluate(parameters, ins.config)  # type: ignore
  File "C:\Users\B00830189\OneDrive - Ulster University\phd\Code\Demos\Flower\FlowerTutorial\client.py", line 55, in evaluate
    loss, accuracy = test(self.model, self.valloader, self.device)
  File "C:\Users\B00830189\OneDrive - Ulster University\phd\Code\Demos\Flower\FlowerTutorial\model.py", line 63, in test
    for data in testloader:
  File "C:\Users\B00830189\AppData\Local\anaconda3\envs\flower_tutorial\lib\site-packages\torch\utils\data\dataloader.py", line 628, in __next__
    data = self._next_data()
  File "C:\Users\B00830189\AppData\Local\anaconda3\envs\flower_tutorial\lib\site-packages\torch\utils\data\dataloader.py", line 1316, in _next_data
    idx, data = self._get_data()
  File "C:\Users\B00830189\AppData\Local\anaconda3\envs\flower_tutorial\lib\site-packages\torch\utils\data\dataloader.py", line 1282, in _get_data
    success, data = self._try_get_data()
  File "C:\Users\B00830189\AppData\Local\anaconda3\envs\flower_tutorial\lib\site-packages\torch\utils\data\dataloader.py", line 1133, in _try_get_data
    raise RuntimeError('DataLoader worker (pid(s) {}) exited unexpectedly'.format(pids_str)) from e
RuntimeError: DataLoader worker (pid(s) 5588, 11712) exited unexpectedly
[2024-05-24 16:06:34,806][flwr][ERROR] - [36mray::launch_and_evaluate()[39m (pid=7840, ip=127.0.0.1)
  File "C:\Users\B00830189\AppData\Local\anaconda3\envs\flower_tutorial\lib\multiprocessing\queues.py", line 108, in get
    raise Empty
_queue.Empty

The above exception was the direct cause of the following exception:

[36mray::launch_and_evaluate()[39m (pid=7840, ip=127.0.0.1)
  File "python\ray\_raylet.pyx", line 633, in ray._raylet.execute_task
  File "python\ray\_raylet.pyx", line 674, in ray._raylet.execute_task
  File "python\ray\_raylet.pyx", line 640, in ray._raylet.execute_task
  File "python\ray\_raylet.pyx", line 644, in ray._raylet.execute_task
  File "C:\Users\B00830189\AppData\Local\anaconda3\envs\flower_tutorial\lib\site-packages\flwr\simulation\ray_transport\ray_client_proxy.py", line 160, in launch_and_evaluate
    return maybe_call_evaluate(
  File "C:\Users\B00830189\AppData\Local\anaconda3\envs\flower_tutorial\lib\site-packages\flwr\client\client.py", line 205, in maybe_call_evaluate
    return client.evaluate(evaluate_ins)
  File "C:\Users\B00830189\AppData\Local\anaconda3\envs\flower_tutorial\lib\site-packages\flwr\client\app.py", line 321, in _evaluate
    results = self.numpy_client.evaluate(parameters, ins.config)  # type: ignore
  File "C:\Users\B00830189\OneDrive - Ulster University\phd\Code\Demos\Flower\FlowerTutorial\client.py", line 55, in evaluate
    loss, accuracy = test(self.model, self.valloader, self.device)
  File "C:\Users\B00830189\OneDrive - Ulster University\phd\Code\Demos\Flower\FlowerTutorial\model.py", line 63, in test
    for data in testloader:
  File "C:\Users\B00830189\AppData\Local\anaconda3\envs\flower_tutorial\lib\site-packages\torch\utils\data\dataloader.py", line 628, in __next__
    data = self._next_data()
  File "C:\Users\B00830189\AppData\Local\anaconda3\envs\flower_tutorial\lib\site-packages\torch\utils\data\dataloader.py", line 1316, in _next_data
    idx, data = self._get_data()
  File "C:\Users\B00830189\AppData\Local\anaconda3\envs\flower_tutorial\lib\site-packages\torch\utils\data\dataloader.py", line 1282, in _get_data
    success, data = self._try_get_data()
  File "C:\Users\B00830189\AppData\Local\anaconda3\envs\flower_tutorial\lib\site-packages\torch\utils\data\dataloader.py", line 1133, in _try_get_data
    raise RuntimeError('DataLoader worker (pid(s) {}) exited unexpectedly'.format(pids_str)) from e
RuntimeError: DataLoader worker (pid(s) 18952) exited unexpectedly
[2024-05-24 16:06:40,677][flwr][ERROR] - [36mray::launch_and_evaluate()[39m (pid=8948, ip=127.0.0.1)
  File "C:\Users\B00830189\AppData\Local\anaconda3\envs\flower_tutorial\lib\multiprocessing\queues.py", line 108, in get
    raise Empty
_queue.Empty

The above exception was the direct cause of the following exception:

[36mray::launch_and_evaluate()[39m (pid=8948, ip=127.0.0.1)
  File "python\ray\_raylet.pyx", line 633, in ray._raylet.execute_task
  File "python\ray\_raylet.pyx", line 674, in ray._raylet.execute_task
  File "python\ray\_raylet.pyx", line 640, in ray._raylet.execute_task
  File "python\ray\_raylet.pyx", line 644, in ray._raylet.execute_task
  File "C:\Users\B00830189\AppData\Local\anaconda3\envs\flower_tutorial\lib\site-packages\flwr\simulation\ray_transport\ray_client_proxy.py", line 160, in launch_and_evaluate
    return maybe_call_evaluate(
  File "C:\Users\B00830189\AppData\Local\anaconda3\envs\flower_tutorial\lib\site-packages\flwr\client\client.py", line 205, in maybe_call_evaluate
    return client.evaluate(evaluate_ins)
  File "C:\Users\B00830189\AppData\Local\anaconda3\envs\flower_tutorial\lib\site-packages\flwr\client\app.py", line 321, in _evaluate
    results = self.numpy_client.evaluate(parameters, ins.config)  # type: ignore
  File "C:\Users\B00830189\OneDrive - Ulster University\phd\Code\Demos\Flower\FlowerTutorial\client.py", line 55, in evaluate
    loss, accuracy = test(self.model, self.valloader, self.device)
  File "C:\Users\B00830189\OneDrive - Ulster University\phd\Code\Demos\Flower\FlowerTutorial\model.py", line 63, in test
    for data in testloader:
  File "C:\Users\B00830189\AppData\Local\anaconda3\envs\flower_tutorial\lib\site-packages\torch\utils\data\dataloader.py", line 628, in __next__
    data = self._next_data()
  File "C:\Users\B00830189\AppData\Local\anaconda3\envs\flower_tutorial\lib\site-packages\torch\utils\data\dataloader.py", line 1316, in _next_data
    idx, data = self._get_data()
  File "C:\Users\B00830189\AppData\Local\anaconda3\envs\flower_tutorial\lib\site-packages\torch\utils\data\dataloader.py", line 1282, in _get_data
    success, data = self._try_get_data()
  File "C:\Users\B00830189\AppData\Local\anaconda3\envs\flower_tutorial\lib\site-packages\torch\utils\data\dataloader.py", line 1133, in _try_get_data
    raise RuntimeError('DataLoader worker (pid(s) {}) exited unexpectedly'.format(pids_str)) from e
RuntimeError: DataLoader worker (pid(s) 17348, 7480) exited unexpectedly
[2024-05-24 16:06:40,759][flwr][ERROR] - [36mray::launch_and_evaluate()[39m (pid=7840, ip=127.0.0.1)
  File "C:\Users\B00830189\AppData\Local\anaconda3\envs\flower_tutorial\lib\multiprocessing\queues.py", line 108, in get
    raise Empty
_queue.Empty

The above exception was the direct cause of the following exception:

[36mray::launch_and_evaluate()[39m (pid=7840, ip=127.0.0.1)
  File "python\ray\_raylet.pyx", line 633, in ray._raylet.execute_task
  File "python\ray\_raylet.pyx", line 674, in ray._raylet.execute_task
  File "python\ray\_raylet.pyx", line 640, in ray._raylet.execute_task
  File "python\ray\_raylet.pyx", line 644, in ray._raylet.execute_task
  File "C:\Users\B00830189\AppData\Local\anaconda3\envs\flower_tutorial\lib\site-packages\flwr\simulation\ray_transport\ray_client_proxy.py", line 160, in launch_and_evaluate
    return maybe_call_evaluate(
  File "C:\Users\B00830189\AppData\Local\anaconda3\envs\flower_tutorial\lib\site-packages\flwr\client\client.py", line 205, in maybe_call_evaluate
    return client.evaluate(evaluate_ins)
  File "C:\Users\B00830189\AppData\Local\anaconda3\envs\flower_tutorial\lib\site-packages\flwr\client\app.py", line 321, in _evaluate
    results = self.numpy_client.evaluate(parameters, ins.config)  # type: ignore
  File "C:\Users\B00830189\OneDrive - Ulster University\phd\Code\Demos\Flower\FlowerTutorial\client.py", line 55, in evaluate
    loss, accuracy = test(self.model, self.valloader, self.device)
  File "C:\Users\B00830189\OneDrive - Ulster University\phd\Code\Demos\Flower\FlowerTutorial\model.py", line 63, in test
    for data in testloader:
  File "C:\Users\B00830189\AppData\Local\anaconda3\envs\flower_tutorial\lib\site-packages\torch\utils\data\dataloader.py", line 628, in __next__
    data = self._next_data()
  File "C:\Users\B00830189\AppData\Local\anaconda3\envs\flower_tutorial\lib\site-packages\torch\utils\data\dataloader.py", line 1316, in _next_data
    idx, data = self._get_data()
  File "C:\Users\B00830189\AppData\Local\anaconda3\envs\flower_tutorial\lib\site-packages\torch\utils\data\dataloader.py", line 1282, in _get_data
    success, data = self._try_get_data()
  File "C:\Users\B00830189\AppData\Local\anaconda3\envs\flower_tutorial\lib\site-packages\torch\utils\data\dataloader.py", line 1133, in _try_get_data
    raise RuntimeError('DataLoader worker (pid(s) {}) exited unexpectedly'.format(pids_str)) from e
RuntimeError: DataLoader worker (pid(s) 9116, 17072) exited unexpectedly
[2024-05-24 16:06:44,970][flwr][ERROR] - The task's local raylet died. Check raylet.out for more information.
[2024-05-24 16:06:44,970][flwr][ERROR] - The task's local raylet died. Check raylet.out for more information.
[2024-05-24 16:06:44,970][flwr][ERROR] - The task's local raylet died. Check raylet.out for more information.
[2024-05-24 16:06:44,970][flwr][ERROR] - The task's local raylet died. Check raylet.out for more information.
[2024-05-24 16:06:44,970][flwr][ERROR] - The task's local raylet died. Check raylet.out for more information.
[2024-05-24 16:06:44,971][flwr][ERROR] - The task's local raylet died. Check raylet.out for more information.
[2024-05-24 16:06:44,972][flwr][ERROR] - The task's local raylet died. Check raylet.out for more information.
[2024-05-24 16:06:46,990][flwr][ERROR] - The task's local raylet died. Check raylet.out for more information.
[2024-05-24 16:06:46,991][flwr][ERROR] - The task's local raylet died. Check raylet.out for more information.
[2024-05-24 16:06:46,991][flwr][ERROR] - The task's local raylet died. Check raylet.out for more information.
