[2024-05-24 16:30:31,016][flwr][INFO] - Starting Flower simulation, config: ServerConfig(num_rounds=5, round_timeout=None)
[2024-05-24 16:30:39,698][flwr][INFO] - Flower VCE: Ray initialized with resources: {'CPU': 8.0, 'memory': 912959079.0, 'object_store_memory': 456479539.0, 'node:127.0.0.1': 1.0}
[2024-05-24 16:30:39,702][flwr][INFO] - Initializing global parameters
[2024-05-24 16:30:39,705][flwr][INFO] - Requesting initial parameters from one random client
[2024-05-24 16:30:42,982][flwr][INFO] - Received initial parameters from one random client
[2024-05-24 16:30:42,983][flwr][INFO] - Evaluating initial parameters
[2024-05-24 16:30:47,079][flwr][INFO] - initial parameters (loss, other metrics): 182.25195240974426, {'accuracy': 0.0804}
[2024-05-24 16:30:47,080][flwr][INFO] - FL starting
[2024-05-24 16:30:47,083][flwr][DEBUG] - fit_round 1: strategy sampled 10 clients (out of 100)
[2024-05-24 16:30:54,342][flwr][ERROR] - [36mray::launch_and_fit()[39m (pid=5680, ip=127.0.0.1)
  File "python\ray\_raylet.pyx", line 600, in ray._raylet.execute_task
  File "C:\Users\B00830189\AppData\Local\anaconda3\envs\flower_tutorial\lib\site-packages\ray\_private\memory_monitor.py", line 156, in raise_if_low_memory
    raise RayOutOfMemoryError(
ray._private.memory_monitor.RayOutOfMemoryError: More than 95% of the memory on node 2RWV8C3 is used (7.36 / 7.63 GB). The top 10 memory consumers are:

PID	MEM	COMMAND
6208	0.37GiB	C:\Users\B00830189\AppData\Local\anaconda3\envs\flower_tutorial\python.exe C:\Users\B00830189\AppDat
7348	0.36GiB	python main.py num_rounds=5
13048	0.33GiB	C:\Program Files\Google\Chrome\Application\chrome.exe --type=renderer --enable-dinosaur-easter-egg-a
19252	0.25GiB	C:\Users\B00830189\AppData\Local\anaconda3\envs\flower_tutorial\python.exe C:\Users\B00830189\AppDat
16408	0.25GiB	C:\Users\B00830189\AppData\Local\anaconda3\envs\flower_tutorial\python.exe C:\Users\B00830189\AppDat
10684	0.25GiB	C:\Users\B00830189\AppData\Local\anaconda3\envs\flower_tutorial\python.exe C:\Users\B00830189\AppDat
8268	0.24GiB	C:\Users\B00830189\AppData\Local\anaconda3\envs\flower_tutorial\python.exe C:\Users\B00830189\AppDat
17724	0.21GiB	C:\Program Files\Google\Chrome\Application\chrome.exe --type=gpu-process --gpu-preferences=WAAAAAAAA
7628	0.15GiB	C:\Users\B00830189\AppData\Local\Programs\Microsoft VS Code\Code.exe --type=renderer --user-data-dir
4904	0.14GiB	C:\Program Files\Google\Chrome\Application\chrome.exe

In addition, up to 0.0 GiB of shared memory is currently being used by the Ray object store.
---
--- Tip: Use the `ray memory` command to list active objects in the cluster.
--- To disable OOM exceptions, set RAY_DISABLE_MEMORY_MONITOR=1.
---
[2024-05-24 16:30:54,532][flwr][ERROR] - [36mray::launch_and_fit()[39m (pid=5680, ip=127.0.0.1)
  File "python\ray\_raylet.pyx", line 602, in ray._raylet.execute_task
  File "python\ray\_raylet.pyx", line 624, in ray._raylet.execute_task
  File "python\ray\_raylet.pyx", line 456, in ray._raylet.raise_if_dependency_failed
ray.exceptions.RaySystemError: System error: [WinError 1455] The paging file is too small for this operation to complete. Error loading "C:\Users\B00830189\AppData\Local\anaconda3\envs\flower_tutorial\lib\site-packages\torch\lib\cudnn_cnn_infer64_8.dll" or one of its dependencies.
traceback: Traceback (most recent call last):
  File "C:\Users\B00830189\AppData\Local\anaconda3\envs\flower_tutorial\lib\site-packages\ray\serialization.py", line 309, in deserialize_objects
    obj = self._deserialize_object(data, metadata, object_ref)
  File "C:\Users\B00830189\AppData\Local\anaconda3\envs\flower_tutorial\lib\site-packages\ray\serialization.py", line 215, in _deserialize_object
    return self._deserialize_msgpack_data(data, metadata_fields)
  File "C:\Users\B00830189\AppData\Local\anaconda3\envs\flower_tutorial\lib\site-packages\ray\serialization.py", line 174, in _deserialize_msgpack_data
    python_objects = self._deserialize_pickle5_data(pickle5_data)
  File "C:\Users\B00830189\AppData\Local\anaconda3\envs\flower_tutorial\lib\site-packages\ray\serialization.py", line 164, in _deserialize_pickle5_data
    obj = pickle.loads(in_band)
  File "C:\Users\B00830189\AppData\Local\anaconda3\envs\flower_tutorial\lib\site-packages\torch\__init__.py", line 128, in <module>
    raise err
OSError: [WinError 1455] The paging file is too small for this operation to complete. Error loading "C:\Users\B00830189\AppData\Local\anaconda3\envs\flower_tutorial\lib\site-packages\torch\lib\cudnn_cnn_infer64_8.dll" or one of its dependencies.
[2024-05-24 16:30:54,607][flwr][ERROR] - [36mray::launch_and_fit()[39m (pid=5680, ip=127.0.0.1)
  File "python\ray\_raylet.pyx", line 602, in ray._raylet.execute_task
  File "python\ray\_raylet.pyx", line 624, in ray._raylet.execute_task
  File "python\ray\_raylet.pyx", line 456, in ray._raylet.raise_if_dependency_failed
ray.exceptions.RaySystemError: System error: [WinError 1455] The paging file is too small for this operation to complete. Error loading "C:\Users\B00830189\AppData\Local\anaconda3\envs\flower_tutorial\lib\site-packages\torch\lib\cudnn_cnn_infer64_8.dll" or one of its dependencies.
traceback: Traceback (most recent call last):
  File "C:\Users\B00830189\AppData\Local\anaconda3\envs\flower_tutorial\lib\site-packages\ray\serialization.py", line 309, in deserialize_objects
    obj = self._deserialize_object(data, metadata, object_ref)
  File "C:\Users\B00830189\AppData\Local\anaconda3\envs\flower_tutorial\lib\site-packages\ray\serialization.py", line 215, in _deserialize_object
    return self._deserialize_msgpack_data(data, metadata_fields)
  File "C:\Users\B00830189\AppData\Local\anaconda3\envs\flower_tutorial\lib\site-packages\ray\serialization.py", line 174, in _deserialize_msgpack_data
    python_objects = self._deserialize_pickle5_data(pickle5_data)
  File "C:\Users\B00830189\AppData\Local\anaconda3\envs\flower_tutorial\lib\site-packages\ray\serialization.py", line 164, in _deserialize_pickle5_data
    obj = pickle.loads(in_band)
  File "C:\Users\B00830189\AppData\Local\anaconda3\envs\flower_tutorial\lib\site-packages\torch\__init__.py", line 128, in <module>
    raise err
OSError: [WinError 1455] The paging file is too small for this operation to complete. Error loading "C:\Users\B00830189\AppData\Local\anaconda3\envs\flower_tutorial\lib\site-packages\torch\lib\cudnn_cnn_infer64_8.dll" or one of its dependencies.
[2024-05-24 16:30:55,892][flwr][ERROR] - [36mray::launch_and_fit()[39m (pid=16408, ip=127.0.0.1)
  File "python\ray\_raylet.pyx", line 602, in ray._raylet.execute_task
  File "python\ray\_raylet.pyx", line 624, in ray._raylet.execute_task
  File "python\ray\_raylet.pyx", line 456, in ray._raylet.raise_if_dependency_failed
ray.exceptions.RaySystemError: System error: 
traceback: Traceback (most recent call last):
  File "C:\Users\B00830189\AppData\Local\anaconda3\envs\flower_tutorial\lib\site-packages\ray\serialization.py", line 309, in deserialize_objects
    obj = self._deserialize_object(data, metadata, object_ref)
  File "C:\Users\B00830189\AppData\Local\anaconda3\envs\flower_tutorial\lib\site-packages\ray\serialization.py", line 215, in _deserialize_object
    return self._deserialize_msgpack_data(data, metadata_fields)
  File "C:\Users\B00830189\AppData\Local\anaconda3\envs\flower_tutorial\lib\site-packages\ray\serialization.py", line 174, in _deserialize_msgpack_data
    python_objects = self._deserialize_pickle5_data(pickle5_data)
  File "C:\Users\B00830189\AppData\Local\anaconda3\envs\flower_tutorial\lib\site-packages\ray\serialization.py", line 164, in _deserialize_pickle5_data
    obj = pickle.loads(in_band)
MemoryError
[2024-05-24 16:30:56,778][flwr][ERROR] - [36mray::launch_and_fit()[39m (pid=8268, ip=127.0.0.1)
  File "python\ray\_raylet.pyx", line 602, in ray._raylet.execute_task
  File "python\ray\_raylet.pyx", line 624, in ray._raylet.execute_task
  File "python\ray\_raylet.pyx", line 456, in ray._raylet.raise_if_dependency_failed
ray.exceptions.RaySystemError: System error: [enforce fail at C:\cb\pytorch_1000000000000\work\c10\core\impl\alloc_cpu.cpp:72] data. DefaultCPUAllocator: not enough memory: you tried to allocate 47040000 bytes.
traceback: Traceback (most recent call last):
  File "C:\Users\B00830189\AppData\Local\anaconda3\envs\flower_tutorial\lib\site-packages\ray\serialization.py", line 309, in deserialize_objects
    obj = self._deserialize_object(data, metadata, object_ref)
  File "C:\Users\B00830189\AppData\Local\anaconda3\envs\flower_tutorial\lib\site-packages\ray\serialization.py", line 215, in _deserialize_object
    return self._deserialize_msgpack_data(data, metadata_fields)
  File "C:\Users\B00830189\AppData\Local\anaconda3\envs\flower_tutorial\lib\site-packages\ray\serialization.py", line 174, in _deserialize_msgpack_data
    python_objects = self._deserialize_pickle5_data(pickle5_data)
  File "C:\Users\B00830189\AppData\Local\anaconda3\envs\flower_tutorial\lib\site-packages\ray\serialization.py", line 164, in _deserialize_pickle5_data
    obj = pickle.loads(in_band)
  File "C:\Users\B00830189\AppData\Local\anaconda3\envs\flower_tutorial\lib\site-packages\torch\storage.py", line 240, in _load_from_bytes
    return torch.load(io.BytesIO(b))
  File "C:\Users\B00830189\AppData\Local\anaconda3\envs\flower_tutorial\lib\site-packages\torch\serialization.py", line 795, in load
    return _legacy_load(opened_file, map_location, pickle_module, **pickle_load_args)
  File "C:\Users\B00830189\AppData\Local\anaconda3\envs\flower_tutorial\lib\site-packages\torch\serialization.py", line 1012, in _legacy_load
    result = unpickler.load()
  File "C:\Users\B00830189\AppData\Local\anaconda3\envs\flower_tutorial\lib\site-packages\torch\serialization.py", line 953, in persistent_load
    obj = cast(Storage, torch.UntypedStorage(nbytes))
RuntimeError: [enforce fail at C:\cb\pytorch_1000000000000\work\c10\core\impl\alloc_cpu.cpp:72] data. DefaultCPUAllocator: not enough memory: you tried to allocate 47040000 bytes.
[2024-05-24 16:30:57,484][flwr][ERROR] - [36mray::launch_and_fit()[39m (pid=10684, ip=127.0.0.1)
  File "python\ray\_raylet.pyx", line 640, in ray._raylet.execute_task
  File "python\ray\_raylet.pyx", line 644, in ray._raylet.execute_task
  File "C:\Users\B00830189\AppData\Local\anaconda3\envs\flower_tutorial\lib\site-packages\flwr\simulation\ray_transport\ray_client_proxy.py", line 148, in launch_and_fit
    return maybe_call_fit(
  File "C:\Users\B00830189\AppData\Local\anaconda3\envs\flower_tutorial\lib\site-packages\flwr\client\client.py", line 184, in maybe_call_fit
    return client.fit(fit_ins)
  File "C:\Users\B00830189\AppData\Local\anaconda3\envs\flower_tutorial\lib\site-packages\flwr\client\app.py", line 297, in _fit
    results = self.numpy_client.fit(parameters, ins.config)  # type: ignore
  File "C:\Users\B00830189\OneDrive - Ulster University\phd\Code\Demos\Flower\FlowerTutorial\client.py", line 48, in fit
    train(self.model, self.trainload, optim, epochs, self.device) # Model no longer has weights sent my the server
  File "C:\Users\B00830189\OneDrive - Ulster University\phd\Code\Demos\Flower\FlowerTutorial\model.py", line 45, in train
    for images, labels in trainloader:
  File "C:\Users\B00830189\AppData\Local\anaconda3\envs\flower_tutorial\lib\site-packages\torch\utils\data\dataloader.py", line 435, in __iter__
    return self._get_iterator()
  File "C:\Users\B00830189\AppData\Local\anaconda3\envs\flower_tutorial\lib\site-packages\torch\utils\data\dataloader.py", line 381, in _get_iterator
    return _MultiProcessingDataLoaderIter(self)
  File "C:\Users\B00830189\AppData\Local\anaconda3\envs\flower_tutorial\lib\site-packages\torch\utils\data\dataloader.py", line 1034, in __init__
    w.start()
  File "C:\Users\B00830189\AppData\Local\anaconda3\envs\flower_tutorial\lib\multiprocessing\process.py", line 121, in start
    self._popen = self._Popen(self)
  File "C:\Users\B00830189\AppData\Local\anaconda3\envs\flower_tutorial\lib\multiprocessing\context.py", line 224, in _Popen
    return _default_context.get_context().Process._Popen(process_obj)
  File "C:\Users\B00830189\AppData\Local\anaconda3\envs\flower_tutorial\lib\multiprocessing\context.py", line 327, in _Popen
    return Popen(process_obj)
  File "C:\Users\B00830189\AppData\Local\anaconda3\envs\flower_tutorial\lib\multiprocessing\popen_spawn_win32.py", line 93, in __init__
    reduction.dump(process_obj, to_child)
  File "C:\Users\B00830189\AppData\Local\anaconda3\envs\flower_tutorial\lib\multiprocessing\reduction.py", line 60, in dump
    ForkingPickler(file, protocol).dump(obj)
  File "C:\Users\B00830189\AppData\Local\anaconda3\envs\flower_tutorial\lib\multiprocessing\synchronize.py", line 104, in __getstate__
    h = context.get_spawning_popen().duplicate_for_child(sl.handle)
  File "C:\Users\B00830189\AppData\Local\anaconda3\envs\flower_tutorial\lib\multiprocessing\popen_spawn_win32.py", line 99, in duplicate_for_child
    return reduction.duplicate(handle, self.sentinel)
  File "C:\Users\B00830189\AppData\Local\anaconda3\envs\flower_tutorial\lib\multiprocessing\reduction.py", line 79, in duplicate
    return _winapi.DuplicateHandle(
PermissionError: [WinError 5] Access is denied
[2024-05-24 16:30:58,835][flwr][ERROR] - [36mray::launch_and_fit()[39m (pid=6208, ip=127.0.0.1)
  File "C:\Users\B00830189\AppData\Local\anaconda3\envs\flower_tutorial\lib\multiprocessing\queues.py", line 108, in get
    raise Empty
_queue.Empty

The above exception was the direct cause of the following exception:

[36mray::launch_and_fit()[39m (pid=6208, ip=127.0.0.1)
  File "python\ray\_raylet.pyx", line 633, in ray._raylet.execute_task
  File "python\ray\_raylet.pyx", line 674, in ray._raylet.execute_task
  File "python\ray\_raylet.pyx", line 640, in ray._raylet.execute_task
  File "python\ray\_raylet.pyx", line 644, in ray._raylet.execute_task
  File "C:\Users\B00830189\AppData\Local\anaconda3\envs\flower_tutorial\lib\site-packages\flwr\simulation\ray_transport\ray_client_proxy.py", line 148, in launch_and_fit
    return maybe_call_fit(
  File "C:\Users\B00830189\AppData\Local\anaconda3\envs\flower_tutorial\lib\site-packages\flwr\client\client.py", line 184, in maybe_call_fit
    return client.fit(fit_ins)
  File "C:\Users\B00830189\AppData\Local\anaconda3\envs\flower_tutorial\lib\site-packages\flwr\client\app.py", line 297, in _fit
    results = self.numpy_client.fit(parameters, ins.config)  # type: ignore
  File "C:\Users\B00830189\OneDrive - Ulster University\phd\Code\Demos\Flower\FlowerTutorial\client.py", line 48, in fit
    train(self.model, self.trainload, optim, epochs, self.device) # Model no longer has weights sent my the server
  File "C:\Users\B00830189\OneDrive - Ulster University\phd\Code\Demos\Flower\FlowerTutorial\model.py", line 45, in train
    for images, labels in trainloader:
  File "C:\Users\B00830189\AppData\Local\anaconda3\envs\flower_tutorial\lib\site-packages\torch\utils\data\dataloader.py", line 628, in __next__
    data = self._next_data()
  File "C:\Users\B00830189\AppData\Local\anaconda3\envs\flower_tutorial\lib\site-packages\torch\utils\data\dataloader.py", line 1316, in _next_data
    idx, data = self._get_data()
  File "C:\Users\B00830189\AppData\Local\anaconda3\envs\flower_tutorial\lib\site-packages\torch\utils\data\dataloader.py", line 1282, in _get_data
    success, data = self._try_get_data()
  File "C:\Users\B00830189\AppData\Local\anaconda3\envs\flower_tutorial\lib\site-packages\torch\utils\data\dataloader.py", line 1133, in _try_get_data
    raise RuntimeError('DataLoader worker (pid(s) {}) exited unexpectedly'.format(pids_str)) from e
RuntimeError: DataLoader worker (pid(s) 17584, 11172) exited unexpectedly
[2024-05-24 16:30:59,539][flwr][ERROR] - [36mray::launch_and_fit()[39m (pid=8268, ip=127.0.0.1)
  File "python\ray\_raylet.pyx", line 600, in ray._raylet.execute_task
  File "C:\Users\B00830189\AppData\Local\anaconda3\envs\flower_tutorial\lib\site-packages\ray\_private\memory_monitor.py", line 156, in raise_if_low_memory
    raise RayOutOfMemoryError(
ray._private.memory_monitor.RayOutOfMemoryError: More than 95% of the memory on node 2RWV8C3 is used (7.36 / 7.63 GB). The top 10 memory consumers are:

PID	MEM	COMMAND
8268	0.36GiB	C:\Users\B00830189\AppData\Local\anaconda3\envs\flower_tutorial\python.exe C:\Users\B00830189\AppDat
19252	0.34GiB	C:\Users\B00830189\AppData\Local\anaconda3\envs\flower_tutorial\python.exe C:\Users\B00830189\AppDat
7348	0.34GiB	python main.py num_rounds=5
6208	0.32GiB	C:\Users\B00830189\AppData\Local\anaconda3\envs\flower_tutorial\python.exe C:\Users\B00830189\AppDat
10684	0.29GiB	C:\Users\B00830189\AppData\Local\anaconda3\envs\flower_tutorial\python.exe C:\Users\B00830189\AppDat
16408	0.27GiB	C:\Users\B00830189\AppData\Local\anaconda3\envs\flower_tutorial\python.exe C:\Users\B00830189\AppDat
13048	0.27GiB	C:\Program Files\Google\Chrome\Application\chrome.exe --type=renderer --enable-dinosaur-easter-egg-a
4904	0.13GiB	C:\Program Files\Google\Chrome\Application\chrome.exe
17724	0.13GiB	C:\Program Files\Google\Chrome\Application\chrome.exe --type=gpu-process --gpu-preferences=WAAAAAAAA
15468	0.12GiB	C:\Users\B00830189\AppData\Local\anaconda3\envs\flower_tutorial\python.exe C:\Users\B00830189\AppDat

In addition, up to 0.0 GiB of shared memory is currently being used by the Ray object store.
---
--- Tip: Use the `ray memory` command to list active objects in the cluster.
--- To disable OOM exceptions, set RAY_DISABLE_MEMORY_MONITOR=1.
---
[2024-05-24 16:30:59,585][flwr][ERROR] - [36mray::launch_and_fit()[39m (pid=16408, ip=127.0.0.1)
  File "python\ray\_raylet.pyx", line 600, in ray._raylet.execute_task
  File "C:\Users\B00830189\AppData\Local\anaconda3\envs\flower_tutorial\lib\site-packages\ray\_private\memory_monitor.py", line 156, in raise_if_low_memory
    raise RayOutOfMemoryError(
ray._private.memory_monitor.RayOutOfMemoryError: More than 95% of the memory on node 2RWV8C3 is used (7.36 / 7.63 GB). The top 10 memory consumers are:

PID	MEM	COMMAND
8268	0.36GiB	C:\Users\B00830189\AppData\Local\anaconda3\envs\flower_tutorial\python.exe C:\Users\B00830189\AppDat
19252	0.34GiB	C:\Users\B00830189\AppData\Local\anaconda3\envs\flower_tutorial\python.exe C:\Users\B00830189\AppDat
7348	0.34GiB	python main.py num_rounds=5
6208	0.32GiB	C:\Users\B00830189\AppData\Local\anaconda3\envs\flower_tutorial\python.exe C:\Users\B00830189\AppDat
10684	0.29GiB	C:\Users\B00830189\AppData\Local\anaconda3\envs\flower_tutorial\python.exe C:\Users\B00830189\AppDat
16408	0.27GiB	C:\Users\B00830189\AppData\Local\anaconda3\envs\flower_tutorial\python.exe C:\Users\B00830189\AppDat
13048	0.27GiB	C:\Program Files\Google\Chrome\Application\chrome.exe --type=renderer --enable-dinosaur-easter-egg-a
4904	0.13GiB	C:\Program Files\Google\Chrome\Application\chrome.exe
17724	0.13GiB	C:\Program Files\Google\Chrome\Application\chrome.exe --type=gpu-process --gpu-preferences=WAAAAAAAA
15468	0.12GiB	C:\Users\B00830189\AppData\Local\anaconda3\envs\flower_tutorial\python.exe C:\Users\B00830189\AppDat

In addition, up to 0.0 GiB of shared memory is currently being used by the Ray object store.
---
--- Tip: Use the `ray memory` command to list active objects in the cluster.
--- To disable OOM exceptions, set RAY_DISABLE_MEMORY_MONITOR=1.
---
[2024-05-24 16:31:02,027][flwr][ERROR] - [36mray::launch_and_fit()[39m (pid=19252, ip=127.0.0.1)
  File "C:\Users\B00830189\AppData\Local\anaconda3\envs\flower_tutorial\lib\multiprocessing\queues.py", line 108, in get
    raise Empty
_queue.Empty

The above exception was the direct cause of the following exception:

[36mray::launch_and_fit()[39m (pid=19252, ip=127.0.0.1)
  File "python\ray\_raylet.pyx", line 633, in ray._raylet.execute_task
  File "python\ray\_raylet.pyx", line 674, in ray._raylet.execute_task
  File "python\ray\_raylet.pyx", line 640, in ray._raylet.execute_task
  File "python\ray\_raylet.pyx", line 644, in ray._raylet.execute_task
  File "C:\Users\B00830189\AppData\Local\anaconda3\envs\flower_tutorial\lib\site-packages\flwr\simulation\ray_transport\ray_client_proxy.py", line 148, in launch_and_fit
    return maybe_call_fit(
  File "C:\Users\B00830189\AppData\Local\anaconda3\envs\flower_tutorial\lib\site-packages\flwr\client\client.py", line 184, in maybe_call_fit
    return client.fit(fit_ins)
  File "C:\Users\B00830189\AppData\Local\anaconda3\envs\flower_tutorial\lib\site-packages\flwr\client\app.py", line 297, in _fit
    results = self.numpy_client.fit(parameters, ins.config)  # type: ignore
  File "C:\Users\B00830189\OneDrive - Ulster University\phd\Code\Demos\Flower\FlowerTutorial\client.py", line 48, in fit
    train(self.model, self.trainload, optim, epochs, self.device) # Model no longer has weights sent my the server
  File "C:\Users\B00830189\OneDrive - Ulster University\phd\Code\Demos\Flower\FlowerTutorial\model.py", line 45, in train
    for images, labels in trainloader:
  File "C:\Users\B00830189\AppData\Local\anaconda3\envs\flower_tutorial\lib\site-packages\torch\utils\data\dataloader.py", line 628, in __next__
    data = self._next_data()
  File "C:\Users\B00830189\AppData\Local\anaconda3\envs\flower_tutorial\lib\site-packages\torch\utils\data\dataloader.py", line 1316, in _next_data
    idx, data = self._get_data()
  File "C:\Users\B00830189\AppData\Local\anaconda3\envs\flower_tutorial\lib\site-packages\torch\utils\data\dataloader.py", line 1282, in _get_data
    success, data = self._try_get_data()
  File "C:\Users\B00830189\AppData\Local\anaconda3\envs\flower_tutorial\lib\site-packages\torch\utils\data\dataloader.py", line 1133, in _try_get_data
    raise RuntimeError('DataLoader worker (pid(s) {}) exited unexpectedly'.format(pids_str)) from e
RuntimeError: DataLoader worker (pid(s) 17080, 18256) exited unexpectedly
[2024-05-24 16:31:02,033][flwr][DEBUG] - fit_round 1 received 0 results and 10 failures
[2024-05-24 16:31:05,358][flwr][INFO] - fit progress: (1, 182.25195240974426, {'accuracy': 0.0804}, 18.276068499999997)
[2024-05-24 16:31:05,359][flwr][DEBUG] - evaluate_round 1: strategy sampled 25 clients (out of 100)
[2024-05-24 16:31:05,829][flwr][DEBUG] - evaluate_round 1 received 0 results and 25 failures
[2024-05-24 16:31:05,830][flwr][DEBUG] - fit_round 2: strategy sampled 10 clients (out of 100)
[2024-05-24 16:31:06,029][flwr][DEBUG] - fit_round 2 received 0 results and 10 failures
[2024-05-24 16:31:09,121][flwr][INFO] - fit progress: (2, 182.25195240974426, {'accuracy': 0.0804}, 22.0392543)
[2024-05-24 16:31:09,121][flwr][DEBUG] - evaluate_round 2: strategy sampled 25 clients (out of 100)
[2024-05-24 16:31:09,449][flwr][DEBUG] - evaluate_round 2 received 0 results and 25 failures
[2024-05-24 16:31:09,468][flwr][DEBUG] - fit_round 3: strategy sampled 10 clients (out of 100)
[2024-05-24 16:31:09,664][flwr][DEBUG] - fit_round 3 received 0 results and 10 failures
[2024-05-24 16:31:13,004][flwr][INFO] - fit progress: (3, 182.25195240974426, {'accuracy': 0.0804}, 25.921653600000003)
[2024-05-24 16:31:13,004][flwr][DEBUG] - evaluate_round 3: strategy sampled 25 clients (out of 100)
[2024-05-24 16:31:13,382][flwr][DEBUG] - evaluate_round 3 received 0 results and 25 failures
[2024-05-24 16:31:13,383][flwr][DEBUG] - fit_round 4: strategy sampled 10 clients (out of 100)
[2024-05-24 16:31:13,586][flwr][DEBUG] - fit_round 4 received 0 results and 10 failures
[2024-05-24 16:31:16,591][flwr][INFO] - fit progress: (4, 182.25195240974426, {'accuracy': 0.0804}, 29.509696099999996)
[2024-05-24 16:31:16,592][flwr][DEBUG] - evaluate_round 4: strategy sampled 25 clients (out of 100)
[2024-05-24 16:31:16,865][flwr][ERROR] - [36mray::launch_and_evaluate()[39m (pid=19252, ip=127.0.0.1)
  File "python\ray\_raylet.pyx", line 602, in ray._raylet.execute_task
  File "python\ray\_raylet.pyx", line 624, in ray._raylet.execute_task
  File "python\ray\_raylet.pyx", line 456, in ray._raylet.raise_if_dependency_failed
ray.exceptions.RaySystemError: System error: 
traceback: Traceback (most recent call last):
  File "C:\Users\B00830189\AppData\Local\anaconda3\envs\flower_tutorial\lib\site-packages\ray\serialization.py", line 309, in deserialize_objects
    obj = self._deserialize_object(data, metadata, object_ref)
  File "C:\Users\B00830189\AppData\Local\anaconda3\envs\flower_tutorial\lib\site-packages\ray\serialization.py", line 215, in _deserialize_object
    return self._deserialize_msgpack_data(data, metadata_fields)
  File "C:\Users\B00830189\AppData\Local\anaconda3\envs\flower_tutorial\lib\site-packages\ray\serialization.py", line 174, in _deserialize_msgpack_data
    python_objects = self._deserialize_pickle5_data(pickle5_data)
  File "C:\Users\B00830189\AppData\Local\anaconda3\envs\flower_tutorial\lib\site-packages\ray\serialization.py", line 164, in _deserialize_pickle5_data
    obj = pickle.loads(in_band)
MemoryError
[2024-05-24 16:31:17,153][flwr][DEBUG] - evaluate_round 4 received 0 results and 25 failures
[2024-05-24 16:31:17,162][flwr][DEBUG] - fit_round 5: strategy sampled 10 clients (out of 100)
[2024-05-24 16:31:17,438][flwr][DEBUG] - fit_round 5 received 0 results and 10 failures
[2024-05-24 16:31:20,580][flwr][INFO] - fit progress: (5, 182.25195240974426, {'accuracy': 0.0804}, 33.498435900000004)
[2024-05-24 16:31:20,581][flwr][DEBUG] - evaluate_round 5: strategy sampled 25 clients (out of 100)
[2024-05-24 16:31:20,917][flwr][DEBUG] - evaluate_round 5 received 0 results and 25 failures
[2024-05-24 16:31:20,930][flwr][INFO] - FL finished in 33.849148
[2024-05-24 16:31:20,940][flwr][INFO] - app_fit: losses_distributed []
[2024-05-24 16:31:20,940][flwr][INFO] - app_fit: metrics_distributed_fit {}
[2024-05-24 16:31:20,940][flwr][INFO] - app_fit: metrics_distributed {}
[2024-05-24 16:31:20,941][flwr][INFO] - app_fit: losses_centralized [(0, 182.25195240974426), (1, 182.25195240974426), (2, 182.25195240974426), (3, 182.25195240974426), (4, 182.25195240974426), (5, 182.25195240974426)]
[2024-05-24 16:31:20,941][flwr][INFO] - app_fit: metrics_centralized {'accuracy': [(0, 0.0804), (1, 0.0804), (2, 0.0804), (3, 0.0804), (4, 0.0804), (5, 0.0804)]}
