[2024-05-24 14:23:18,196][flwr][INFO] - Starting Flower simulation, config: ServerConfig(num_rounds=5, round_timeout=None)
[2024-05-24 14:23:23,654][flwr][INFO] - Flower VCE: Ray initialized with resources: {'memory': 728933991.0, 'node:127.0.0.1': 1.0, 'CPU': 8.0, 'object_store_memory': 364466995.0}
[2024-05-24 14:23:23,656][flwr][INFO] - Initializing global parameters
[2024-05-24 14:23:23,657][flwr][INFO] - Requesting initial parameters from one random client
[2024-05-24 14:23:26,235][flwr][INFO] - Received initial parameters from one random client
[2024-05-24 14:23:26,235][flwr][INFO] - Evaluating initial parameters
[2024-05-24 14:23:28,910][flwr][INFO] - initial parameters (loss, other metrics): 181.93332147598267, {'accuracy': 0.0786}
[2024-05-24 14:23:28,922][flwr][INFO] - FL starting
[2024-05-24 14:23:28,923][flwr][DEBUG] - fit_round 1: strategy sampled 10 clients (out of 100)
[2024-05-24 14:23:36,098][flwr][ERROR] - [36mray::launch_and_fit()[39m (pid=12948, ip=127.0.0.1)
  File "C:\Users\B00830189\AppData\Local\anaconda3\envs\flower_tutorial\lib\multiprocessing\queues.py", line 108, in get
    raise Empty
_queue.Empty

The above exception was the direct cause of the following exception:

[36mray::launch_and_fit()[39m (pid=12948, ip=127.0.0.1)
  File "python\ray\_raylet.pyx", line 633, in ray._raylet.execute_task
  File "python\ray\_raylet.pyx", line 674, in ray._raylet.execute_task
  File "python\ray\_raylet.pyx", line 640, in ray._raylet.execute_task
  File "python\ray\_raylet.pyx", line 644, in ray._raylet.execute_task
  File "C:\Users\B00830189\AppData\Local\anaconda3\envs\flower_tutorial\lib\site-packages\flwr\simulation\ray_transport\ray_client_proxy.py", line 148, in launch_and_fit
    return maybe_call_fit(
  File "C:\Users\B00830189\AppData\Local\anaconda3\envs\flower_tutorial\lib\site-packages\flwr\client\client.py", line 184, in maybe_call_fit
    return client.fit(fit_ins)
  File "C:\Users\B00830189\AppData\Local\anaconda3\envs\flower_tutorial\lib\site-packages\flwr\client\app.py", line 297, in _fit
    results = self.numpy_client.fit(parameters, ins.config)  # type: ignore
  File "C:\Users\B00830189\OneDrive - Ulster University\phd\Code\Demos\Flower\FlowerTutorial\client.py", line 48, in fit
    train(self.model, self.trainloader, optim, epochs, self.device) # Model no longer has weights sent my the server
  File "C:\Users\B00830189\OneDrive - Ulster University\phd\Code\Demos\Flower\FlowerTutorial\model.py", line 45, in train
    for images, labels in trainloader:
  File "C:\Users\B00830189\AppData\Local\anaconda3\envs\flower_tutorial\lib\site-packages\torch\utils\data\dataloader.py", line 628, in __next__
    data = self._next_data()
  File "C:\Users\B00830189\AppData\Local\anaconda3\envs\flower_tutorial\lib\site-packages\torch\utils\data\dataloader.py", line 1316, in _next_data
    idx, data = self._get_data()
  File "C:\Users\B00830189\AppData\Local\anaconda3\envs\flower_tutorial\lib\site-packages\torch\utils\data\dataloader.py", line 1282, in _get_data
    success, data = self._try_get_data()
  File "C:\Users\B00830189\AppData\Local\anaconda3\envs\flower_tutorial\lib\site-packages\torch\utils\data\dataloader.py", line 1133, in _try_get_data
    raise RuntimeError('DataLoader worker (pid(s) {}) exited unexpectedly'.format(pids_str)) from e
RuntimeError: DataLoader worker (pid(s) 19368) exited unexpectedly
[2024-05-24 14:23:36,369][flwr][ERROR] - [36mray::launch_and_fit()[39m (pid=14596, ip=127.0.0.1)
  File "python\ray\_raylet.pyx", line 600, in ray._raylet.execute_task
  File "C:\Users\B00830189\AppData\Local\anaconda3\envs\flower_tutorial\lib\site-packages\ray\_private\memory_monitor.py", line 156, in raise_if_low_memory
    raise RayOutOfMemoryError(
ray._private.memory_monitor.RayOutOfMemoryError: More than 95% of the memory on node 2RWV8C3 is used (7.31 / 7.63 GB). The top 10 memory consumers are:

PID	MEM	COMMAND
3212	0.48GiB	C:\Users\B00830189\AppData\Local\Programs\Microsoft VS Code\Code.exe c:\Users\B00830189\.vscode\exte
19108	0.34GiB	C:\Program Files\Google\Chrome\Application\chrome.exe --type=renderer --enable-dinosaur-easter-egg-a
12948	0.34GiB	C:\Users\B00830189\AppData\Local\anaconda3\envs\flower_tutorial\python.exe C:\Users\B00830189\AppDat
7636	0.26GiB	python main.py num_rounds=5
6672	0.26GiB	C:\Users\B00830189\AppData\Local\anaconda3\envs\flower_tutorial\python.exe C:\Users\B00830189\AppDat
9844	0.25GiB	C:\Users\B00830189\AppData\Local\anaconda3\envs\flower_tutorial\python.exe C:\Users\B00830189\AppDat
5420	0.25GiB	C:\Users\B00830189\AppData\Local\anaconda3\envs\flower_tutorial\python.exe C:\Users\B00830189\AppDat
10524	0.18GiB	C:\Users\B00830189\AppData\Local\anaconda3\envs\flower_tutorial\python.exe -c from multiprocessing.s
15292	0.14GiB	C:\Program Files\Google\Chrome\Application\chrome.exe --type=renderer --enable-dinosaur-easter-egg-a
7628	0.13GiB	C:\Users\B00830189\AppData\Local\Programs\Microsoft VS Code\Code.exe --type=renderer --user-data-dir

In addition, up to 0.0 GiB of shared memory is currently being used by the Ray object store.
---
--- Tip: Use the `ray memory` command to list active objects in the cluster.
--- To disable OOM exceptions, set RAY_DISABLE_MEMORY_MONITOR=1.
---
[2024-05-24 14:23:40,330][flwr][ERROR] - [36mray::launch_and_fit()[39m (pid=14596, ip=127.0.0.1)
  File "python\ray\_raylet.pyx", line 600, in ray._raylet.execute_task
  File "C:\Users\B00830189\AppData\Local\anaconda3\envs\flower_tutorial\lib\site-packages\ray\_private\memory_monitor.py", line 156, in raise_if_low_memory
    raise RayOutOfMemoryError(
ray._private.memory_monitor.RayOutOfMemoryError: More than 95% of the memory on node 2RWV8C3 is used (7.36 / 7.63 GB). The top 10 memory consumers are:

PID	MEM	COMMAND
9844	0.37GiB	C:\Users\B00830189\AppData\Local\anaconda3\envs\flower_tutorial\python.exe C:\Users\B00830189\AppDat
19108	0.34GiB	C:\Program Files\Google\Chrome\Application\chrome.exe --type=renderer --enable-dinosaur-easter-egg-a
6672	0.34GiB	C:\Users\B00830189\AppData\Local\anaconda3\envs\flower_tutorial\python.exe C:\Users\B00830189\AppDat
12948	0.34GiB	C:\Users\B00830189\AppData\Local\anaconda3\envs\flower_tutorial\python.exe C:\Users\B00830189\AppDat
1440	0.25GiB	C:\Users\B00830189\AppData\Local\anaconda3\envs\flower_tutorial\python.exe C:\Users\B00830189\AppDat
4704	0.24GiB	C:\Users\B00830189\AppData\Local\anaconda3\envs\flower_tutorial\python.exe C:\Users\B00830189\AppDat
7636	0.22GiB	python main.py num_rounds=5
3212	0.2GiB	C:\Users\B00830189\AppData\Local\Programs\Microsoft VS Code\Code.exe c:\Users\B00830189\.vscode\exte
7720	0.13GiB	C:\Program Files (x86)\Microsoft\EdgeWebView\Application\124.0.2478.97\msedgewebview2.exe --type=ren
15292	0.12GiB	C:\Program Files\Google\Chrome\Application\chrome.exe --type=renderer --enable-dinosaur-easter-egg-a

In addition, up to 0.0 GiB of shared memory is currently being used by the Ray object store.
---
--- Tip: Use the `ray memory` command to list active objects in the cluster.
--- To disable OOM exceptions, set RAY_DISABLE_MEMORY_MONITOR=1.
---
[2024-05-24 14:23:40,638][flwr][ERROR] - [36mray::launch_and_fit()[39m (pid=14596, ip=127.0.0.1)
  File "python\ray\_raylet.pyx", line 602, in ray._raylet.execute_task
  File "python\ray\_raylet.pyx", line 624, in ray._raylet.execute_task
  File "python\ray\_raylet.pyx", line 456, in ray._raylet.raise_if_dependency_failed
ray.exceptions.RaySystemError: System error: [WinError 1455] The paging file is too small for this operation to complete. Error loading "C:\Users\B00830189\AppData\Local\anaconda3\envs\flower_tutorial\lib\site-packages\torch\lib\shm.dll" or one of its dependencies.
traceback: Traceback (most recent call last):
  File "C:\Users\B00830189\AppData\Local\anaconda3\envs\flower_tutorial\lib\site-packages\ray\serialization.py", line 309, in deserialize_objects
    obj = self._deserialize_object(data, metadata, object_ref)
  File "C:\Users\B00830189\AppData\Local\anaconda3\envs\flower_tutorial\lib\site-packages\ray\serialization.py", line 215, in _deserialize_object
    return self._deserialize_msgpack_data(data, metadata_fields)
  File "C:\Users\B00830189\AppData\Local\anaconda3\envs\flower_tutorial\lib\site-packages\ray\serialization.py", line 174, in _deserialize_msgpack_data
    python_objects = self._deserialize_pickle5_data(pickle5_data)
  File "C:\Users\B00830189\AppData\Local\anaconda3\envs\flower_tutorial\lib\site-packages\ray\serialization.py", line 164, in _deserialize_pickle5_data
    obj = pickle.loads(in_band)
  File "C:\Users\B00830189\AppData\Local\anaconda3\envs\flower_tutorial\lib\site-packages\torch\__init__.py", line 128, in <module>
    raise err
OSError: [WinError 1455] The paging file is too small for this operation to complete. Error loading "C:\Users\B00830189\AppData\Local\anaconda3\envs\flower_tutorial\lib\site-packages\torch\lib\shm.dll" or one of its dependencies.
[2024-05-24 14:23:40,682][flwr][ERROR] - [36mray::launch_and_fit()[39m (pid=14596, ip=127.0.0.1)
  File "python\ray\_raylet.pyx", line 602, in ray._raylet.execute_task
  File "python\ray\_raylet.pyx", line 624, in ray._raylet.execute_task
  File "python\ray\_raylet.pyx", line 456, in ray._raylet.raise_if_dependency_failed
ray.exceptions.RaySystemError: System error: [WinError 1455] The paging file is too small for this operation to complete. Error loading "C:\Users\B00830189\AppData\Local\anaconda3\envs\flower_tutorial\lib\site-packages\torch\lib\shm.dll" or one of its dependencies.
traceback: Traceback (most recent call last):
  File "C:\Users\B00830189\AppData\Local\anaconda3\envs\flower_tutorial\lib\site-packages\ray\serialization.py", line 309, in deserialize_objects
    obj = self._deserialize_object(data, metadata, object_ref)
  File "C:\Users\B00830189\AppData\Local\anaconda3\envs\flower_tutorial\lib\site-packages\ray\serialization.py", line 215, in _deserialize_object
    return self._deserialize_msgpack_data(data, metadata_fields)
  File "C:\Users\B00830189\AppData\Local\anaconda3\envs\flower_tutorial\lib\site-packages\ray\serialization.py", line 174, in _deserialize_msgpack_data
    python_objects = self._deserialize_pickle5_data(pickle5_data)
  File "C:\Users\B00830189\AppData\Local\anaconda3\envs\flower_tutorial\lib\site-packages\ray\serialization.py", line 164, in _deserialize_pickle5_data
    obj = pickle.loads(in_band)
  File "C:\Users\B00830189\AppData\Local\anaconda3\envs\flower_tutorial\lib\site-packages\torch\__init__.py", line 128, in <module>
    raise err
OSError: [WinError 1455] The paging file is too small for this operation to complete. Error loading "C:\Users\B00830189\AppData\Local\anaconda3\envs\flower_tutorial\lib\site-packages\torch\lib\shm.dll" or one of its dependencies.
[2024-05-24 14:23:42,869][flwr][ERROR] - [36mray::launch_and_fit()[39m (pid=12948, ip=127.0.0.1)
  File "C:\Users\B00830189\AppData\Local\anaconda3\envs\flower_tutorial\lib\multiprocessing\queues.py", line 108, in get
    raise Empty
_queue.Empty

The above exception was the direct cause of the following exception:

[36mray::launch_and_fit()[39m (pid=12948, ip=127.0.0.1)
  File "python\ray\_raylet.pyx", line 633, in ray._raylet.execute_task
  File "python\ray\_raylet.pyx", line 674, in ray._raylet.execute_task
  File "python\ray\_raylet.pyx", line 640, in ray._raylet.execute_task
  File "python\ray\_raylet.pyx", line 644, in ray._raylet.execute_task
  File "C:\Users\B00830189\AppData\Local\anaconda3\envs\flower_tutorial\lib\site-packages\flwr\simulation\ray_transport\ray_client_proxy.py", line 148, in launch_and_fit
    return maybe_call_fit(
  File "C:\Users\B00830189\AppData\Local\anaconda3\envs\flower_tutorial\lib\site-packages\flwr\client\client.py", line 184, in maybe_call_fit
    return client.fit(fit_ins)
  File "C:\Users\B00830189\AppData\Local\anaconda3\envs\flower_tutorial\lib\site-packages\flwr\client\app.py", line 297, in _fit
    results = self.numpy_client.fit(parameters, ins.config)  # type: ignore
  File "C:\Users\B00830189\OneDrive - Ulster University\phd\Code\Demos\Flower\FlowerTutorial\client.py", line 48, in fit
    train(self.model, self.trainloader, optim, epochs, self.device) # Model no longer has weights sent my the server
  File "C:\Users\B00830189\OneDrive - Ulster University\phd\Code\Demos\Flower\FlowerTutorial\model.py", line 45, in train
    for images, labels in trainloader:
  File "C:\Users\B00830189\AppData\Local\anaconda3\envs\flower_tutorial\lib\site-packages\torch\utils\data\dataloader.py", line 628, in __next__
    data = self._next_data()
  File "C:\Users\B00830189\AppData\Local\anaconda3\envs\flower_tutorial\lib\site-packages\torch\utils\data\dataloader.py", line 1316, in _next_data
    idx, data = self._get_data()
  File "C:\Users\B00830189\AppData\Local\anaconda3\envs\flower_tutorial\lib\site-packages\torch\utils\data\dataloader.py", line 1282, in _get_data
    success, data = self._try_get_data()
  File "C:\Users\B00830189\AppData\Local\anaconda3\envs\flower_tutorial\lib\site-packages\torch\utils\data\dataloader.py", line 1133, in _try_get_data
    raise RuntimeError('DataLoader worker (pid(s) {}) exited unexpectedly'.format(pids_str)) from e
RuntimeError: DataLoader worker (pid(s) 17028, 18940) exited unexpectedly
[2024-05-24 14:23:42,988][flwr][ERROR] - [36mray::launch_and_fit()[39m (pid=6672, ip=127.0.0.1)
  File "C:\Users\B00830189\AppData\Local\anaconda3\envs\flower_tutorial\lib\multiprocessing\queues.py", line 108, in get
    raise Empty
_queue.Empty

The above exception was the direct cause of the following exception:

[36mray::launch_and_fit()[39m (pid=6672, ip=127.0.0.1)
  File "python\ray\_raylet.pyx", line 633, in ray._raylet.execute_task
  File "python\ray\_raylet.pyx", line 674, in ray._raylet.execute_task
  File "python\ray\_raylet.pyx", line 640, in ray._raylet.execute_task
  File "python\ray\_raylet.pyx", line 644, in ray._raylet.execute_task
  File "C:\Users\B00830189\AppData\Local\anaconda3\envs\flower_tutorial\lib\site-packages\flwr\simulation\ray_transport\ray_client_proxy.py", line 148, in launch_and_fit
    return maybe_call_fit(
  File "C:\Users\B00830189\AppData\Local\anaconda3\envs\flower_tutorial\lib\site-packages\flwr\client\client.py", line 184, in maybe_call_fit
    return client.fit(fit_ins)
  File "C:\Users\B00830189\AppData\Local\anaconda3\envs\flower_tutorial\lib\site-packages\flwr\client\app.py", line 297, in _fit
    results = self.numpy_client.fit(parameters, ins.config)  # type: ignore
  File "C:\Users\B00830189\OneDrive - Ulster University\phd\Code\Demos\Flower\FlowerTutorial\client.py", line 48, in fit
    train(self.model, self.trainloader, optim, epochs, self.device) # Model no longer has weights sent my the server
  File "C:\Users\B00830189\OneDrive - Ulster University\phd\Code\Demos\Flower\FlowerTutorial\model.py", line 45, in train
    for images, labels in trainloader:
  File "C:\Users\B00830189\AppData\Local\anaconda3\envs\flower_tutorial\lib\site-packages\torch\utils\data\dataloader.py", line 628, in __next__
    data = self._next_data()
  File "C:\Users\B00830189\AppData\Local\anaconda3\envs\flower_tutorial\lib\site-packages\torch\utils\data\dataloader.py", line 1316, in _next_data
    idx, data = self._get_data()
  File "C:\Users\B00830189\AppData\Local\anaconda3\envs\flower_tutorial\lib\site-packages\torch\utils\data\dataloader.py", line 1282, in _get_data
    success, data = self._try_get_data()
  File "C:\Users\B00830189\AppData\Local\anaconda3\envs\flower_tutorial\lib\site-packages\torch\utils\data\dataloader.py", line 1133, in _try_get_data
    raise RuntimeError('DataLoader worker (pid(s) {}) exited unexpectedly'.format(pids_str)) from e
RuntimeError: DataLoader worker (pid(s) 9108, 8292) exited unexpectedly
[2024-05-24 14:23:44,167][flwr][ERROR] - [36mray::launch_and_fit()[39m (pid=9844, ip=127.0.0.1)
  File "C:\Users\B00830189\AppData\Local\anaconda3\envs\flower_tutorial\lib\multiprocessing\queues.py", line 108, in get
    raise Empty
_queue.Empty

The above exception was the direct cause of the following exception:

[36mray::launch_and_fit()[39m (pid=9844, ip=127.0.0.1)
  File "python\ray\_raylet.pyx", line 633, in ray._raylet.execute_task
  File "python\ray\_raylet.pyx", line 674, in ray._raylet.execute_task
  File "python\ray\_raylet.pyx", line 640, in ray._raylet.execute_task
  File "python\ray\_raylet.pyx", line 644, in ray._raylet.execute_task
  File "C:\Users\B00830189\AppData\Local\anaconda3\envs\flower_tutorial\lib\site-packages\flwr\simulation\ray_transport\ray_client_proxy.py", line 148, in launch_and_fit
    return maybe_call_fit(
  File "C:\Users\B00830189\AppData\Local\anaconda3\envs\flower_tutorial\lib\site-packages\flwr\client\client.py", line 184, in maybe_call_fit
    return client.fit(fit_ins)
  File "C:\Users\B00830189\AppData\Local\anaconda3\envs\flower_tutorial\lib\site-packages\flwr\client\app.py", line 297, in _fit
    results = self.numpy_client.fit(parameters, ins.config)  # type: ignore
  File "C:\Users\B00830189\OneDrive - Ulster University\phd\Code\Demos\Flower\FlowerTutorial\client.py", line 48, in fit
    train(self.model, self.trainloader, optim, epochs, self.device) # Model no longer has weights sent my the server
  File "C:\Users\B00830189\OneDrive - Ulster University\phd\Code\Demos\Flower\FlowerTutorial\model.py", line 45, in train
    for images, labels in trainloader:
  File "C:\Users\B00830189\AppData\Local\anaconda3\envs\flower_tutorial\lib\site-packages\torch\utils\data\dataloader.py", line 628, in __next__
    data = self._next_data()
  File "C:\Users\B00830189\AppData\Local\anaconda3\envs\flower_tutorial\lib\site-packages\torch\utils\data\dataloader.py", line 1316, in _next_data
    idx, data = self._get_data()
  File "C:\Users\B00830189\AppData\Local\anaconda3\envs\flower_tutorial\lib\site-packages\torch\utils\data\dataloader.py", line 1282, in _get_data
    success, data = self._try_get_data()
  File "C:\Users\B00830189\AppData\Local\anaconda3\envs\flower_tutorial\lib\site-packages\torch\utils\data\dataloader.py", line 1133, in _try_get_data
    raise RuntimeError('DataLoader worker (pid(s) {}) exited unexpectedly'.format(pids_str)) from e
RuntimeError: DataLoader worker (pid(s) 10420, 788) exited unexpectedly
[2024-05-24 14:23:45,092][flwr][ERROR] - [36mray::launch_and_fit()[39m (pid=14596, ip=127.0.0.1)
  File "python\ray\_raylet.pyx", line 600, in ray._raylet.execute_task
  File "C:\Users\B00830189\AppData\Local\anaconda3\envs\flower_tutorial\lib\site-packages\ray\_private\memory_monitor.py", line 156, in raise_if_low_memory
    raise RayOutOfMemoryError(
ray._private.memory_monitor.RayOutOfMemoryError: More than 95% of the memory on node 2RWV8C3 is used (7.25 / 7.63 GB). The top 10 memory consumers are:

PID	MEM	COMMAND
4704	0.34GiB	C:\Users\B00830189\AppData\Local\anaconda3\envs\flower_tutorial\python.exe C:\Users\B00830189\AppDat
19108	0.32GiB	C:\Program Files\Google\Chrome\Application\chrome.exe --type=renderer --enable-dinosaur-easter-egg-a
9844	0.32GiB	C:\Users\B00830189\AppData\Local\anaconda3\envs\flower_tutorial\python.exe C:\Users\B00830189\AppDat
6672	0.29GiB	C:\Users\B00830189\AppData\Local\anaconda3\envs\flower_tutorial\python.exe C:\Users\B00830189\AppDat
12948	0.29GiB	C:\Users\B00830189\AppData\Local\anaconda3\envs\flower_tutorial\python.exe C:\Users\B00830189\AppDat
1440	0.25GiB	C:\Users\B00830189\AppData\Local\anaconda3\envs\flower_tutorial\python.exe C:\Users\B00830189\AppDat
7636	0.23GiB	python main.py num_rounds=5
14596	0.13GiB	C:\Users\B00830189\AppData\Local\anaconda3\envs\flower_tutorial\python.exe C:\Users\B00830189\AppDat
15292	0.12GiB	C:\Program Files\Google\Chrome\Application\chrome.exe --type=renderer --enable-dinosaur-easter-egg-a
9872	0.12GiB	C:\Users\B00830189\AppData\Local\anaconda3\envs\flower_tutorial\python.exe C:\Users\B00830189\AppDat

In addition, up to 0.0 GiB of shared memory is currently being used by the Ray object store.
---
--- Tip: Use the `ray memory` command to list active objects in the cluster.
--- To disable OOM exceptions, set RAY_DISABLE_MEMORY_MONITOR=1.
---
[2024-05-24 14:23:47,919][flwr][ERROR] - [36mray::launch_and_fit()[39m (pid=4704, ip=127.0.0.1)
  File "C:\Users\B00830189\AppData\Local\anaconda3\envs\flower_tutorial\lib\multiprocessing\queues.py", line 108, in get
    raise Empty
_queue.Empty

The above exception was the direct cause of the following exception:

[36mray::launch_and_fit()[39m (pid=4704, ip=127.0.0.1)
  File "python\ray\_raylet.pyx", line 633, in ray._raylet.execute_task
  File "python\ray\_raylet.pyx", line 674, in ray._raylet.execute_task
  File "python\ray\_raylet.pyx", line 640, in ray._raylet.execute_task
  File "python\ray\_raylet.pyx", line 644, in ray._raylet.execute_task
  File "C:\Users\B00830189\AppData\Local\anaconda3\envs\flower_tutorial\lib\site-packages\flwr\simulation\ray_transport\ray_client_proxy.py", line 148, in launch_and_fit
    return maybe_call_fit(
  File "C:\Users\B00830189\AppData\Local\anaconda3\envs\flower_tutorial\lib\site-packages\flwr\client\client.py", line 184, in maybe_call_fit
    return client.fit(fit_ins)
  File "C:\Users\B00830189\AppData\Local\anaconda3\envs\flower_tutorial\lib\site-packages\flwr\client\app.py", line 297, in _fit
    results = self.numpy_client.fit(parameters, ins.config)  # type: ignore
  File "C:\Users\B00830189\OneDrive - Ulster University\phd\Code\Demos\Flower\FlowerTutorial\client.py", line 48, in fit
    train(self.model, self.trainloader, optim, epochs, self.device) # Model no longer has weights sent my the server
  File "C:\Users\B00830189\OneDrive - Ulster University\phd\Code\Demos\Flower\FlowerTutorial\model.py", line 45, in train
    for images, labels in trainloader:
  File "C:\Users\B00830189\AppData\Local\anaconda3\envs\flower_tutorial\lib\site-packages\torch\utils\data\dataloader.py", line 628, in __next__
    data = self._next_data()
  File "C:\Users\B00830189\AppData\Local\anaconda3\envs\flower_tutorial\lib\site-packages\torch\utils\data\dataloader.py", line 1316, in _next_data
    idx, data = self._get_data()
  File "C:\Users\B00830189\AppData\Local\anaconda3\envs\flower_tutorial\lib\site-packages\torch\utils\data\dataloader.py", line 1282, in _get_data
    success, data = self._try_get_data()
  File "C:\Users\B00830189\AppData\Local\anaconda3\envs\flower_tutorial\lib\site-packages\torch\utils\data\dataloader.py", line 1133, in _try_get_data
    raise RuntimeError('DataLoader worker (pid(s) {}) exited unexpectedly'.format(pids_str)) from e
RuntimeError: DataLoader worker (pid(s) 11156, 10968) exited unexpectedly
[2024-05-24 14:23:47,925][flwr][DEBUG] - fit_round 1 received 0 results and 10 failures
[2024-05-24 14:23:50,776][flwr][INFO] - fit progress: (1, 181.93332147598267, {'accuracy': 0.0786}, 21.853323800000002)
[2024-05-24 14:23:50,777][flwr][DEBUG] - evaluate_round 1: strategy sampled 25 clients (out of 100)
[2024-05-24 14:23:51,397][flwr][ERROR] - [36mray::launch_and_evaluate()[39m (pid=14596, ip=127.0.0.1)
  File "python\ray\_raylet.pyx", line 602, in ray._raylet.execute_task
  File "python\ray\_raylet.pyx", line 624, in ray._raylet.execute_task
  File "python\ray\_raylet.pyx", line 456, in ray._raylet.raise_if_dependency_failed
ray.exceptions.RaySystemError: System error: [WinError 1455] The paging file is too small for this operation to complete. Error loading "C:\Users\B00830189\AppData\Local\anaconda3\envs\flower_tutorial\lib\site-packages\torch\lib\shm.dll" or one of its dependencies.
traceback: Traceback (most recent call last):
  File "C:\Users\B00830189\AppData\Local\anaconda3\envs\flower_tutorial\lib\site-packages\ray\serialization.py", line 309, in deserialize_objects
    obj = self._deserialize_object(data, metadata, object_ref)
  File "C:\Users\B00830189\AppData\Local\anaconda3\envs\flower_tutorial\lib\site-packages\ray\serialization.py", line 215, in _deserialize_object
    return self._deserialize_msgpack_data(data, metadata_fields)
  File "C:\Users\B00830189\AppData\Local\anaconda3\envs\flower_tutorial\lib\site-packages\ray\serialization.py", line 174, in _deserialize_msgpack_data
    python_objects = self._deserialize_pickle5_data(pickle5_data)
  File "C:\Users\B00830189\AppData\Local\anaconda3\envs\flower_tutorial\lib\site-packages\ray\serialization.py", line 164, in _deserialize_pickle5_data
    obj = pickle.loads(in_band)
  File "C:\Users\B00830189\AppData\Local\anaconda3\envs\flower_tutorial\lib\site-packages\torch\__init__.py", line 128, in <module>
    raise err
OSError: [WinError 1455] The paging file is too small for this operation to complete. Error loading "C:\Users\B00830189\AppData\Local\anaconda3\envs\flower_tutorial\lib\site-packages\torch\lib\shm.dll" or one of its dependencies.
[2024-05-24 14:23:51,541][flwr][ERROR] - [36mray::launch_and_evaluate()[39m (pid=14596, ip=127.0.0.1)
  File "python\ray\_raylet.pyx", line 602, in ray._raylet.execute_task
  File "python\ray\_raylet.pyx", line 624, in ray._raylet.execute_task
  File "python\ray\_raylet.pyx", line 456, in ray._raylet.raise_if_dependency_failed
ray.exceptions.RaySystemError: System error: [WinError 1455] The paging file is too small for this operation to complete. Error loading "C:\Users\B00830189\AppData\Local\anaconda3\envs\flower_tutorial\lib\site-packages\torch\lib\shm.dll" or one of its dependencies.
traceback: Traceback (most recent call last):
  File "C:\Users\B00830189\AppData\Local\anaconda3\envs\flower_tutorial\lib\site-packages\ray\serialization.py", line 309, in deserialize_objects
    obj = self._deserialize_object(data, metadata, object_ref)
  File "C:\Users\B00830189\AppData\Local\anaconda3\envs\flower_tutorial\lib\site-packages\ray\serialization.py", line 215, in _deserialize_object
    return self._deserialize_msgpack_data(data, metadata_fields)
  File "C:\Users\B00830189\AppData\Local\anaconda3\envs\flower_tutorial\lib\site-packages\ray\serialization.py", line 174, in _deserialize_msgpack_data
    python_objects = self._deserialize_pickle5_data(pickle5_data)
  File "C:\Users\B00830189\AppData\Local\anaconda3\envs\flower_tutorial\lib\site-packages\ray\serialization.py", line 164, in _deserialize_pickle5_data
    obj = pickle.loads(in_band)
  File "C:\Users\B00830189\AppData\Local\anaconda3\envs\flower_tutorial\lib\site-packages\torch\__init__.py", line 128, in <module>
    raise err
OSError: [WinError 1455] The paging file is too small for this operation to complete. Error loading "C:\Users\B00830189\AppData\Local\anaconda3\envs\flower_tutorial\lib\site-packages\torch\lib\shm.dll" or one of its dependencies.
[2024-05-24 14:23:51,694][flwr][ERROR] - [36mray::launch_and_evaluate()[39m (pid=14596, ip=127.0.0.1)
  File "python\ray\_raylet.pyx", line 602, in ray._raylet.execute_task
  File "python\ray\_raylet.pyx", line 624, in ray._raylet.execute_task
  File "python\ray\_raylet.pyx", line 456, in ray._raylet.raise_if_dependency_failed
ray.exceptions.RaySystemError: System error: [WinError 1455] The paging file is too small for this operation to complete. Error loading "C:\Users\B00830189\AppData\Local\anaconda3\envs\flower_tutorial\lib\site-packages\torch\lib\shm.dll" or one of its dependencies.
traceback: Traceback (most recent call last):
  File "C:\Users\B00830189\AppData\Local\anaconda3\envs\flower_tutorial\lib\site-packages\ray\serialization.py", line 309, in deserialize_objects
    obj = self._deserialize_object(data, metadata, object_ref)
  File "C:\Users\B00830189\AppData\Local\anaconda3\envs\flower_tutorial\lib\site-packages\ray\serialization.py", line 215, in _deserialize_object
    return self._deserialize_msgpack_data(data, metadata_fields)
  File "C:\Users\B00830189\AppData\Local\anaconda3\envs\flower_tutorial\lib\site-packages\ray\serialization.py", line 174, in _deserialize_msgpack_data
    python_objects = self._deserialize_pickle5_data(pickle5_data)
  File "C:\Users\B00830189\AppData\Local\anaconda3\envs\flower_tutorial\lib\site-packages\ray\serialization.py", line 164, in _deserialize_pickle5_data
    obj = pickle.loads(in_band)
  File "C:\Users\B00830189\AppData\Local\anaconda3\envs\flower_tutorial\lib\site-packages\torch\__init__.py", line 128, in <module>
    raise err
OSError: [WinError 1455] The paging file is too small for this operation to complete. Error loading "C:\Users\B00830189\AppData\Local\anaconda3\envs\flower_tutorial\lib\site-packages\torch\lib\shm.dll" or one of its dependencies.
[2024-05-24 14:23:52,037][flwr][ERROR] - [36mray::launch_and_evaluate()[39m (pid=14596, ip=127.0.0.1)
  File "python\ray\_raylet.pyx", line 602, in ray._raylet.execute_task
  File "python\ray\_raylet.pyx", line 624, in ray._raylet.execute_task
  File "python\ray\_raylet.pyx", line 456, in ray._raylet.raise_if_dependency_failed
ray.exceptions.RaySystemError: System error: [WinError 1455] The paging file is too small for this operation to complete. Error loading "C:\Users\B00830189\AppData\Local\anaconda3\envs\flower_tutorial\lib\site-packages\torch\lib\shm.dll" or one of its dependencies.
traceback: Traceback (most recent call last):
  File "C:\Users\B00830189\AppData\Local\anaconda3\envs\flower_tutorial\lib\site-packages\ray\serialization.py", line 309, in deserialize_objects
    obj = self._deserialize_object(data, metadata, object_ref)
  File "C:\Users\B00830189\AppData\Local\anaconda3\envs\flower_tutorial\lib\site-packages\ray\serialization.py", line 215, in _deserialize_object
    return self._deserialize_msgpack_data(data, metadata_fields)
  File "C:\Users\B00830189\AppData\Local\anaconda3\envs\flower_tutorial\lib\site-packages\ray\serialization.py", line 174, in _deserialize_msgpack_data
    python_objects = self._deserialize_pickle5_data(pickle5_data)
  File "C:\Users\B00830189\AppData\Local\anaconda3\envs\flower_tutorial\lib\site-packages\ray\serialization.py", line 164, in _deserialize_pickle5_data
    obj = pickle.loads(in_band)
  File "C:\Users\B00830189\AppData\Local\anaconda3\envs\flower_tutorial\lib\site-packages\torch\__init__.py", line 128, in <module>
    raise err
OSError: [WinError 1455] The paging file is too small for this operation to complete. Error loading "C:\Users\B00830189\AppData\Local\anaconda3\envs\flower_tutorial\lib\site-packages\torch\lib\shm.dll" or one of its dependencies.
[2024-05-24 14:23:52,537][flwr][ERROR] - [36mray::launch_and_evaluate()[39m (pid=14596, ip=127.0.0.1)
  File "python\ray\_raylet.pyx", line 602, in ray._raylet.execute_task
  File "python\ray\_raylet.pyx", line 624, in ray._raylet.execute_task
  File "python\ray\_raylet.pyx", line 456, in ray._raylet.raise_if_dependency_failed
ray.exceptions.RaySystemError: System error: [WinError 1455] The paging file is too small for this operation to complete. Error loading "C:\Users\B00830189\AppData\Local\anaconda3\envs\flower_tutorial\lib\site-packages\torch\lib\shm.dll" or one of its dependencies.
traceback: Traceback (most recent call last):
  File "C:\Users\B00830189\AppData\Local\anaconda3\envs\flower_tutorial\lib\site-packages\ray\serialization.py", line 309, in deserialize_objects
    obj = self._deserialize_object(data, metadata, object_ref)
  File "C:\Users\B00830189\AppData\Local\anaconda3\envs\flower_tutorial\lib\site-packages\ray\serialization.py", line 215, in _deserialize_object
    return self._deserialize_msgpack_data(data, metadata_fields)
  File "C:\Users\B00830189\AppData\Local\anaconda3\envs\flower_tutorial\lib\site-packages\ray\serialization.py", line 174, in _deserialize_msgpack_data
    python_objects = self._deserialize_pickle5_data(pickle5_data)
  File "C:\Users\B00830189\AppData\Local\anaconda3\envs\flower_tutorial\lib\site-packages\ray\serialization.py", line 164, in _deserialize_pickle5_data
    obj = pickle.loads(in_band)
  File "C:\Users\B00830189\AppData\Local\anaconda3\envs\flower_tutorial\lib\site-packages\torch\__init__.py", line 128, in <module>
    raise err
OSError: [WinError 1455] The paging file is too small for this operation to complete. Error loading "C:\Users\B00830189\AppData\Local\anaconda3\envs\flower_tutorial\lib\site-packages\torch\lib\shm.dll" or one of its dependencies.
[2024-05-24 14:23:52,731][flwr][ERROR] - [36mray::launch_and_evaluate()[39m (pid=14596, ip=127.0.0.1)
  File "python\ray\_raylet.pyx", line 602, in ray._raylet.execute_task
  File "python\ray\_raylet.pyx", line 624, in ray._raylet.execute_task
  File "python\ray\_raylet.pyx", line 456, in ray._raylet.raise_if_dependency_failed
ray.exceptions.RaySystemError: System error: [WinError 1455] The paging file is too small for this operation to complete. Error loading "C:\Users\B00830189\AppData\Local\anaconda3\envs\flower_tutorial\lib\site-packages\torch\lib\shm.dll" or one of its dependencies.
traceback: Traceback (most recent call last):
  File "C:\Users\B00830189\AppData\Local\anaconda3\envs\flower_tutorial\lib\site-packages\ray\serialization.py", line 309, in deserialize_objects
    obj = self._deserialize_object(data, metadata, object_ref)
  File "C:\Users\B00830189\AppData\Local\anaconda3\envs\flower_tutorial\lib\site-packages\ray\serialization.py", line 215, in _deserialize_object
    return self._deserialize_msgpack_data(data, metadata_fields)
  File "C:\Users\B00830189\AppData\Local\anaconda3\envs\flower_tutorial\lib\site-packages\ray\serialization.py", line 174, in _deserialize_msgpack_data
    python_objects = self._deserialize_pickle5_data(pickle5_data)
  File "C:\Users\B00830189\AppData\Local\anaconda3\envs\flower_tutorial\lib\site-packages\ray\serialization.py", line 164, in _deserialize_pickle5_data
    obj = pickle.loads(in_band)
  File "C:\Users\B00830189\AppData\Local\anaconda3\envs\flower_tutorial\lib\site-packages\torch\__init__.py", line 128, in <module>
    raise err
OSError: [WinError 1455] The paging file is too small for this operation to complete. Error loading "C:\Users\B00830189\AppData\Local\anaconda3\envs\flower_tutorial\lib\site-packages\torch\lib\shm.dll" or one of its dependencies.
[2024-05-24 14:23:53,216][flwr][ERROR] - [36mray::launch_and_evaluate()[39m (pid=14596, ip=127.0.0.1)
  File "python\ray\_raylet.pyx", line 602, in ray._raylet.execute_task
  File "python\ray\_raylet.pyx", line 624, in ray._raylet.execute_task
  File "python\ray\_raylet.pyx", line 456, in ray._raylet.raise_if_dependency_failed
ray.exceptions.RaySystemError: System error: [WinError 1455] The paging file is too small for this operation to complete. Error loading "C:\Users\B00830189\AppData\Local\anaconda3\envs\flower_tutorial\lib\site-packages\torch\lib\shm.dll" or one of its dependencies.
traceback: Traceback (most recent call last):
  File "C:\Users\B00830189\AppData\Local\anaconda3\envs\flower_tutorial\lib\site-packages\ray\serialization.py", line 309, in deserialize_objects
    obj = self._deserialize_object(data, metadata, object_ref)
  File "C:\Users\B00830189\AppData\Local\anaconda3\envs\flower_tutorial\lib\site-packages\ray\serialization.py", line 215, in _deserialize_object
    return self._deserialize_msgpack_data(data, metadata_fields)
  File "C:\Users\B00830189\AppData\Local\anaconda3\envs\flower_tutorial\lib\site-packages\ray\serialization.py", line 174, in _deserialize_msgpack_data
    python_objects = self._deserialize_pickle5_data(pickle5_data)
  File "C:\Users\B00830189\AppData\Local\anaconda3\envs\flower_tutorial\lib\site-packages\ray\serialization.py", line 164, in _deserialize_pickle5_data
    obj = pickle.loads(in_band)
  File "C:\Users\B00830189\AppData\Local\anaconda3\envs\flower_tutorial\lib\site-packages\torch\__init__.py", line 128, in <module>
    raise err
OSError: [WinError 1455] The paging file is too small for this operation to complete. Error loading "C:\Users\B00830189\AppData\Local\anaconda3\envs\flower_tutorial\lib\site-packages\torch\lib\shm.dll" or one of its dependencies.
[2024-05-24 14:23:53,557][flwr][ERROR] - [36mray::launch_and_evaluate()[39m (pid=14596, ip=127.0.0.1)
  File "python\ray\_raylet.pyx", line 602, in ray._raylet.execute_task
  File "python\ray\_raylet.pyx", line 624, in ray._raylet.execute_task
  File "python\ray\_raylet.pyx", line 456, in ray._raylet.raise_if_dependency_failed
ray.exceptions.RaySystemError: System error: [WinError 1455] The paging file is too small for this operation to complete. Error loading "C:\Users\B00830189\AppData\Local\anaconda3\envs\flower_tutorial\lib\site-packages\torch\lib\shm.dll" or one of its dependencies.
traceback: Traceback (most recent call last):
  File "C:\Users\B00830189\AppData\Local\anaconda3\envs\flower_tutorial\lib\site-packages\ray\serialization.py", line 309, in deserialize_objects
    obj = self._deserialize_object(data, metadata, object_ref)
  File "C:\Users\B00830189\AppData\Local\anaconda3\envs\flower_tutorial\lib\site-packages\ray\serialization.py", line 215, in _deserialize_object
    return self._deserialize_msgpack_data(data, metadata_fields)
  File "C:\Users\B00830189\AppData\Local\anaconda3\envs\flower_tutorial\lib\site-packages\ray\serialization.py", line 174, in _deserialize_msgpack_data
    python_objects = self._deserialize_pickle5_data(pickle5_data)
  File "C:\Users\B00830189\AppData\Local\anaconda3\envs\flower_tutorial\lib\site-packages\ray\serialization.py", line 164, in _deserialize_pickle5_data
    obj = pickle.loads(in_band)
  File "C:\Users\B00830189\AppData\Local\anaconda3\envs\flower_tutorial\lib\site-packages\torch\__init__.py", line 128, in <module>
    raise err
OSError: [WinError 1455] The paging file is too small for this operation to complete. Error loading "C:\Users\B00830189\AppData\Local\anaconda3\envs\flower_tutorial\lib\site-packages\torch\lib\shm.dll" or one of its dependencies.
[2024-05-24 14:23:53,828][flwr][ERROR] - [36mray::launch_and_evaluate()[39m (pid=14596, ip=127.0.0.1)
  File "python\ray\_raylet.pyx", line 602, in ray._raylet.execute_task
  File "python\ray\_raylet.pyx", line 624, in ray._raylet.execute_task
  File "python\ray\_raylet.pyx", line 456, in ray._raylet.raise_if_dependency_failed
ray.exceptions.RaySystemError: System error: [WinError 1455] The paging file is too small for this operation to complete. Error loading "C:\Users\B00830189\AppData\Local\anaconda3\envs\flower_tutorial\lib\site-packages\torch\lib\shm.dll" or one of its dependencies.
traceback: Traceback (most recent call last):
  File "C:\Users\B00830189\AppData\Local\anaconda3\envs\flower_tutorial\lib\site-packages\ray\serialization.py", line 309, in deserialize_objects
    obj = self._deserialize_object(data, metadata, object_ref)
  File "C:\Users\B00830189\AppData\Local\anaconda3\envs\flower_tutorial\lib\site-packages\ray\serialization.py", line 215, in _deserialize_object
    return self._deserialize_msgpack_data(data, metadata_fields)
  File "C:\Users\B00830189\AppData\Local\anaconda3\envs\flower_tutorial\lib\site-packages\ray\serialization.py", line 174, in _deserialize_msgpack_data
    python_objects = self._deserialize_pickle5_data(pickle5_data)
  File "C:\Users\B00830189\AppData\Local\anaconda3\envs\flower_tutorial\lib\site-packages\ray\serialization.py", line 164, in _deserialize_pickle5_data
    obj = pickle.loads(in_band)
  File "C:\Users\B00830189\AppData\Local\anaconda3\envs\flower_tutorial\lib\site-packages\torch\__init__.py", line 128, in <module>
    raise err
OSError: [WinError 1455] The paging file is too small for this operation to complete. Error loading "C:\Users\B00830189\AppData\Local\anaconda3\envs\flower_tutorial\lib\site-packages\torch\lib\shm.dll" or one of its dependencies.
[2024-05-24 14:23:54,995][flwr][ERROR] - [36mray::launch_and_evaluate()[39m (pid=14596, ip=127.0.0.1)
  File "python\ray\_raylet.pyx", line 602, in ray._raylet.execute_task
  File "python\ray\_raylet.pyx", line 624, in ray._raylet.execute_task
  File "python\ray\_raylet.pyx", line 456, in ray._raylet.raise_if_dependency_failed
ray.exceptions.RaySystemError: System error: [WinError 1455] The paging file is too small for this operation to complete. Error loading "C:\Users\B00830189\AppData\Local\anaconda3\envs\flower_tutorial\lib\site-packages\torch\lib\shm.dll" or one of its dependencies.
traceback: Traceback (most recent call last):
  File "C:\Users\B00830189\AppData\Local\anaconda3\envs\flower_tutorial\lib\site-packages\ray\serialization.py", line 309, in deserialize_objects
    obj = self._deserialize_object(data, metadata, object_ref)
  File "C:\Users\B00830189\AppData\Local\anaconda3\envs\flower_tutorial\lib\site-packages\ray\serialization.py", line 215, in _deserialize_object
    return self._deserialize_msgpack_data(data, metadata_fields)
  File "C:\Users\B00830189\AppData\Local\anaconda3\envs\flower_tutorial\lib\site-packages\ray\serialization.py", line 174, in _deserialize_msgpack_data
    python_objects = self._deserialize_pickle5_data(pickle5_data)
  File "C:\Users\B00830189\AppData\Local\anaconda3\envs\flower_tutorial\lib\site-packages\ray\serialization.py", line 164, in _deserialize_pickle5_data
    obj = pickle.loads(in_band)
  File "C:\Users\B00830189\AppData\Local\anaconda3\envs\flower_tutorial\lib\site-packages\torch\__init__.py", line 128, in <module>
    raise err
OSError: [WinError 1455] The paging file is too small for this operation to complete. Error loading "C:\Users\B00830189\AppData\Local\anaconda3\envs\flower_tutorial\lib\site-packages\torch\lib\shm.dll" or one of its dependencies.
[2024-05-24 14:23:57,176][flwr][ERROR] - [36mray::launch_and_evaluate()[39m (pid=4704, ip=127.0.0.1)
  File "C:\Users\B00830189\AppData\Local\anaconda3\envs\flower_tutorial\lib\multiprocessing\queues.py", line 108, in get
    raise Empty
_queue.Empty

The above exception was the direct cause of the following exception:

[36mray::launch_and_evaluate()[39m (pid=4704, ip=127.0.0.1)
  File "python\ray\_raylet.pyx", line 633, in ray._raylet.execute_task
  File "python\ray\_raylet.pyx", line 674, in ray._raylet.execute_task
  File "python\ray\_raylet.pyx", line 640, in ray._raylet.execute_task
  File "python\ray\_raylet.pyx", line 644, in ray._raylet.execute_task
  File "C:\Users\B00830189\AppData\Local\anaconda3\envs\flower_tutorial\lib\site-packages\flwr\simulation\ray_transport\ray_client_proxy.py", line 160, in launch_and_evaluate
    return maybe_call_evaluate(
  File "C:\Users\B00830189\AppData\Local\anaconda3\envs\flower_tutorial\lib\site-packages\flwr\client\client.py", line 205, in maybe_call_evaluate
    return client.evaluate(evaluate_ins)
  File "C:\Users\B00830189\AppData\Local\anaconda3\envs\flower_tutorial\lib\site-packages\flwr\client\app.py", line 321, in _evaluate
    results = self.numpy_client.evaluate(parameters, ins.config)  # type: ignore
  File "C:\Users\B00830189\OneDrive - Ulster University\phd\Code\Demos\Flower\FlowerTutorial\client.py", line 55, in evaluate
    loss, accuracy = test(self.model, self.valloader, self.device)
  File "C:\Users\B00830189\OneDrive - Ulster University\phd\Code\Demos\Flower\FlowerTutorial\model.py", line 63, in test
    for data in testloader:
  File "C:\Users\B00830189\AppData\Local\anaconda3\envs\flower_tutorial\lib\site-packages\torch\utils\data\dataloader.py", line 628, in __next__
    data = self._next_data()
  File "C:\Users\B00830189\AppData\Local\anaconda3\envs\flower_tutorial\lib\site-packages\torch\utils\data\dataloader.py", line 1316, in _next_data
    idx, data = self._get_data()
  File "C:\Users\B00830189\AppData\Local\anaconda3\envs\flower_tutorial\lib\site-packages\torch\utils\data\dataloader.py", line 1282, in _get_data
    success, data = self._try_get_data()
  File "C:\Users\B00830189\AppData\Local\anaconda3\envs\flower_tutorial\lib\site-packages\torch\utils\data\dataloader.py", line 1133, in _try_get_data
    raise RuntimeError('DataLoader worker (pid(s) {}) exited unexpectedly'.format(pids_str)) from e
RuntimeError: DataLoader worker (pid(s) 12276) exited unexpectedly
[2024-05-24 14:23:59,446][flwr][ERROR] - [36mray::launch_and_evaluate()[39m (pid=9844, ip=127.0.0.1)
  File "C:\Users\B00830189\AppData\Local\anaconda3\envs\flower_tutorial\lib\multiprocessing\queues.py", line 108, in get
    raise Empty
_queue.Empty

The above exception was the direct cause of the following exception:

[36mray::launch_and_evaluate()[39m (pid=9844, ip=127.0.0.1)
  File "python\ray\_raylet.pyx", line 633, in ray._raylet.execute_task
  File "python\ray\_raylet.pyx", line 674, in ray._raylet.execute_task
  File "python\ray\_raylet.pyx", line 640, in ray._raylet.execute_task
  File "python\ray\_raylet.pyx", line 644, in ray._raylet.execute_task
  File "C:\Users\B00830189\AppData\Local\anaconda3\envs\flower_tutorial\lib\site-packages\flwr\simulation\ray_transport\ray_client_proxy.py", line 160, in launch_and_evaluate
    return maybe_call_evaluate(
  File "C:\Users\B00830189\AppData\Local\anaconda3\envs\flower_tutorial\lib\site-packages\flwr\client\client.py", line 205, in maybe_call_evaluate
    return client.evaluate(evaluate_ins)
  File "C:\Users\B00830189\AppData\Local\anaconda3\envs\flower_tutorial\lib\site-packages\flwr\client\app.py", line 321, in _evaluate
    results = self.numpy_client.evaluate(parameters, ins.config)  # type: ignore
  File "C:\Users\B00830189\OneDrive - Ulster University\phd\Code\Demos\Flower\FlowerTutorial\client.py", line 55, in evaluate
    loss, accuracy = test(self.model, self.valloader, self.device)
  File "C:\Users\B00830189\OneDrive - Ulster University\phd\Code\Demos\Flower\FlowerTutorial\model.py", line 63, in test
    for data in testloader:
  File "C:\Users\B00830189\AppData\Local\anaconda3\envs\flower_tutorial\lib\site-packages\torch\utils\data\dataloader.py", line 628, in __next__
    data = self._next_data()
  File "C:\Users\B00830189\AppData\Local\anaconda3\envs\flower_tutorial\lib\site-packages\torch\utils\data\dataloader.py", line 1316, in _next_data
    idx, data = self._get_data()
  File "C:\Users\B00830189\AppData\Local\anaconda3\envs\flower_tutorial\lib\site-packages\torch\utils\data\dataloader.py", line 1282, in _get_data
    success, data = self._try_get_data()
  File "C:\Users\B00830189\AppData\Local\anaconda3\envs\flower_tutorial\lib\site-packages\torch\utils\data\dataloader.py", line 1133, in _try_get_data
    raise RuntimeError('DataLoader worker (pid(s) {}) exited unexpectedly'.format(pids_str)) from e
RuntimeError: DataLoader worker (pid(s) 18292, 8764) exited unexpectedly
[2024-05-24 14:23:59,508][flwr][ERROR] - [36mray::launch_and_evaluate()[39m (pid=6672, ip=127.0.0.1)
  File "C:\Users\B00830189\AppData\Local\anaconda3\envs\flower_tutorial\lib\multiprocessing\queues.py", line 108, in get
    raise Empty
_queue.Empty

The above exception was the direct cause of the following exception:

[36mray::launch_and_evaluate()[39m (pid=6672, ip=127.0.0.1)
  File "python\ray\_raylet.pyx", line 633, in ray._raylet.execute_task
  File "python\ray\_raylet.pyx", line 674, in ray._raylet.execute_task
  File "python\ray\_raylet.pyx", line 640, in ray._raylet.execute_task
  File "python\ray\_raylet.pyx", line 644, in ray._raylet.execute_task
  File "C:\Users\B00830189\AppData\Local\anaconda3\envs\flower_tutorial\lib\site-packages\flwr\simulation\ray_transport\ray_client_proxy.py", line 160, in launch_and_evaluate
    return maybe_call_evaluate(
  File "C:\Users\B00830189\AppData\Local\anaconda3\envs\flower_tutorial\lib\site-packages\flwr\client\client.py", line 205, in maybe_call_evaluate
    return client.evaluate(evaluate_ins)
  File "C:\Users\B00830189\AppData\Local\anaconda3\envs\flower_tutorial\lib\site-packages\flwr\client\app.py", line 321, in _evaluate
    results = self.numpy_client.evaluate(parameters, ins.config)  # type: ignore
  File "C:\Users\B00830189\OneDrive - Ulster University\phd\Code\Demos\Flower\FlowerTutorial\client.py", line 55, in evaluate
    loss, accuracy = test(self.model, self.valloader, self.device)
  File "C:\Users\B00830189\OneDrive - Ulster University\phd\Code\Demos\Flower\FlowerTutorial\model.py", line 63, in test
    for data in testloader:
  File "C:\Users\B00830189\AppData\Local\anaconda3\envs\flower_tutorial\lib\site-packages\torch\utils\data\dataloader.py", line 628, in __next__
    data = self._next_data()
  File "C:\Users\B00830189\AppData\Local\anaconda3\envs\flower_tutorial\lib\site-packages\torch\utils\data\dataloader.py", line 1316, in _next_data
    idx, data = self._get_data()
  File "C:\Users\B00830189\AppData\Local\anaconda3\envs\flower_tutorial\lib\site-packages\torch\utils\data\dataloader.py", line 1282, in _get_data
    success, data = self._try_get_data()
  File "C:\Users\B00830189\AppData\Local\anaconda3\envs\flower_tutorial\lib\site-packages\torch\utils\data\dataloader.py", line 1133, in _try_get_data
    raise RuntimeError('DataLoader worker (pid(s) {}) exited unexpectedly'.format(pids_str)) from e
RuntimeError: DataLoader worker (pid(s) 7756, 16576) exited unexpectedly
[2024-05-24 14:24:03,173][flwr][ERROR] - [36mray::launch_and_evaluate()[39m (pid=14596, ip=127.0.0.1)
  File "python\ray\_raylet.pyx", line 602, in ray._raylet.execute_task
  File "python\ray\_raylet.pyx", line 624, in ray._raylet.execute_task
  File "python\ray\_raylet.pyx", line 456, in ray._raylet.raise_if_dependency_failed
ray.exceptions.RaySystemError: System error: [WinError 1455] The paging file is too small for this operation to complete. Error loading "C:\Users\B00830189\AppData\Local\anaconda3\envs\flower_tutorial\lib\site-packages\torch\lib\shm.dll" or one of its dependencies.
traceback: Traceback (most recent call last):
  File "C:\Users\B00830189\AppData\Local\anaconda3\envs\flower_tutorial\lib\site-packages\ray\serialization.py", line 309, in deserialize_objects
    obj = self._deserialize_object(data, metadata, object_ref)
  File "C:\Users\B00830189\AppData\Local\anaconda3\envs\flower_tutorial\lib\site-packages\ray\serialization.py", line 215, in _deserialize_object
    return self._deserialize_msgpack_data(data, metadata_fields)
  File "C:\Users\B00830189\AppData\Local\anaconda3\envs\flower_tutorial\lib\site-packages\ray\serialization.py", line 174, in _deserialize_msgpack_data
    python_objects = self._deserialize_pickle5_data(pickle5_data)
  File "C:\Users\B00830189\AppData\Local\anaconda3\envs\flower_tutorial\lib\site-packages\ray\serialization.py", line 164, in _deserialize_pickle5_data
    obj = pickle.loads(in_band)
  File "C:\Users\B00830189\AppData\Local\anaconda3\envs\flower_tutorial\lib\site-packages\torch\__init__.py", line 128, in <module>
    raise err
OSError: [WinError 1455] The paging file is too small for this operation to complete. Error loading "C:\Users\B00830189\AppData\Local\anaconda3\envs\flower_tutorial\lib\site-packages\torch\lib\shm.dll" or one of its dependencies.
[2024-05-24 14:24:03,202][flwr][ERROR] - [36mray::launch_and_evaluate()[39m (pid=14596, ip=127.0.0.1)
  File "python\ray\_raylet.pyx", line 602, in ray._raylet.execute_task
  File "python\ray\_raylet.pyx", line 624, in ray._raylet.execute_task
  File "python\ray\_raylet.pyx", line 456, in ray._raylet.raise_if_dependency_failed
ray.exceptions.RaySystemError: System error: [WinError 1455] The paging file is too small for this operation to complete. Error loading "C:\Users\B00830189\AppData\Local\anaconda3\envs\flower_tutorial\lib\site-packages\torch\lib\shm.dll" or one of its dependencies.
traceback: Traceback (most recent call last):
  File "C:\Users\B00830189\AppData\Local\anaconda3\envs\flower_tutorial\lib\site-packages\ray\serialization.py", line 309, in deserialize_objects
    obj = self._deserialize_object(data, metadata, object_ref)
  File "C:\Users\B00830189\AppData\Local\anaconda3\envs\flower_tutorial\lib\site-packages\ray\serialization.py", line 215, in _deserialize_object
    return self._deserialize_msgpack_data(data, metadata_fields)
  File "C:\Users\B00830189\AppData\Local\anaconda3\envs\flower_tutorial\lib\site-packages\ray\serialization.py", line 174, in _deserialize_msgpack_data
    python_objects = self._deserialize_pickle5_data(pickle5_data)
  File "C:\Users\B00830189\AppData\Local\anaconda3\envs\flower_tutorial\lib\site-packages\ray\serialization.py", line 164, in _deserialize_pickle5_data
    obj = pickle.loads(in_band)
  File "C:\Users\B00830189\AppData\Local\anaconda3\envs\flower_tutorial\lib\site-packages\torch\__init__.py", line 128, in <module>
    raise err
OSError: [WinError 1455] The paging file is too small for this operation to complete. Error loading "C:\Users\B00830189\AppData\Local\anaconda3\envs\flower_tutorial\lib\site-packages\torch\lib\shm.dll" or one of its dependencies.
[2024-05-24 14:24:04,658][flwr][ERROR] - [36mray::launch_and_evaluate()[39m (pid=14596, ip=127.0.0.1)
  File "python\ray\_raylet.pyx", line 602, in ray._raylet.execute_task
  File "python\ray\_raylet.pyx", line 624, in ray._raylet.execute_task
  File "python\ray\_raylet.pyx", line 456, in ray._raylet.raise_if_dependency_failed
ray.exceptions.RaySystemError: System error: [WinError 1455] The paging file is too small for this operation to complete. Error loading "C:\Users\B00830189\AppData\Local\anaconda3\envs\flower_tutorial\lib\site-packages\torch\lib\shm.dll" or one of its dependencies.
traceback: Traceback (most recent call last):
  File "C:\Users\B00830189\AppData\Local\anaconda3\envs\flower_tutorial\lib\site-packages\ray\serialization.py", line 309, in deserialize_objects
    obj = self._deserialize_object(data, metadata, object_ref)
  File "C:\Users\B00830189\AppData\Local\anaconda3\envs\flower_tutorial\lib\site-packages\ray\serialization.py", line 215, in _deserialize_object
    return self._deserialize_msgpack_data(data, metadata_fields)
  File "C:\Users\B00830189\AppData\Local\anaconda3\envs\flower_tutorial\lib\site-packages\ray\serialization.py", line 174, in _deserialize_msgpack_data
    python_objects = self._deserialize_pickle5_data(pickle5_data)
  File "C:\Users\B00830189\AppData\Local\anaconda3\envs\flower_tutorial\lib\site-packages\ray\serialization.py", line 164, in _deserialize_pickle5_data
    obj = pickle.loads(in_band)
  File "C:\Users\B00830189\AppData\Local\anaconda3\envs\flower_tutorial\lib\site-packages\torch\__init__.py", line 128, in <module>
    raise err
OSError: [WinError 1455] The paging file is too small for this operation to complete. Error loading "C:\Users\B00830189\AppData\Local\anaconda3\envs\flower_tutorial\lib\site-packages\torch\lib\shm.dll" or one of its dependencies.
[2024-05-24 14:24:04,754][flwr][ERROR] - [36mray::launch_and_evaluate()[39m (pid=14596, ip=127.0.0.1)
  File "python\ray\_raylet.pyx", line 602, in ray._raylet.execute_task
  File "python\ray\_raylet.pyx", line 624, in ray._raylet.execute_task
  File "python\ray\_raylet.pyx", line 456, in ray._raylet.raise_if_dependency_failed
ray.exceptions.RaySystemError: System error: [WinError 1455] The paging file is too small for this operation to complete. Error loading "C:\Users\B00830189\AppData\Local\anaconda3\envs\flower_tutorial\lib\site-packages\torch\lib\shm.dll" or one of its dependencies.
traceback: Traceback (most recent call last):
  File "C:\Users\B00830189\AppData\Local\anaconda3\envs\flower_tutorial\lib\site-packages\ray\serialization.py", line 309, in deserialize_objects
    obj = self._deserialize_object(data, metadata, object_ref)
  File "C:\Users\B00830189\AppData\Local\anaconda3\envs\flower_tutorial\lib\site-packages\ray\serialization.py", line 215, in _deserialize_object
    return self._deserialize_msgpack_data(data, metadata_fields)
  File "C:\Users\B00830189\AppData\Local\anaconda3\envs\flower_tutorial\lib\site-packages\ray\serialization.py", line 174, in _deserialize_msgpack_data
    python_objects = self._deserialize_pickle5_data(pickle5_data)
  File "C:\Users\B00830189\AppData\Local\anaconda3\envs\flower_tutorial\lib\site-packages\ray\serialization.py", line 164, in _deserialize_pickle5_data
    obj = pickle.loads(in_band)
  File "C:\Users\B00830189\AppData\Local\anaconda3\envs\flower_tutorial\lib\site-packages\torch\__init__.py", line 128, in <module>
    raise err
OSError: [WinError 1455] The paging file is too small for this operation to complete. Error loading "C:\Users\B00830189\AppData\Local\anaconda3\envs\flower_tutorial\lib\site-packages\torch\lib\shm.dll" or one of its dependencies.
[2024-05-24 14:24:04,828][flwr][ERROR] - [36mray::launch_and_evaluate()[39m (pid=14596, ip=127.0.0.1)
  File "python\ray\_raylet.pyx", line 602, in ray._raylet.execute_task
  File "python\ray\_raylet.pyx", line 624, in ray._raylet.execute_task
  File "python\ray\_raylet.pyx", line 456, in ray._raylet.raise_if_dependency_failed
ray.exceptions.RaySystemError: System error: [WinError 1455] The paging file is too small for this operation to complete. Error loading "C:\Users\B00830189\AppData\Local\anaconda3\envs\flower_tutorial\lib\site-packages\torch\lib\shm.dll" or one of its dependencies.
traceback: Traceback (most recent call last):
  File "C:\Users\B00830189\AppData\Local\anaconda3\envs\flower_tutorial\lib\site-packages\ray\serialization.py", line 309, in deserialize_objects
    obj = self._deserialize_object(data, metadata, object_ref)
  File "C:\Users\B00830189\AppData\Local\anaconda3\envs\flower_tutorial\lib\site-packages\ray\serialization.py", line 215, in _deserialize_object
    return self._deserialize_msgpack_data(data, metadata_fields)
  File "C:\Users\B00830189\AppData\Local\anaconda3\envs\flower_tutorial\lib\site-packages\ray\serialization.py", line 174, in _deserialize_msgpack_data
    python_objects = self._deserialize_pickle5_data(pickle5_data)
  File "C:\Users\B00830189\AppData\Local\anaconda3\envs\flower_tutorial\lib\site-packages\ray\serialization.py", line 164, in _deserialize_pickle5_data
    obj = pickle.loads(in_band)
  File "C:\Users\B00830189\AppData\Local\anaconda3\envs\flower_tutorial\lib\site-packages\torch\__init__.py", line 128, in <module>
    raise err
OSError: [WinError 1455] The paging file is too small for this operation to complete. Error loading "C:\Users\B00830189\AppData\Local\anaconda3\envs\flower_tutorial\lib\site-packages\torch\lib\shm.dll" or one of its dependencies.
[2024-05-24 14:24:05,731][flwr][ERROR] - [36mray::launch_and_evaluate()[39m (pid=6672, ip=127.0.0.1)
  File "C:\Users\B00830189\AppData\Local\anaconda3\envs\flower_tutorial\lib\multiprocessing\queues.py", line 108, in get
    raise Empty
_queue.Empty

The above exception was the direct cause of the following exception:

[36mray::launch_and_evaluate()[39m (pid=6672, ip=127.0.0.1)
  File "python\ray\_raylet.pyx", line 633, in ray._raylet.execute_task
  File "python\ray\_raylet.pyx", line 674, in ray._raylet.execute_task
  File "python\ray\_raylet.pyx", line 640, in ray._raylet.execute_task
  File "python\ray\_raylet.pyx", line 644, in ray._raylet.execute_task
  File "C:\Users\B00830189\AppData\Local\anaconda3\envs\flower_tutorial\lib\site-packages\flwr\simulation\ray_transport\ray_client_proxy.py", line 160, in launch_and_evaluate
    return maybe_call_evaluate(
  File "C:\Users\B00830189\AppData\Local\anaconda3\envs\flower_tutorial\lib\site-packages\flwr\client\client.py", line 205, in maybe_call_evaluate
    return client.evaluate(evaluate_ins)
  File "C:\Users\B00830189\AppData\Local\anaconda3\envs\flower_tutorial\lib\site-packages\flwr\client\app.py", line 321, in _evaluate
    results = self.numpy_client.evaluate(parameters, ins.config)  # type: ignore
  File "C:\Users\B00830189\OneDrive - Ulster University\phd\Code\Demos\Flower\FlowerTutorial\client.py", line 55, in evaluate
    loss, accuracy = test(self.model, self.valloader, self.device)
  File "C:\Users\B00830189\OneDrive - Ulster University\phd\Code\Demos\Flower\FlowerTutorial\model.py", line 63, in test
    for data in testloader:
  File "C:\Users\B00830189\AppData\Local\anaconda3\envs\flower_tutorial\lib\site-packages\torch\utils\data\dataloader.py", line 628, in __next__
    data = self._next_data()
  File "C:\Users\B00830189\AppData\Local\anaconda3\envs\flower_tutorial\lib\site-packages\torch\utils\data\dataloader.py", line 1316, in _next_data
    idx, data = self._get_data()
  File "C:\Users\B00830189\AppData\Local\anaconda3\envs\flower_tutorial\lib\site-packages\torch\utils\data\dataloader.py", line 1282, in _get_data
    success, data = self._try_get_data()
  File "C:\Users\B00830189\AppData\Local\anaconda3\envs\flower_tutorial\lib\site-packages\torch\utils\data\dataloader.py", line 1133, in _try_get_data
    raise RuntimeError('DataLoader worker (pid(s) {}) exited unexpectedly'.format(pids_str)) from e
RuntimeError: DataLoader worker (pid(s) 6728, 2668) exited unexpectedly
[2024-05-24 14:24:05,951][flwr][ERROR] - [36mray::launch_and_evaluate()[39m (pid=9844, ip=127.0.0.1)
  File "C:\Users\B00830189\AppData\Local\anaconda3\envs\flower_tutorial\lib\multiprocessing\queues.py", line 108, in get
    raise Empty
_queue.Empty

The above exception was the direct cause of the following exception:

[36mray::launch_and_evaluate()[39m (pid=9844, ip=127.0.0.1)
  File "python\ray\_raylet.pyx", line 633, in ray._raylet.execute_task
  File "python\ray\_raylet.pyx", line 674, in ray._raylet.execute_task
  File "python\ray\_raylet.pyx", line 640, in ray._raylet.execute_task
  File "python\ray\_raylet.pyx", line 644, in ray._raylet.execute_task
  File "C:\Users\B00830189\AppData\Local\anaconda3\envs\flower_tutorial\lib\site-packages\flwr\simulation\ray_transport\ray_client_proxy.py", line 160, in launch_and_evaluate
    return maybe_call_evaluate(
  File "C:\Users\B00830189\AppData\Local\anaconda3\envs\flower_tutorial\lib\site-packages\flwr\client\client.py", line 205, in maybe_call_evaluate
    return client.evaluate(evaluate_ins)
  File "C:\Users\B00830189\AppData\Local\anaconda3\envs\flower_tutorial\lib\site-packages\flwr\client\app.py", line 321, in _evaluate
    results = self.numpy_client.evaluate(parameters, ins.config)  # type: ignore
  File "C:\Users\B00830189\OneDrive - Ulster University\phd\Code\Demos\Flower\FlowerTutorial\client.py", line 55, in evaluate
    loss, accuracy = test(self.model, self.valloader, self.device)
  File "C:\Users\B00830189\OneDrive - Ulster University\phd\Code\Demos\Flower\FlowerTutorial\model.py", line 63, in test
    for data in testloader:
  File "C:\Users\B00830189\AppData\Local\anaconda3\envs\flower_tutorial\lib\site-packages\torch\utils\data\dataloader.py", line 628, in __next__
    data = self._next_data()
  File "C:\Users\B00830189\AppData\Local\anaconda3\envs\flower_tutorial\lib\site-packages\torch\utils\data\dataloader.py", line 1316, in _next_data
    idx, data = self._get_data()
  File "C:\Users\B00830189\AppData\Local\anaconda3\envs\flower_tutorial\lib\site-packages\torch\utils\data\dataloader.py", line 1282, in _get_data
    success, data = self._try_get_data()
  File "C:\Users\B00830189\AppData\Local\anaconda3\envs\flower_tutorial\lib\site-packages\torch\utils\data\dataloader.py", line 1133, in _try_get_data
    raise RuntimeError('DataLoader worker (pid(s) {}) exited unexpectedly'.format(pids_str)) from e
RuntimeError: DataLoader worker (pid(s) 18416, 8740) exited unexpectedly
[2024-05-24 14:24:06,405][flwr][ERROR] - [36mray::launch_and_evaluate()[39m (pid=4704, ip=127.0.0.1)
  File "C:\Users\B00830189\AppData\Local\anaconda3\envs\flower_tutorial\lib\multiprocessing\queues.py", line 108, in get
    raise Empty
_queue.Empty

The above exception was the direct cause of the following exception:

[36mray::launch_and_evaluate()[39m (pid=4704, ip=127.0.0.1)
  File "python\ray\_raylet.pyx", line 633, in ray._raylet.execute_task
  File "python\ray\_raylet.pyx", line 674, in ray._raylet.execute_task
  File "python\ray\_raylet.pyx", line 640, in ray._raylet.execute_task
  File "python\ray\_raylet.pyx", line 644, in ray._raylet.execute_task
  File "C:\Users\B00830189\AppData\Local\anaconda3\envs\flower_tutorial\lib\site-packages\flwr\simulation\ray_transport\ray_client_proxy.py", line 160, in launch_and_evaluate
    return maybe_call_evaluate(
  File "C:\Users\B00830189\AppData\Local\anaconda3\envs\flower_tutorial\lib\site-packages\flwr\client\client.py", line 205, in maybe_call_evaluate
    return client.evaluate(evaluate_ins)
  File "C:\Users\B00830189\AppData\Local\anaconda3\envs\flower_tutorial\lib\site-packages\flwr\client\app.py", line 321, in _evaluate
    results = self.numpy_client.evaluate(parameters, ins.config)  # type: ignore
  File "C:\Users\B00830189\OneDrive - Ulster University\phd\Code\Demos\Flower\FlowerTutorial\client.py", line 55, in evaluate
    loss, accuracy = test(self.model, self.valloader, self.device)
  File "C:\Users\B00830189\OneDrive - Ulster University\phd\Code\Demos\Flower\FlowerTutorial\model.py", line 63, in test
    for data in testloader:
  File "C:\Users\B00830189\AppData\Local\anaconda3\envs\flower_tutorial\lib\site-packages\torch\utils\data\dataloader.py", line 628, in __next__
    data = self._next_data()
  File "C:\Users\B00830189\AppData\Local\anaconda3\envs\flower_tutorial\lib\site-packages\torch\utils\data\dataloader.py", line 1316, in _next_data
    idx, data = self._get_data()
  File "C:\Users\B00830189\AppData\Local\anaconda3\envs\flower_tutorial\lib\site-packages\torch\utils\data\dataloader.py", line 1282, in _get_data
    success, data = self._try_get_data()
  File "C:\Users\B00830189\AppData\Local\anaconda3\envs\flower_tutorial\lib\site-packages\torch\utils\data\dataloader.py", line 1133, in _try_get_data
    raise RuntimeError('DataLoader worker (pid(s) {}) exited unexpectedly'.format(pids_str)) from e
RuntimeError: DataLoader worker (pid(s) 3428, 17420) exited unexpectedly
[2024-05-24 14:24:09,018][flwr][ERROR] - [36mray::launch_and_evaluate()[39m (pid=12948, ip=127.0.0.1)
  File "C:\Users\B00830189\AppData\Local\anaconda3\envs\flower_tutorial\lib\multiprocessing\queues.py", line 108, in get
    raise Empty
_queue.Empty

The above exception was the direct cause of the following exception:

[36mray::launch_and_evaluate()[39m (pid=12948, ip=127.0.0.1)
  File "python\ray\_raylet.pyx", line 633, in ray._raylet.execute_task
  File "python\ray\_raylet.pyx", line 674, in ray._raylet.execute_task
  File "python\ray\_raylet.pyx", line 640, in ray._raylet.execute_task
  File "python\ray\_raylet.pyx", line 644, in ray._raylet.execute_task
  File "C:\Users\B00830189\AppData\Local\anaconda3\envs\flower_tutorial\lib\site-packages\flwr\simulation\ray_transport\ray_client_proxy.py", line 160, in launch_and_evaluate
    return maybe_call_evaluate(
  File "C:\Users\B00830189\AppData\Local\anaconda3\envs\flower_tutorial\lib\site-packages\flwr\client\client.py", line 205, in maybe_call_evaluate
    return client.evaluate(evaluate_ins)
  File "C:\Users\B00830189\AppData\Local\anaconda3\envs\flower_tutorial\lib\site-packages\flwr\client\app.py", line 321, in _evaluate
    results = self.numpy_client.evaluate(parameters, ins.config)  # type: ignore
  File "C:\Users\B00830189\OneDrive - Ulster University\phd\Code\Demos\Flower\FlowerTutorial\client.py", line 55, in evaluate
    loss, accuracy = test(self.model, self.valloader, self.device)
  File "C:\Users\B00830189\OneDrive - Ulster University\phd\Code\Demos\Flower\FlowerTutorial\model.py", line 63, in test
    for data in testloader:
  File "C:\Users\B00830189\AppData\Local\anaconda3\envs\flower_tutorial\lib\site-packages\torch\utils\data\dataloader.py", line 628, in __next__
    data = self._next_data()
  File "C:\Users\B00830189\AppData\Local\anaconda3\envs\flower_tutorial\lib\site-packages\torch\utils\data\dataloader.py", line 1316, in _next_data
    idx, data = self._get_data()
  File "C:\Users\B00830189\AppData\Local\anaconda3\envs\flower_tutorial\lib\site-packages\torch\utils\data\dataloader.py", line 1282, in _get_data
    success, data = self._try_get_data()
  File "C:\Users\B00830189\AppData\Local\anaconda3\envs\flower_tutorial\lib\site-packages\torch\utils\data\dataloader.py", line 1133, in _try_get_data
    raise RuntimeError('DataLoader worker (pid(s) {}) exited unexpectedly'.format(pids_str)) from e
RuntimeError: DataLoader worker (pid(s) 9436, 11964) exited unexpectedly
[2024-05-24 14:24:11,189][flwr][ERROR] - [36mray::launch_and_evaluate()[39m (pid=6672, ip=127.0.0.1)
  File "C:\Users\B00830189\AppData\Local\anaconda3\envs\flower_tutorial\lib\multiprocessing\queues.py", line 108, in get
    raise Empty
_queue.Empty

The above exception was the direct cause of the following exception:

[36mray::launch_and_evaluate()[39m (pid=6672, ip=127.0.0.1)
  File "python\ray\_raylet.pyx", line 633, in ray._raylet.execute_task
  File "python\ray\_raylet.pyx", line 674, in ray._raylet.execute_task
  File "python\ray\_raylet.pyx", line 640, in ray._raylet.execute_task
  File "python\ray\_raylet.pyx", line 644, in ray._raylet.execute_task
  File "C:\Users\B00830189\AppData\Local\anaconda3\envs\flower_tutorial\lib\site-packages\flwr\simulation\ray_transport\ray_client_proxy.py", line 160, in launch_and_evaluate
    return maybe_call_evaluate(
  File "C:\Users\B00830189\AppData\Local\anaconda3\envs\flower_tutorial\lib\site-packages\flwr\client\client.py", line 205, in maybe_call_evaluate
    return client.evaluate(evaluate_ins)
  File "C:\Users\B00830189\AppData\Local\anaconda3\envs\flower_tutorial\lib\site-packages\flwr\client\app.py", line 321, in _evaluate
    results = self.numpy_client.evaluate(parameters, ins.config)  # type: ignore
  File "C:\Users\B00830189\OneDrive - Ulster University\phd\Code\Demos\Flower\FlowerTutorial\client.py", line 55, in evaluate
    loss, accuracy = test(self.model, self.valloader, self.device)
  File "C:\Users\B00830189\OneDrive - Ulster University\phd\Code\Demos\Flower\FlowerTutorial\model.py", line 63, in test
    for data in testloader:
  File "C:\Users\B00830189\AppData\Local\anaconda3\envs\flower_tutorial\lib\site-packages\torch\utils\data\dataloader.py", line 628, in __next__
    data = self._next_data()
  File "C:\Users\B00830189\AppData\Local\anaconda3\envs\flower_tutorial\lib\site-packages\torch\utils\data\dataloader.py", line 1316, in _next_data
    idx, data = self._get_data()
  File "C:\Users\B00830189\AppData\Local\anaconda3\envs\flower_tutorial\lib\site-packages\torch\utils\data\dataloader.py", line 1282, in _get_data
    success, data = self._try_get_data()
  File "C:\Users\B00830189\AppData\Local\anaconda3\envs\flower_tutorial\lib\site-packages\torch\utils\data\dataloader.py", line 1133, in _try_get_data
    raise RuntimeError('DataLoader worker (pid(s) {}) exited unexpectedly'.format(pids_str)) from e
RuntimeError: DataLoader worker (pid(s) 13328, 10136) exited unexpectedly
[2024-05-24 14:24:11,405][flwr][ERROR] - [36mray::launch_and_evaluate()[39m (pid=9844, ip=127.0.0.1)
  File "C:\Users\B00830189\AppData\Local\anaconda3\envs\flower_tutorial\lib\multiprocessing\queues.py", line 108, in get
    raise Empty
_queue.Empty

The above exception was the direct cause of the following exception:

[36mray::launch_and_evaluate()[39m (pid=9844, ip=127.0.0.1)
  File "python\ray\_raylet.pyx", line 633, in ray._raylet.execute_task
  File "python\ray\_raylet.pyx", line 674, in ray._raylet.execute_task
  File "python\ray\_raylet.pyx", line 640, in ray._raylet.execute_task
  File "python\ray\_raylet.pyx", line 644, in ray._raylet.execute_task
  File "C:\Users\B00830189\AppData\Local\anaconda3\envs\flower_tutorial\lib\site-packages\flwr\simulation\ray_transport\ray_client_proxy.py", line 160, in launch_and_evaluate
    return maybe_call_evaluate(
  File "C:\Users\B00830189\AppData\Local\anaconda3\envs\flower_tutorial\lib\site-packages\flwr\client\client.py", line 205, in maybe_call_evaluate
    return client.evaluate(evaluate_ins)
  File "C:\Users\B00830189\AppData\Local\anaconda3\envs\flower_tutorial\lib\site-packages\flwr\client\app.py", line 321, in _evaluate
    results = self.numpy_client.evaluate(parameters, ins.config)  # type: ignore
  File "C:\Users\B00830189\OneDrive - Ulster University\phd\Code\Demos\Flower\FlowerTutorial\client.py", line 55, in evaluate
    loss, accuracy = test(self.model, self.valloader, self.device)
  File "C:\Users\B00830189\OneDrive - Ulster University\phd\Code\Demos\Flower\FlowerTutorial\model.py", line 63, in test
    for data in testloader:
  File "C:\Users\B00830189\AppData\Local\anaconda3\envs\flower_tutorial\lib\site-packages\torch\utils\data\dataloader.py", line 628, in __next__
    data = self._next_data()
  File "C:\Users\B00830189\AppData\Local\anaconda3\envs\flower_tutorial\lib\site-packages\torch\utils\data\dataloader.py", line 1316, in _next_data
    idx, data = self._get_data()
  File "C:\Users\B00830189\AppData\Local\anaconda3\envs\flower_tutorial\lib\site-packages\torch\utils\data\dataloader.py", line 1282, in _get_data
    success, data = self._try_get_data()
  File "C:\Users\B00830189\AppData\Local\anaconda3\envs\flower_tutorial\lib\site-packages\torch\utils\data\dataloader.py", line 1133, in _try_get_data
    raise RuntimeError('DataLoader worker (pid(s) {}) exited unexpectedly'.format(pids_str)) from e
RuntimeError: DataLoader worker (pid(s) 18820, 2172) exited unexpectedly
[2024-05-24 14:24:12,041][flwr][ERROR] - [36mray::launch_and_evaluate()[39m (pid=4704, ip=127.0.0.1)
  File "C:\Users\B00830189\AppData\Local\anaconda3\envs\flower_tutorial\lib\multiprocessing\queues.py", line 108, in get
    raise Empty
_queue.Empty

The above exception was the direct cause of the following exception:

[36mray::launch_and_evaluate()[39m (pid=4704, ip=127.0.0.1)
  File "python\ray\_raylet.pyx", line 633, in ray._raylet.execute_task
  File "python\ray\_raylet.pyx", line 674, in ray._raylet.execute_task
  File "python\ray\_raylet.pyx", line 640, in ray._raylet.execute_task
  File "python\ray\_raylet.pyx", line 644, in ray._raylet.execute_task
  File "C:\Users\B00830189\AppData\Local\anaconda3\envs\flower_tutorial\lib\site-packages\flwr\simulation\ray_transport\ray_client_proxy.py", line 160, in launch_and_evaluate
    return maybe_call_evaluate(
  File "C:\Users\B00830189\AppData\Local\anaconda3\envs\flower_tutorial\lib\site-packages\flwr\client\client.py", line 205, in maybe_call_evaluate
    return client.evaluate(evaluate_ins)
  File "C:\Users\B00830189\AppData\Local\anaconda3\envs\flower_tutorial\lib\site-packages\flwr\client\app.py", line 321, in _evaluate
    results = self.numpy_client.evaluate(parameters, ins.config)  # type: ignore
  File "C:\Users\B00830189\OneDrive - Ulster University\phd\Code\Demos\Flower\FlowerTutorial\client.py", line 55, in evaluate
    loss, accuracy = test(self.model, self.valloader, self.device)
  File "C:\Users\B00830189\OneDrive - Ulster University\phd\Code\Demos\Flower\FlowerTutorial\model.py", line 63, in test
    for data in testloader:
  File "C:\Users\B00830189\AppData\Local\anaconda3\envs\flower_tutorial\lib\site-packages\torch\utils\data\dataloader.py", line 628, in __next__
    data = self._next_data()
  File "C:\Users\B00830189\AppData\Local\anaconda3\envs\flower_tutorial\lib\site-packages\torch\utils\data\dataloader.py", line 1316, in _next_data
    idx, data = self._get_data()
  File "C:\Users\B00830189\AppData\Local\anaconda3\envs\flower_tutorial\lib\site-packages\torch\utils\data\dataloader.py", line 1282, in _get_data
    success, data = self._try_get_data()
  File "C:\Users\B00830189\AppData\Local\anaconda3\envs\flower_tutorial\lib\site-packages\torch\utils\data\dataloader.py", line 1133, in _try_get_data
    raise RuntimeError('DataLoader worker (pid(s) {}) exited unexpectedly'.format(pids_str)) from e
RuntimeError: DataLoader worker (pid(s) 14836, 11456) exited unexpectedly
[2024-05-24 14:24:12,047][flwr][DEBUG] - evaluate_round 1 received 0 results and 25 failures
[2024-05-24 14:24:12,049][flwr][DEBUG] - fit_round 2: strategy sampled 10 clients (out of 100)
[2024-05-24 14:24:13,623][flwr][ERROR] - [36mray::launch_and_fit()[39m (pid=14596, ip=127.0.0.1)
  File "python\ray\_raylet.pyx", line 602, in ray._raylet.execute_task
  File "python\ray\_raylet.pyx", line 624, in ray._raylet.execute_task
  File "python\ray\_raylet.pyx", line 456, in ray._raylet.raise_if_dependency_failed
ray.exceptions.RaySystemError: System error: [WinError 1455] The paging file is too small for this operation to complete. Error loading "C:\Users\B00830189\AppData\Local\anaconda3\envs\flower_tutorial\lib\site-packages\torch\lib\shm.dll" or one of its dependencies.
traceback: Traceback (most recent call last):
  File "C:\Users\B00830189\AppData\Local\anaconda3\envs\flower_tutorial\lib\site-packages\ray\serialization.py", line 309, in deserialize_objects
    obj = self._deserialize_object(data, metadata, object_ref)
  File "C:\Users\B00830189\AppData\Local\anaconda3\envs\flower_tutorial\lib\site-packages\ray\serialization.py", line 215, in _deserialize_object
    return self._deserialize_msgpack_data(data, metadata_fields)
  File "C:\Users\B00830189\AppData\Local\anaconda3\envs\flower_tutorial\lib\site-packages\ray\serialization.py", line 174, in _deserialize_msgpack_data
    python_objects = self._deserialize_pickle5_data(pickle5_data)
  File "C:\Users\B00830189\AppData\Local\anaconda3\envs\flower_tutorial\lib\site-packages\ray\serialization.py", line 164, in _deserialize_pickle5_data
    obj = pickle.loads(in_band)
  File "C:\Users\B00830189\AppData\Local\anaconda3\envs\flower_tutorial\lib\site-packages\torch\__init__.py", line 128, in <module>
    raise err
OSError: [WinError 1455] The paging file is too small for this operation to complete. Error loading "C:\Users\B00830189\AppData\Local\anaconda3\envs\flower_tutorial\lib\site-packages\torch\lib\shm.dll" or one of its dependencies.
[2024-05-24 14:24:15,157][flwr][ERROR] - [36mray::launch_and_fit()[39m (pid=14596, ip=127.0.0.1)
  File "python\ray\_raylet.pyx", line 602, in ray._raylet.execute_task
  File "python\ray\_raylet.pyx", line 624, in ray._raylet.execute_task
  File "python\ray\_raylet.pyx", line 456, in ray._raylet.raise_if_dependency_failed
ray.exceptions.RaySystemError: System error: [WinError 1455] The paging file is too small for this operation to complete. Error loading "C:\Users\B00830189\AppData\Local\anaconda3\envs\flower_tutorial\lib\site-packages\torch\lib\shm.dll" or one of its dependencies.
traceback: Traceback (most recent call last):
  File "C:\Users\B00830189\AppData\Local\anaconda3\envs\flower_tutorial\lib\site-packages\ray\serialization.py", line 309, in deserialize_objects
    obj = self._deserialize_object(data, metadata, object_ref)
  File "C:\Users\B00830189\AppData\Local\anaconda3\envs\flower_tutorial\lib\site-packages\ray\serialization.py", line 215, in _deserialize_object
    return self._deserialize_msgpack_data(data, metadata_fields)
  File "C:\Users\B00830189\AppData\Local\anaconda3\envs\flower_tutorial\lib\site-packages\ray\serialization.py", line 174, in _deserialize_msgpack_data
    python_objects = self._deserialize_pickle5_data(pickle5_data)
  File "C:\Users\B00830189\AppData\Local\anaconda3\envs\flower_tutorial\lib\site-packages\ray\serialization.py", line 164, in _deserialize_pickle5_data
    obj = pickle.loads(in_band)
  File "C:\Users\B00830189\AppData\Local\anaconda3\envs\flower_tutorial\lib\site-packages\torch\__init__.py", line 128, in <module>
    raise err
OSError: [WinError 1455] The paging file is too small for this operation to complete. Error loading "C:\Users\B00830189\AppData\Local\anaconda3\envs\flower_tutorial\lib\site-packages\torch\lib\shm.dll" or one of its dependencies.
[2024-05-24 14:24:17,307][flwr][ERROR] - [36mray::launch_and_fit()[39m (pid=14596, ip=127.0.0.1)
  File "python\ray\_raylet.pyx", line 602, in ray._raylet.execute_task
  File "python\ray\_raylet.pyx", line 624, in ray._raylet.execute_task
  File "python\ray\_raylet.pyx", line 456, in ray._raylet.raise_if_dependency_failed
ray.exceptions.RaySystemError: System error: [WinError 1455] The paging file is too small for this operation to complete. Error loading "C:\Users\B00830189\AppData\Local\anaconda3\envs\flower_tutorial\lib\site-packages\torch\lib\shm.dll" or one of its dependencies.
traceback: Traceback (most recent call last):
  File "C:\Users\B00830189\AppData\Local\anaconda3\envs\flower_tutorial\lib\site-packages\ray\serialization.py", line 309, in deserialize_objects
    obj = self._deserialize_object(data, metadata, object_ref)
  File "C:\Users\B00830189\AppData\Local\anaconda3\envs\flower_tutorial\lib\site-packages\ray\serialization.py", line 215, in _deserialize_object
    return self._deserialize_msgpack_data(data, metadata_fields)
  File "C:\Users\B00830189\AppData\Local\anaconda3\envs\flower_tutorial\lib\site-packages\ray\serialization.py", line 174, in _deserialize_msgpack_data
    python_objects = self._deserialize_pickle5_data(pickle5_data)
  File "C:\Users\B00830189\AppData\Local\anaconda3\envs\flower_tutorial\lib\site-packages\ray\serialization.py", line 164, in _deserialize_pickle5_data
    obj = pickle.loads(in_band)
  File "C:\Users\B00830189\AppData\Local\anaconda3\envs\flower_tutorial\lib\site-packages\torch\__init__.py", line 128, in <module>
    raise err
OSError: [WinError 1455] The paging file is too small for this operation to complete. Error loading "C:\Users\B00830189\AppData\Local\anaconda3\envs\flower_tutorial\lib\site-packages\torch\lib\shm.dll" or one of its dependencies.
[2024-05-24 14:24:17,394][flwr][ERROR] - [36mray::launch_and_fit()[39m (pid=14596, ip=127.0.0.1)
  File "python\ray\_raylet.pyx", line 602, in ray._raylet.execute_task
  File "python\ray\_raylet.pyx", line 624, in ray._raylet.execute_task
  File "python\ray\_raylet.pyx", line 456, in ray._raylet.raise_if_dependency_failed
ray.exceptions.RaySystemError: System error: [WinError 1455] The paging file is too small for this operation to complete. Error loading "C:\Users\B00830189\AppData\Local\anaconda3\envs\flower_tutorial\lib\site-packages\torch\lib\shm.dll" or one of its dependencies.
traceback: Traceback (most recent call last):
  File "C:\Users\B00830189\AppData\Local\anaconda3\envs\flower_tutorial\lib\site-packages\ray\serialization.py", line 309, in deserialize_objects
    obj = self._deserialize_object(data, metadata, object_ref)
  File "C:\Users\B00830189\AppData\Local\anaconda3\envs\flower_tutorial\lib\site-packages\ray\serialization.py", line 215, in _deserialize_object
    return self._deserialize_msgpack_data(data, metadata_fields)
  File "C:\Users\B00830189\AppData\Local\anaconda3\envs\flower_tutorial\lib\site-packages\ray\serialization.py", line 174, in _deserialize_msgpack_data
    python_objects = self._deserialize_pickle5_data(pickle5_data)
  File "C:\Users\B00830189\AppData\Local\anaconda3\envs\flower_tutorial\lib\site-packages\ray\serialization.py", line 164, in _deserialize_pickle5_data
    obj = pickle.loads(in_band)
  File "C:\Users\B00830189\AppData\Local\anaconda3\envs\flower_tutorial\lib\site-packages\torch\__init__.py", line 128, in <module>
    raise err
OSError: [WinError 1455] The paging file is too small for this operation to complete. Error loading "C:\Users\B00830189\AppData\Local\anaconda3\envs\flower_tutorial\lib\site-packages\torch\lib\shm.dll" or one of its dependencies.
[2024-05-24 14:24:17,463][flwr][ERROR] - [36mray::launch_and_fit()[39m (pid=14596, ip=127.0.0.1)
  File "python\ray\_raylet.pyx", line 602, in ray._raylet.execute_task
  File "python\ray\_raylet.pyx", line 624, in ray._raylet.execute_task
  File "python\ray\_raylet.pyx", line 456, in ray._raylet.raise_if_dependency_failed
ray.exceptions.RaySystemError: System error: [WinError 1455] The paging file is too small for this operation to complete. Error loading "C:\Users\B00830189\AppData\Local\anaconda3\envs\flower_tutorial\lib\site-packages\torch\lib\shm.dll" or one of its dependencies.
traceback: Traceback (most recent call last):
  File "C:\Users\B00830189\AppData\Local\anaconda3\envs\flower_tutorial\lib\site-packages\ray\serialization.py", line 309, in deserialize_objects
    obj = self._deserialize_object(data, metadata, object_ref)
  File "C:\Users\B00830189\AppData\Local\anaconda3\envs\flower_tutorial\lib\site-packages\ray\serialization.py", line 215, in _deserialize_object
    return self._deserialize_msgpack_data(data, metadata_fields)
  File "C:\Users\B00830189\AppData\Local\anaconda3\envs\flower_tutorial\lib\site-packages\ray\serialization.py", line 174, in _deserialize_msgpack_data
    python_objects = self._deserialize_pickle5_data(pickle5_data)
  File "C:\Users\B00830189\AppData\Local\anaconda3\envs\flower_tutorial\lib\site-packages\ray\serialization.py", line 164, in _deserialize_pickle5_data
    obj = pickle.loads(in_band)
  File "C:\Users\B00830189\AppData\Local\anaconda3\envs\flower_tutorial\lib\site-packages\torch\__init__.py", line 128, in <module>
    raise err
OSError: [WinError 1455] The paging file is too small for this operation to complete. Error loading "C:\Users\B00830189\AppData\Local\anaconda3\envs\flower_tutorial\lib\site-packages\torch\lib\shm.dll" or one of its dependencies.
[2024-05-24 14:24:18,588][flwr][ERROR] - [36mray::launch_and_fit()[39m (pid=9844, ip=127.0.0.1)
  File "C:\Users\B00830189\AppData\Local\anaconda3\envs\flower_tutorial\lib\multiprocessing\queues.py", line 108, in get
    raise Empty
_queue.Empty

The above exception was the direct cause of the following exception:

[36mray::launch_and_fit()[39m (pid=9844, ip=127.0.0.1)
  File "python\ray\_raylet.pyx", line 633, in ray._raylet.execute_task
  File "python\ray\_raylet.pyx", line 674, in ray._raylet.execute_task
  File "python\ray\_raylet.pyx", line 640, in ray._raylet.execute_task
  File "python\ray\_raylet.pyx", line 644, in ray._raylet.execute_task
  File "C:\Users\B00830189\AppData\Local\anaconda3\envs\flower_tutorial\lib\site-packages\flwr\simulation\ray_transport\ray_client_proxy.py", line 148, in launch_and_fit
    return maybe_call_fit(
  File "C:\Users\B00830189\AppData\Local\anaconda3\envs\flower_tutorial\lib\site-packages\flwr\client\client.py", line 184, in maybe_call_fit
    return client.fit(fit_ins)
  File "C:\Users\B00830189\AppData\Local\anaconda3\envs\flower_tutorial\lib\site-packages\flwr\client\app.py", line 297, in _fit
    results = self.numpy_client.fit(parameters, ins.config)  # type: ignore
  File "C:\Users\B00830189\OneDrive - Ulster University\phd\Code\Demos\Flower\FlowerTutorial\client.py", line 48, in fit
    train(self.model, self.trainloader, optim, epochs, self.device) # Model no longer has weights sent my the server
  File "C:\Users\B00830189\OneDrive - Ulster University\phd\Code\Demos\Flower\FlowerTutorial\model.py", line 45, in train
    for images, labels in trainloader:
  File "C:\Users\B00830189\AppData\Local\anaconda3\envs\flower_tutorial\lib\site-packages\torch\utils\data\dataloader.py", line 628, in __next__
    data = self._next_data()
  File "C:\Users\B00830189\AppData\Local\anaconda3\envs\flower_tutorial\lib\site-packages\torch\utils\data\dataloader.py", line 1316, in _next_data
    idx, data = self._get_data()
  File "C:\Users\B00830189\AppData\Local\anaconda3\envs\flower_tutorial\lib\site-packages\torch\utils\data\dataloader.py", line 1282, in _get_data
    success, data = self._try_get_data()
  File "C:\Users\B00830189\AppData\Local\anaconda3\envs\flower_tutorial\lib\site-packages\torch\utils\data\dataloader.py", line 1133, in _try_get_data
    raise RuntimeError('DataLoader worker (pid(s) {}) exited unexpectedly'.format(pids_str)) from e
RuntimeError: DataLoader worker (pid(s) 16624, 18580) exited unexpectedly
[2024-05-24 14:24:18,628][flwr][ERROR] - [36mray::launch_and_fit()[39m (pid=4704, ip=127.0.0.1)
  File "C:\Users\B00830189\AppData\Local\anaconda3\envs\flower_tutorial\lib\multiprocessing\queues.py", line 108, in get
    raise Empty
_queue.Empty

The above exception was the direct cause of the following exception:

[36mray::launch_and_fit()[39m (pid=4704, ip=127.0.0.1)
  File "python\ray\_raylet.pyx", line 633, in ray._raylet.execute_task
  File "python\ray\_raylet.pyx", line 674, in ray._raylet.execute_task
  File "python\ray\_raylet.pyx", line 640, in ray._raylet.execute_task
  File "python\ray\_raylet.pyx", line 644, in ray._raylet.execute_task
  File "C:\Users\B00830189\AppData\Local\anaconda3\envs\flower_tutorial\lib\site-packages\flwr\simulation\ray_transport\ray_client_proxy.py", line 148, in launch_and_fit
    return maybe_call_fit(
  File "C:\Users\B00830189\AppData\Local\anaconda3\envs\flower_tutorial\lib\site-packages\flwr\client\client.py", line 184, in maybe_call_fit
    return client.fit(fit_ins)
  File "C:\Users\B00830189\AppData\Local\anaconda3\envs\flower_tutorial\lib\site-packages\flwr\client\app.py", line 297, in _fit
    results = self.numpy_client.fit(parameters, ins.config)  # type: ignore
  File "C:\Users\B00830189\OneDrive - Ulster University\phd\Code\Demos\Flower\FlowerTutorial\client.py", line 48, in fit
    train(self.model, self.trainloader, optim, epochs, self.device) # Model no longer has weights sent my the server
  File "C:\Users\B00830189\OneDrive - Ulster University\phd\Code\Demos\Flower\FlowerTutorial\model.py", line 45, in train
    for images, labels in trainloader:
  File "C:\Users\B00830189\AppData\Local\anaconda3\envs\flower_tutorial\lib\site-packages\torch\utils\data\dataloader.py", line 628, in __next__
    data = self._next_data()
  File "C:\Users\B00830189\AppData\Local\anaconda3\envs\flower_tutorial\lib\site-packages\torch\utils\data\dataloader.py", line 1316, in _next_data
    idx, data = self._get_data()
  File "C:\Users\B00830189\AppData\Local\anaconda3\envs\flower_tutorial\lib\site-packages\torch\utils\data\dataloader.py", line 1282, in _get_data
    success, data = self._try_get_data()
  File "C:\Users\B00830189\AppData\Local\anaconda3\envs\flower_tutorial\lib\site-packages\torch\utils\data\dataloader.py", line 1133, in _try_get_data
    raise RuntimeError('DataLoader worker (pid(s) {}) exited unexpectedly'.format(pids_str)) from e
RuntimeError: DataLoader worker (pid(s) 10564, 16984) exited unexpectedly
[2024-05-24 14:24:18,988][flwr][ERROR] - [36mray::launch_and_fit()[39m (pid=6672, ip=127.0.0.1)
  File "C:\Users\B00830189\AppData\Local\anaconda3\envs\flower_tutorial\lib\multiprocessing\queues.py", line 108, in get
    raise Empty
_queue.Empty

The above exception was the direct cause of the following exception:

[36mray::launch_and_fit()[39m (pid=6672, ip=127.0.0.1)
  File "python\ray\_raylet.pyx", line 633, in ray._raylet.execute_task
  File "python\ray\_raylet.pyx", line 674, in ray._raylet.execute_task
  File "python\ray\_raylet.pyx", line 640, in ray._raylet.execute_task
  File "python\ray\_raylet.pyx", line 644, in ray._raylet.execute_task
  File "C:\Users\B00830189\AppData\Local\anaconda3\envs\flower_tutorial\lib\site-packages\flwr\simulation\ray_transport\ray_client_proxy.py", line 148, in launch_and_fit
    return maybe_call_fit(
  File "C:\Users\B00830189\AppData\Local\anaconda3\envs\flower_tutorial\lib\site-packages\flwr\client\client.py", line 184, in maybe_call_fit
    return client.fit(fit_ins)
  File "C:\Users\B00830189\AppData\Local\anaconda3\envs\flower_tutorial\lib\site-packages\flwr\client\app.py", line 297, in _fit
    results = self.numpy_client.fit(parameters, ins.config)  # type: ignore
  File "C:\Users\B00830189\OneDrive - Ulster University\phd\Code\Demos\Flower\FlowerTutorial\client.py", line 48, in fit
    train(self.model, self.trainloader, optim, epochs, self.device) # Model no longer has weights sent my the server
  File "C:\Users\B00830189\OneDrive - Ulster University\phd\Code\Demos\Flower\FlowerTutorial\model.py", line 45, in train
    for images, labels in trainloader:
  File "C:\Users\B00830189\AppData\Local\anaconda3\envs\flower_tutorial\lib\site-packages\torch\utils\data\dataloader.py", line 628, in __next__
    data = self._next_data()
  File "C:\Users\B00830189\AppData\Local\anaconda3\envs\flower_tutorial\lib\site-packages\torch\utils\data\dataloader.py", line 1316, in _next_data
    idx, data = self._get_data()
  File "C:\Users\B00830189\AppData\Local\anaconda3\envs\flower_tutorial\lib\site-packages\torch\utils\data\dataloader.py", line 1282, in _get_data
    success, data = self._try_get_data()
  File "C:\Users\B00830189\AppData\Local\anaconda3\envs\flower_tutorial\lib\site-packages\torch\utils\data\dataloader.py", line 1133, in _try_get_data
    raise RuntimeError('DataLoader worker (pid(s) {}) exited unexpectedly'.format(pids_str)) from e
RuntimeError: DataLoader worker (pid(s) 14440, 13892) exited unexpectedly
[2024-05-24 14:24:19,263][flwr][ERROR] - [36mray::launch_and_fit()[39m (pid=12948, ip=127.0.0.1)
  File "C:\Users\B00830189\AppData\Local\anaconda3\envs\flower_tutorial\lib\multiprocessing\queues.py", line 108, in get
    raise Empty
_queue.Empty

The above exception was the direct cause of the following exception:

[36mray::launch_and_fit()[39m (pid=12948, ip=127.0.0.1)
  File "python\ray\_raylet.pyx", line 633, in ray._raylet.execute_task
  File "python\ray\_raylet.pyx", line 674, in ray._raylet.execute_task
  File "python\ray\_raylet.pyx", line 640, in ray._raylet.execute_task
  File "python\ray\_raylet.pyx", line 644, in ray._raylet.execute_task
  File "C:\Users\B00830189\AppData\Local\anaconda3\envs\flower_tutorial\lib\site-packages\flwr\simulation\ray_transport\ray_client_proxy.py", line 148, in launch_and_fit
    return maybe_call_fit(
  File "C:\Users\B00830189\AppData\Local\anaconda3\envs\flower_tutorial\lib\site-packages\flwr\client\client.py", line 184, in maybe_call_fit
    return client.fit(fit_ins)
  File "C:\Users\B00830189\AppData\Local\anaconda3\envs\flower_tutorial\lib\site-packages\flwr\client\app.py", line 297, in _fit
    results = self.numpy_client.fit(parameters, ins.config)  # type: ignore
  File "C:\Users\B00830189\OneDrive - Ulster University\phd\Code\Demos\Flower\FlowerTutorial\client.py", line 48, in fit
    train(self.model, self.trainloader, optim, epochs, self.device) # Model no longer has weights sent my the server
  File "C:\Users\B00830189\OneDrive - Ulster University\phd\Code\Demos\Flower\FlowerTutorial\model.py", line 45, in train
    for images, labels in trainloader:
  File "C:\Users\B00830189\AppData\Local\anaconda3\envs\flower_tutorial\lib\site-packages\torch\utils\data\dataloader.py", line 628, in __next__
    data = self._next_data()
  File "C:\Users\B00830189\AppData\Local\anaconda3\envs\flower_tutorial\lib\site-packages\torch\utils\data\dataloader.py", line 1316, in _next_data
    idx, data = self._get_data()
  File "C:\Users\B00830189\AppData\Local\anaconda3\envs\flower_tutorial\lib\site-packages\torch\utils\data\dataloader.py", line 1282, in _get_data
    success, data = self._try_get_data()
  File "C:\Users\B00830189\AppData\Local\anaconda3\envs\flower_tutorial\lib\site-packages\torch\utils\data\dataloader.py", line 1133, in _try_get_data
    raise RuntimeError('DataLoader worker (pid(s) {}) exited unexpectedly'.format(pids_str)) from e
RuntimeError: DataLoader worker (pid(s) 9616, 6680) exited unexpectedly
[2024-05-24 14:24:23,961][flwr][ERROR] - [36mray::launch_and_fit()[39m (pid=4704, ip=127.0.0.1)
  File "C:\Users\B00830189\AppData\Local\anaconda3\envs\flower_tutorial\lib\multiprocessing\queues.py", line 108, in get
    raise Empty
_queue.Empty

The above exception was the direct cause of the following exception:

[36mray::launch_and_fit()[39m (pid=4704, ip=127.0.0.1)
  File "python\ray\_raylet.pyx", line 633, in ray._raylet.execute_task
  File "python\ray\_raylet.pyx", line 674, in ray._raylet.execute_task
  File "python\ray\_raylet.pyx", line 640, in ray._raylet.execute_task
  File "python\ray\_raylet.pyx", line 644, in ray._raylet.execute_task
  File "C:\Users\B00830189\AppData\Local\anaconda3\envs\flower_tutorial\lib\site-packages\flwr\simulation\ray_transport\ray_client_proxy.py", line 148, in launch_and_fit
    return maybe_call_fit(
  File "C:\Users\B00830189\AppData\Local\anaconda3\envs\flower_tutorial\lib\site-packages\flwr\client\client.py", line 184, in maybe_call_fit
    return client.fit(fit_ins)
  File "C:\Users\B00830189\AppData\Local\anaconda3\envs\flower_tutorial\lib\site-packages\flwr\client\app.py", line 297, in _fit
    results = self.numpy_client.fit(parameters, ins.config)  # type: ignore
  File "C:\Users\B00830189\OneDrive - Ulster University\phd\Code\Demos\Flower\FlowerTutorial\client.py", line 48, in fit
    train(self.model, self.trainloader, optim, epochs, self.device) # Model no longer has weights sent my the server
  File "C:\Users\B00830189\OneDrive - Ulster University\phd\Code\Demos\Flower\FlowerTutorial\model.py", line 45, in train
    for images, labels in trainloader:
  File "C:\Users\B00830189\AppData\Local\anaconda3\envs\flower_tutorial\lib\site-packages\torch\utils\data\dataloader.py", line 628, in __next__
    data = self._next_data()
  File "C:\Users\B00830189\AppData\Local\anaconda3\envs\flower_tutorial\lib\site-packages\torch\utils\data\dataloader.py", line 1316, in _next_data
    idx, data = self._get_data()
  File "C:\Users\B00830189\AppData\Local\anaconda3\envs\flower_tutorial\lib\site-packages\torch\utils\data\dataloader.py", line 1282, in _get_data
    success, data = self._try_get_data()
  File "C:\Users\B00830189\AppData\Local\anaconda3\envs\flower_tutorial\lib\site-packages\torch\utils\data\dataloader.py", line 1133, in _try_get_data
    raise RuntimeError('DataLoader worker (pid(s) {}) exited unexpectedly'.format(pids_str)) from e
RuntimeError: DataLoader worker (pid(s) 4700, 3824) exited unexpectedly
[2024-05-24 14:24:23,964][flwr][DEBUG] - fit_round 2 received 0 results and 10 failures
[2024-05-24 14:24:26,837][flwr][INFO] - fit progress: (2, 181.93332147598267, {'accuracy': 0.0786}, 57.9148551)
[2024-05-24 14:24:26,838][flwr][DEBUG] - evaluate_round 2: strategy sampled 25 clients (out of 100)
[2024-05-24 14:24:27,882][flwr][ERROR] - [36mray::launch_and_evaluate()[39m (pid=14596, ip=127.0.0.1)
  File "python\ray\_raylet.pyx", line 602, in ray._raylet.execute_task
  File "python\ray\_raylet.pyx", line 624, in ray._raylet.execute_task
  File "python\ray\_raylet.pyx", line 456, in ray._raylet.raise_if_dependency_failed
ray.exceptions.RaySystemError: System error: [WinError 1455] The paging file is too small for this operation to complete. Error loading "C:\Users\B00830189\AppData\Local\anaconda3\envs\flower_tutorial\lib\site-packages\torch\lib\shm.dll" or one of its dependencies.
traceback: Traceback (most recent call last):
  File "C:\Users\B00830189\AppData\Local\anaconda3\envs\flower_tutorial\lib\site-packages\ray\serialization.py", line 309, in deserialize_objects
    obj = self._deserialize_object(data, metadata, object_ref)
  File "C:\Users\B00830189\AppData\Local\anaconda3\envs\flower_tutorial\lib\site-packages\ray\serialization.py", line 215, in _deserialize_object
    return self._deserialize_msgpack_data(data, metadata_fields)
  File "C:\Users\B00830189\AppData\Local\anaconda3\envs\flower_tutorial\lib\site-packages\ray\serialization.py", line 174, in _deserialize_msgpack_data
    python_objects = self._deserialize_pickle5_data(pickle5_data)
  File "C:\Users\B00830189\AppData\Local\anaconda3\envs\flower_tutorial\lib\site-packages\ray\serialization.py", line 164, in _deserialize_pickle5_data
    obj = pickle.loads(in_band)
  File "C:\Users\B00830189\AppData\Local\anaconda3\envs\flower_tutorial\lib\site-packages\torch\__init__.py", line 128, in <module>
    raise err
OSError: [WinError 1455] The paging file is too small for this operation to complete. Error loading "C:\Users\B00830189\AppData\Local\anaconda3\envs\flower_tutorial\lib\site-packages\torch\lib\shm.dll" or one of its dependencies.
[2024-05-24 14:24:29,043][flwr][ERROR] - [36mray::launch_and_evaluate()[39m (pid=14596, ip=127.0.0.1)
  File "python\ray\_raylet.pyx", line 602, in ray._raylet.execute_task
  File "python\ray\_raylet.pyx", line 624, in ray._raylet.execute_task
  File "python\ray\_raylet.pyx", line 456, in ray._raylet.raise_if_dependency_failed
ray.exceptions.RaySystemError: System error: [WinError 1455] The paging file is too small for this operation to complete. Error loading "C:\Users\B00830189\AppData\Local\anaconda3\envs\flower_tutorial\lib\site-packages\torch\lib\shm.dll" or one of its dependencies.
traceback: Traceback (most recent call last):
  File "C:\Users\B00830189\AppData\Local\anaconda3\envs\flower_tutorial\lib\site-packages\ray\serialization.py", line 309, in deserialize_objects
    obj = self._deserialize_object(data, metadata, object_ref)
  File "C:\Users\B00830189\AppData\Local\anaconda3\envs\flower_tutorial\lib\site-packages\ray\serialization.py", line 215, in _deserialize_object
    return self._deserialize_msgpack_data(data, metadata_fields)
  File "C:\Users\B00830189\AppData\Local\anaconda3\envs\flower_tutorial\lib\site-packages\ray\serialization.py", line 174, in _deserialize_msgpack_data
    python_objects = self._deserialize_pickle5_data(pickle5_data)
  File "C:\Users\B00830189\AppData\Local\anaconda3\envs\flower_tutorial\lib\site-packages\ray\serialization.py", line 164, in _deserialize_pickle5_data
    obj = pickle.loads(in_band)
  File "C:\Users\B00830189\AppData\Local\anaconda3\envs\flower_tutorial\lib\site-packages\torch\__init__.py", line 128, in <module>
    raise err
OSError: [WinError 1455] The paging file is too small for this operation to complete. Error loading "C:\Users\B00830189\AppData\Local\anaconda3\envs\flower_tutorial\lib\site-packages\torch\lib\shm.dll" or one of its dependencies.
[2024-05-24 14:24:33,271][flwr][ERROR] - [36mray::launch_and_evaluate()[39m (pid=6672, ip=127.0.0.1)
  File "C:\Users\B00830189\AppData\Local\anaconda3\envs\flower_tutorial\lib\multiprocessing\queues.py", line 108, in get
    raise Empty
_queue.Empty

The above exception was the direct cause of the following exception:

[36mray::launch_and_evaluate()[39m (pid=6672, ip=127.0.0.1)
  File "python\ray\_raylet.pyx", line 633, in ray._raylet.execute_task
  File "python\ray\_raylet.pyx", line 674, in ray._raylet.execute_task
  File "python\ray\_raylet.pyx", line 640, in ray._raylet.execute_task
  File "python\ray\_raylet.pyx", line 644, in ray._raylet.execute_task
  File "C:\Users\B00830189\AppData\Local\anaconda3\envs\flower_tutorial\lib\site-packages\flwr\simulation\ray_transport\ray_client_proxy.py", line 160, in launch_and_evaluate
    return maybe_call_evaluate(
  File "C:\Users\B00830189\AppData\Local\anaconda3\envs\flower_tutorial\lib\site-packages\flwr\client\client.py", line 205, in maybe_call_evaluate
    return client.evaluate(evaluate_ins)
  File "C:\Users\B00830189\AppData\Local\anaconda3\envs\flower_tutorial\lib\site-packages\flwr\client\app.py", line 321, in _evaluate
    results = self.numpy_client.evaluate(parameters, ins.config)  # type: ignore
  File "C:\Users\B00830189\OneDrive - Ulster University\phd\Code\Demos\Flower\FlowerTutorial\client.py", line 55, in evaluate
    loss, accuracy = test(self.model, self.valloader, self.device)
  File "C:\Users\B00830189\OneDrive - Ulster University\phd\Code\Demos\Flower\FlowerTutorial\model.py", line 63, in test
    for data in testloader:
  File "C:\Users\B00830189\AppData\Local\anaconda3\envs\flower_tutorial\lib\site-packages\torch\utils\data\dataloader.py", line 628, in __next__
    data = self._next_data()
  File "C:\Users\B00830189\AppData\Local\anaconda3\envs\flower_tutorial\lib\site-packages\torch\utils\data\dataloader.py", line 1316, in _next_data
    idx, data = self._get_data()
  File "C:\Users\B00830189\AppData\Local\anaconda3\envs\flower_tutorial\lib\site-packages\torch\utils\data\dataloader.py", line 1282, in _get_data
    success, data = self._try_get_data()
  File "C:\Users\B00830189\AppData\Local\anaconda3\envs\flower_tutorial\lib\site-packages\torch\utils\data\dataloader.py", line 1133, in _try_get_data
    raise RuntimeError('DataLoader worker (pid(s) {}) exited unexpectedly'.format(pids_str)) from e
RuntimeError: DataLoader worker (pid(s) 7488, 17068) exited unexpectedly
[2024-05-24 14:24:33,381][flwr][ERROR] - [36mray::launch_and_evaluate()[39m (pid=4704, ip=127.0.0.1)
  File "C:\Users\B00830189\AppData\Local\anaconda3\envs\flower_tutorial\lib\multiprocessing\queues.py", line 108, in get
    raise Empty
_queue.Empty

The above exception was the direct cause of the following exception:

[36mray::launch_and_evaluate()[39m (pid=4704, ip=127.0.0.1)
  File "python\ray\_raylet.pyx", line 633, in ray._raylet.execute_task
  File "python\ray\_raylet.pyx", line 674, in ray._raylet.execute_task
  File "python\ray\_raylet.pyx", line 640, in ray._raylet.execute_task
  File "python\ray\_raylet.pyx", line 644, in ray._raylet.execute_task
  File "C:\Users\B00830189\AppData\Local\anaconda3\envs\flower_tutorial\lib\site-packages\flwr\simulation\ray_transport\ray_client_proxy.py", line 160, in launch_and_evaluate
    return maybe_call_evaluate(
  File "C:\Users\B00830189\AppData\Local\anaconda3\envs\flower_tutorial\lib\site-packages\flwr\client\client.py", line 205, in maybe_call_evaluate
    return client.evaluate(evaluate_ins)
  File "C:\Users\B00830189\AppData\Local\anaconda3\envs\flower_tutorial\lib\site-packages\flwr\client\app.py", line 321, in _evaluate
    results = self.numpy_client.evaluate(parameters, ins.config)  # type: ignore
  File "C:\Users\B00830189\OneDrive - Ulster University\phd\Code\Demos\Flower\FlowerTutorial\client.py", line 55, in evaluate
    loss, accuracy = test(self.model, self.valloader, self.device)
  File "C:\Users\B00830189\OneDrive - Ulster University\phd\Code\Demos\Flower\FlowerTutorial\model.py", line 63, in test
    for data in testloader:
  File "C:\Users\B00830189\AppData\Local\anaconda3\envs\flower_tutorial\lib\site-packages\torch\utils\data\dataloader.py", line 628, in __next__
    data = self._next_data()
  File "C:\Users\B00830189\AppData\Local\anaconda3\envs\flower_tutorial\lib\site-packages\torch\utils\data\dataloader.py", line 1316, in _next_data
    idx, data = self._get_data()
  File "C:\Users\B00830189\AppData\Local\anaconda3\envs\flower_tutorial\lib\site-packages\torch\utils\data\dataloader.py", line 1282, in _get_data
    success, data = self._try_get_data()
  File "C:\Users\B00830189\AppData\Local\anaconda3\envs\flower_tutorial\lib\site-packages\torch\utils\data\dataloader.py", line 1133, in _try_get_data
    raise RuntimeError('DataLoader worker (pid(s) {}) exited unexpectedly'.format(pids_str)) from e
RuntimeError: DataLoader worker (pid(s) 19260, 12176) exited unexpectedly
[2024-05-24 14:24:33,688][flwr][ERROR] - [36mray::launch_and_evaluate()[39m (pid=12948, ip=127.0.0.1)
  File "C:\Users\B00830189\AppData\Local\anaconda3\envs\flower_tutorial\lib\multiprocessing\queues.py", line 108, in get
    raise Empty
_queue.Empty

The above exception was the direct cause of the following exception:

[36mray::launch_and_evaluate()[39m (pid=12948, ip=127.0.0.1)
  File "python\ray\_raylet.pyx", line 633, in ray._raylet.execute_task
  File "python\ray\_raylet.pyx", line 674, in ray._raylet.execute_task
  File "python\ray\_raylet.pyx", line 640, in ray._raylet.execute_task
  File "python\ray\_raylet.pyx", line 644, in ray._raylet.execute_task
  File "C:\Users\B00830189\AppData\Local\anaconda3\envs\flower_tutorial\lib\site-packages\flwr\simulation\ray_transport\ray_client_proxy.py", line 160, in launch_and_evaluate
    return maybe_call_evaluate(
  File "C:\Users\B00830189\AppData\Local\anaconda3\envs\flower_tutorial\lib\site-packages\flwr\client\client.py", line 205, in maybe_call_evaluate
    return client.evaluate(evaluate_ins)
  File "C:\Users\B00830189\AppData\Local\anaconda3\envs\flower_tutorial\lib\site-packages\flwr\client\app.py", line 321, in _evaluate
    results = self.numpy_client.evaluate(parameters, ins.config)  # type: ignore
  File "C:\Users\B00830189\OneDrive - Ulster University\phd\Code\Demos\Flower\FlowerTutorial\client.py", line 55, in evaluate
    loss, accuracy = test(self.model, self.valloader, self.device)
  File "C:\Users\B00830189\OneDrive - Ulster University\phd\Code\Demos\Flower\FlowerTutorial\model.py", line 63, in test
    for data in testloader:
  File "C:\Users\B00830189\AppData\Local\anaconda3\envs\flower_tutorial\lib\site-packages\torch\utils\data\dataloader.py", line 628, in __next__
    data = self._next_data()
  File "C:\Users\B00830189\AppData\Local\anaconda3\envs\flower_tutorial\lib\site-packages\torch\utils\data\dataloader.py", line 1316, in _next_data
    idx, data = self._get_data()
  File "C:\Users\B00830189\AppData\Local\anaconda3\envs\flower_tutorial\lib\site-packages\torch\utils\data\dataloader.py", line 1282, in _get_data
    success, data = self._try_get_data()
  File "C:\Users\B00830189\AppData\Local\anaconda3\envs\flower_tutorial\lib\site-packages\torch\utils\data\dataloader.py", line 1133, in _try_get_data
    raise RuntimeError('DataLoader worker (pid(s) {}) exited unexpectedly'.format(pids_str)) from e
RuntimeError: DataLoader worker (pid(s) 3948, 17808) exited unexpectedly
[2024-05-24 14:24:33,920][flwr][ERROR] - [36mray::launch_and_evaluate()[39m (pid=14596, ip=127.0.0.1)
  File "python\ray\_raylet.pyx", line 602, in ray._raylet.execute_task
  File "python\ray\_raylet.pyx", line 624, in ray._raylet.execute_task
  File "python\ray\_raylet.pyx", line 456, in ray._raylet.raise_if_dependency_failed
ray.exceptions.RaySystemError: System error: [WinError 1455] The paging file is too small for this operation to complete. Error loading "C:\Users\B00830189\AppData\Local\anaconda3\envs\flower_tutorial\lib\site-packages\torch\lib\shm.dll" or one of its dependencies.
traceback: Traceback (most recent call last):
  File "C:\Users\B00830189\AppData\Local\anaconda3\envs\flower_tutorial\lib\site-packages\ray\serialization.py", line 309, in deserialize_objects
    obj = self._deserialize_object(data, metadata, object_ref)
  File "C:\Users\B00830189\AppData\Local\anaconda3\envs\flower_tutorial\lib\site-packages\ray\serialization.py", line 215, in _deserialize_object
    return self._deserialize_msgpack_data(data, metadata_fields)
  File "C:\Users\B00830189\AppData\Local\anaconda3\envs\flower_tutorial\lib\site-packages\ray\serialization.py", line 174, in _deserialize_msgpack_data
    python_objects = self._deserialize_pickle5_data(pickle5_data)
  File "C:\Users\B00830189\AppData\Local\anaconda3\envs\flower_tutorial\lib\site-packages\ray\serialization.py", line 164, in _deserialize_pickle5_data
    obj = pickle.loads(in_band)
  File "C:\Users\B00830189\AppData\Local\anaconda3\envs\flower_tutorial\lib\site-packages\torch\__init__.py", line 128, in <module>
    raise err
OSError: [WinError 1455] The paging file is too small for this operation to complete. Error loading "C:\Users\B00830189\AppData\Local\anaconda3\envs\flower_tutorial\lib\site-packages\torch\lib\shm.dll" or one of its dependencies.
[2024-05-24 14:24:34,411][flwr][ERROR] - [36mray::launch_and_evaluate()[39m (pid=9844, ip=127.0.0.1)
  File "C:\Users\B00830189\AppData\Local\anaconda3\envs\flower_tutorial\lib\multiprocessing\queues.py", line 108, in get
    raise Empty
_queue.Empty

The above exception was the direct cause of the following exception:

[36mray::launch_and_evaluate()[39m (pid=9844, ip=127.0.0.1)
  File "python\ray\_raylet.pyx", line 633, in ray._raylet.execute_task
  File "python\ray\_raylet.pyx", line 674, in ray._raylet.execute_task
  File "python\ray\_raylet.pyx", line 640, in ray._raylet.execute_task
  File "python\ray\_raylet.pyx", line 644, in ray._raylet.execute_task
  File "C:\Users\B00830189\AppData\Local\anaconda3\envs\flower_tutorial\lib\site-packages\flwr\simulation\ray_transport\ray_client_proxy.py", line 160, in launch_and_evaluate
    return maybe_call_evaluate(
  File "C:\Users\B00830189\AppData\Local\anaconda3\envs\flower_tutorial\lib\site-packages\flwr\client\client.py", line 205, in maybe_call_evaluate
    return client.evaluate(evaluate_ins)
  File "C:\Users\B00830189\AppData\Local\anaconda3\envs\flower_tutorial\lib\site-packages\flwr\client\app.py", line 321, in _evaluate
    results = self.numpy_client.evaluate(parameters, ins.config)  # type: ignore
  File "C:\Users\B00830189\OneDrive - Ulster University\phd\Code\Demos\Flower\FlowerTutorial\client.py", line 55, in evaluate
    loss, accuracy = test(self.model, self.valloader, self.device)
  File "C:\Users\B00830189\OneDrive - Ulster University\phd\Code\Demos\Flower\FlowerTutorial\model.py", line 63, in test
    for data in testloader:
  File "C:\Users\B00830189\AppData\Local\anaconda3\envs\flower_tutorial\lib\site-packages\torch\utils\data\dataloader.py", line 628, in __next__
    data = self._next_data()
  File "C:\Users\B00830189\AppData\Local\anaconda3\envs\flower_tutorial\lib\site-packages\torch\utils\data\dataloader.py", line 1316, in _next_data
    idx, data = self._get_data()
  File "C:\Users\B00830189\AppData\Local\anaconda3\envs\flower_tutorial\lib\site-packages\torch\utils\data\dataloader.py", line 1282, in _get_data
    success, data = self._try_get_data()
  File "C:\Users\B00830189\AppData\Local\anaconda3\envs\flower_tutorial\lib\site-packages\torch\utils\data\dataloader.py", line 1133, in _try_get_data
    raise RuntimeError('DataLoader worker (pid(s) {}) exited unexpectedly'.format(pids_str)) from e
RuntimeError: DataLoader worker (pid(s) 17832, 2212) exited unexpectedly
[2024-05-24 14:24:34,536][flwr][ERROR] - [36mray::launch_and_evaluate()[39m (pid=14596, ip=127.0.0.1)
  File "python\ray\_raylet.pyx", line 602, in ray._raylet.execute_task
  File "python\ray\_raylet.pyx", line 624, in ray._raylet.execute_task
  File "python\ray\_raylet.pyx", line 456, in ray._raylet.raise_if_dependency_failed
ray.exceptions.RaySystemError: System error: [WinError 1455] The paging file is too small for this operation to complete. Error loading "C:\Users\B00830189\AppData\Local\anaconda3\envs\flower_tutorial\lib\site-packages\torch\lib\shm.dll" or one of its dependencies.
traceback: Traceback (most recent call last):
  File "C:\Users\B00830189\AppData\Local\anaconda3\envs\flower_tutorial\lib\site-packages\ray\serialization.py", line 309, in deserialize_objects
    obj = self._deserialize_object(data, metadata, object_ref)
  File "C:\Users\B00830189\AppData\Local\anaconda3\envs\flower_tutorial\lib\site-packages\ray\serialization.py", line 215, in _deserialize_object
    return self._deserialize_msgpack_data(data, metadata_fields)
  File "C:\Users\B00830189\AppData\Local\anaconda3\envs\flower_tutorial\lib\site-packages\ray\serialization.py", line 174, in _deserialize_msgpack_data
    python_objects = self._deserialize_pickle5_data(pickle5_data)
  File "C:\Users\B00830189\AppData\Local\anaconda3\envs\flower_tutorial\lib\site-packages\ray\serialization.py", line 164, in _deserialize_pickle5_data
    obj = pickle.loads(in_band)
  File "C:\Users\B00830189\AppData\Local\anaconda3\envs\flower_tutorial\lib\site-packages\torch\__init__.py", line 128, in <module>
    raise err
OSError: [WinError 1455] The paging file is too small for this operation to complete. Error loading "C:\Users\B00830189\AppData\Local\anaconda3\envs\flower_tutorial\lib\site-packages\torch\lib\shm.dll" or one of its dependencies.
[2024-05-24 14:24:38,933][flwr][ERROR] - [36mray::launch_and_evaluate()[39m (pid=14596, ip=127.0.0.1)
  File "python\ray\_raylet.pyx", line 602, in ray._raylet.execute_task
  File "python\ray\_raylet.pyx", line 624, in ray._raylet.execute_task
  File "python\ray\_raylet.pyx", line 456, in ray._raylet.raise_if_dependency_failed
ray.exceptions.RaySystemError: System error: [WinError 1455] The paging file is too small for this operation to complete. Error loading "C:\Users\B00830189\AppData\Local\anaconda3\envs\flower_tutorial\lib\site-packages\torch\lib\shm.dll" or one of its dependencies.
traceback: Traceback (most recent call last):
  File "C:\Users\B00830189\AppData\Local\anaconda3\envs\flower_tutorial\lib\site-packages\ray\serialization.py", line 309, in deserialize_objects
    obj = self._deserialize_object(data, metadata, object_ref)
  File "C:\Users\B00830189\AppData\Local\anaconda3\envs\flower_tutorial\lib\site-packages\ray\serialization.py", line 215, in _deserialize_object
    return self._deserialize_msgpack_data(data, metadata_fields)
  File "C:\Users\B00830189\AppData\Local\anaconda3\envs\flower_tutorial\lib\site-packages\ray\serialization.py", line 174, in _deserialize_msgpack_data
    python_objects = self._deserialize_pickle5_data(pickle5_data)
  File "C:\Users\B00830189\AppData\Local\anaconda3\envs\flower_tutorial\lib\site-packages\ray\serialization.py", line 164, in _deserialize_pickle5_data
    obj = pickle.loads(in_band)
  File "C:\Users\B00830189\AppData\Local\anaconda3\envs\flower_tutorial\lib\site-packages\torch\__init__.py", line 128, in <module>
    raise err
OSError: [WinError 1455] The paging file is too small for this operation to complete. Error loading "C:\Users\B00830189\AppData\Local\anaconda3\envs\flower_tutorial\lib\site-packages\torch\lib\shm.dll" or one of its dependencies.
[2024-05-24 14:24:39,460][flwr][ERROR] - [36mray::launch_and_evaluate()[39m (pid=14596, ip=127.0.0.1)
  File "python\ray\_raylet.pyx", line 602, in ray._raylet.execute_task
  File "python\ray\_raylet.pyx", line 624, in ray._raylet.execute_task
  File "python\ray\_raylet.pyx", line 456, in ray._raylet.raise_if_dependency_failed
ray.exceptions.RaySystemError: System error: [WinError 1455] The paging file is too small for this operation to complete. Error loading "C:\Users\B00830189\AppData\Local\anaconda3\envs\flower_tutorial\lib\site-packages\torch\lib\shm.dll" or one of its dependencies.
traceback: Traceback (most recent call last):
  File "C:\Users\B00830189\AppData\Local\anaconda3\envs\flower_tutorial\lib\site-packages\ray\serialization.py", line 309, in deserialize_objects
    obj = self._deserialize_object(data, metadata, object_ref)
  File "C:\Users\B00830189\AppData\Local\anaconda3\envs\flower_tutorial\lib\site-packages\ray\serialization.py", line 215, in _deserialize_object
    return self._deserialize_msgpack_data(data, metadata_fields)
  File "C:\Users\B00830189\AppData\Local\anaconda3\envs\flower_tutorial\lib\site-packages\ray\serialization.py", line 174, in _deserialize_msgpack_data
    python_objects = self._deserialize_pickle5_data(pickle5_data)
  File "C:\Users\B00830189\AppData\Local\anaconda3\envs\flower_tutorial\lib\site-packages\ray\serialization.py", line 164, in _deserialize_pickle5_data
    obj = pickle.loads(in_band)
  File "C:\Users\B00830189\AppData\Local\anaconda3\envs\flower_tutorial\lib\site-packages\torch\__init__.py", line 128, in <module>
    raise err
OSError: [WinError 1455] The paging file is too small for this operation to complete. Error loading "C:\Users\B00830189\AppData\Local\anaconda3\envs\flower_tutorial\lib\site-packages\torch\lib\shm.dll" or one of its dependencies.
[2024-05-24 14:24:40,259][flwr][ERROR] - [36mray::launch_and_evaluate()[39m (pid=14596, ip=127.0.0.1)
  File "python\ray\_raylet.pyx", line 602, in ray._raylet.execute_task
  File "python\ray\_raylet.pyx", line 624, in ray._raylet.execute_task
  File "python\ray\_raylet.pyx", line 456, in ray._raylet.raise_if_dependency_failed
ray.exceptions.RaySystemError: System error: [WinError 1455] The paging file is too small for this operation to complete. Error loading "C:\Users\B00830189\AppData\Local\anaconda3\envs\flower_tutorial\lib\site-packages\torch\lib\shm.dll" or one of its dependencies.
traceback: Traceback (most recent call last):
  File "C:\Users\B00830189\AppData\Local\anaconda3\envs\flower_tutorial\lib\site-packages\ray\serialization.py", line 309, in deserialize_objects
    obj = self._deserialize_object(data, metadata, object_ref)
  File "C:\Users\B00830189\AppData\Local\anaconda3\envs\flower_tutorial\lib\site-packages\ray\serialization.py", line 215, in _deserialize_object
    return self._deserialize_msgpack_data(data, metadata_fields)
  File "C:\Users\B00830189\AppData\Local\anaconda3\envs\flower_tutorial\lib\site-packages\ray\serialization.py", line 174, in _deserialize_msgpack_data
    python_objects = self._deserialize_pickle5_data(pickle5_data)
  File "C:\Users\B00830189\AppData\Local\anaconda3\envs\flower_tutorial\lib\site-packages\ray\serialization.py", line 164, in _deserialize_pickle5_data
    obj = pickle.loads(in_band)
  File "C:\Users\B00830189\AppData\Local\anaconda3\envs\flower_tutorial\lib\site-packages\torch\__init__.py", line 128, in <module>
    raise err
OSError: [WinError 1455] The paging file is too small for this operation to complete. Error loading "C:\Users\B00830189\AppData\Local\anaconda3\envs\flower_tutorial\lib\site-packages\torch\lib\shm.dll" or one of its dependencies.
[2024-05-24 14:24:40,259][flwr][ERROR] - [36mray::launch_and_evaluate()[39m (pid=6672, ip=127.0.0.1)
  File "C:\Users\B00830189\AppData\Local\anaconda3\envs\flower_tutorial\lib\multiprocessing\queues.py", line 108, in get
    raise Empty
_queue.Empty

The above exception was the direct cause of the following exception:

[36mray::launch_and_evaluate()[39m (pid=6672, ip=127.0.0.1)
  File "python\ray\_raylet.pyx", line 633, in ray._raylet.execute_task
  File "python\ray\_raylet.pyx", line 674, in ray._raylet.execute_task
  File "python\ray\_raylet.pyx", line 640, in ray._raylet.execute_task
  File "python\ray\_raylet.pyx", line 644, in ray._raylet.execute_task
  File "C:\Users\B00830189\AppData\Local\anaconda3\envs\flower_tutorial\lib\site-packages\flwr\simulation\ray_transport\ray_client_proxy.py", line 160, in launch_and_evaluate
    return maybe_call_evaluate(
  File "C:\Users\B00830189\AppData\Local\anaconda3\envs\flower_tutorial\lib\site-packages\flwr\client\client.py", line 205, in maybe_call_evaluate
    return client.evaluate(evaluate_ins)
  File "C:\Users\B00830189\AppData\Local\anaconda3\envs\flower_tutorial\lib\site-packages\flwr\client\app.py", line 321, in _evaluate
    results = self.numpy_client.evaluate(parameters, ins.config)  # type: ignore
  File "C:\Users\B00830189\OneDrive - Ulster University\phd\Code\Demos\Flower\FlowerTutorial\client.py", line 55, in evaluate
    loss, accuracy = test(self.model, self.valloader, self.device)
  File "C:\Users\B00830189\OneDrive - Ulster University\phd\Code\Demos\Flower\FlowerTutorial\model.py", line 63, in test
    for data in testloader:
  File "C:\Users\B00830189\AppData\Local\anaconda3\envs\flower_tutorial\lib\site-packages\torch\utils\data\dataloader.py", line 628, in __next__
    data = self._next_data()
  File "C:\Users\B00830189\AppData\Local\anaconda3\envs\flower_tutorial\lib\site-packages\torch\utils\data\dataloader.py", line 1316, in _next_data
    idx, data = self._get_data()
  File "C:\Users\B00830189\AppData\Local\anaconda3\envs\flower_tutorial\lib\site-packages\torch\utils\data\dataloader.py", line 1282, in _get_data
    success, data = self._try_get_data()
  File "C:\Users\B00830189\AppData\Local\anaconda3\envs\flower_tutorial\lib\site-packages\torch\utils\data\dataloader.py", line 1133, in _try_get_data
    raise RuntimeError('DataLoader worker (pid(s) {}) exited unexpectedly'.format(pids_str)) from e
RuntimeError: DataLoader worker (pid(s) 4820, 12880) exited unexpectedly
[2024-05-24 14:24:40,374][flwr][ERROR] - [36mray::launch_and_evaluate()[39m (pid=12948, ip=127.0.0.1)
  File "C:\Users\B00830189\AppData\Local\anaconda3\envs\flower_tutorial\lib\multiprocessing\queues.py", line 108, in get
    raise Empty
_queue.Empty

The above exception was the direct cause of the following exception:

[36mray::launch_and_evaluate()[39m (pid=12948, ip=127.0.0.1)
  File "python\ray\_raylet.pyx", line 633, in ray._raylet.execute_task
  File "python\ray\_raylet.pyx", line 674, in ray._raylet.execute_task
  File "python\ray\_raylet.pyx", line 640, in ray._raylet.execute_task
  File "python\ray\_raylet.pyx", line 644, in ray._raylet.execute_task
  File "C:\Users\B00830189\AppData\Local\anaconda3\envs\flower_tutorial\lib\site-packages\flwr\simulation\ray_transport\ray_client_proxy.py", line 160, in launch_and_evaluate
    return maybe_call_evaluate(
  File "C:\Users\B00830189\AppData\Local\anaconda3\envs\flower_tutorial\lib\site-packages\flwr\client\client.py", line 205, in maybe_call_evaluate
    return client.evaluate(evaluate_ins)
  File "C:\Users\B00830189\AppData\Local\anaconda3\envs\flower_tutorial\lib\site-packages\flwr\client\app.py", line 321, in _evaluate
    results = self.numpy_client.evaluate(parameters, ins.config)  # type: ignore
  File "C:\Users\B00830189\OneDrive - Ulster University\phd\Code\Demos\Flower\FlowerTutorial\client.py", line 55, in evaluate
    loss, accuracy = test(self.model, self.valloader, self.device)
  File "C:\Users\B00830189\OneDrive - Ulster University\phd\Code\Demos\Flower\FlowerTutorial\model.py", line 63, in test
    for data in testloader:
  File "C:\Users\B00830189\AppData\Local\anaconda3\envs\flower_tutorial\lib\site-packages\torch\utils\data\dataloader.py", line 628, in __next__
    data = self._next_data()
  File "C:\Users\B00830189\AppData\Local\anaconda3\envs\flower_tutorial\lib\site-packages\torch\utils\data\dataloader.py", line 1316, in _next_data
    idx, data = self._get_data()
  File "C:\Users\B00830189\AppData\Local\anaconda3\envs\flower_tutorial\lib\site-packages\torch\utils\data\dataloader.py", line 1282, in _get_data
    success, data = self._try_get_data()
  File "C:\Users\B00830189\AppData\Local\anaconda3\envs\flower_tutorial\lib\site-packages\torch\utils\data\dataloader.py", line 1133, in _try_get_data
    raise RuntimeError('DataLoader worker (pid(s) {}) exited unexpectedly'.format(pids_str)) from e
RuntimeError: DataLoader worker (pid(s) 12720, 11156) exited unexpectedly
[2024-05-24 14:24:40,457][flwr][ERROR] - [36mray::launch_and_evaluate()[39m (pid=4704, ip=127.0.0.1)
  File "C:\Users\B00830189\AppData\Local\anaconda3\envs\flower_tutorial\lib\multiprocessing\queues.py", line 108, in get
    raise Empty
_queue.Empty

The above exception was the direct cause of the following exception:

[36mray::launch_and_evaluate()[39m (pid=4704, ip=127.0.0.1)
  File "python\ray\_raylet.pyx", line 633, in ray._raylet.execute_task
  File "python\ray\_raylet.pyx", line 674, in ray._raylet.execute_task
  File "python\ray\_raylet.pyx", line 640, in ray._raylet.execute_task
  File "python\ray\_raylet.pyx", line 644, in ray._raylet.execute_task
  File "C:\Users\B00830189\AppData\Local\anaconda3\envs\flower_tutorial\lib\site-packages\flwr\simulation\ray_transport\ray_client_proxy.py", line 160, in launch_and_evaluate
    return maybe_call_evaluate(
  File "C:\Users\B00830189\AppData\Local\anaconda3\envs\flower_tutorial\lib\site-packages\flwr\client\client.py", line 205, in maybe_call_evaluate
    return client.evaluate(evaluate_ins)
  File "C:\Users\B00830189\AppData\Local\anaconda3\envs\flower_tutorial\lib\site-packages\flwr\client\app.py", line 321, in _evaluate
    results = self.numpy_client.evaluate(parameters, ins.config)  # type: ignore
  File "C:\Users\B00830189\OneDrive - Ulster University\phd\Code\Demos\Flower\FlowerTutorial\client.py", line 55, in evaluate
    loss, accuracy = test(self.model, self.valloader, self.device)
  File "C:\Users\B00830189\OneDrive - Ulster University\phd\Code\Demos\Flower\FlowerTutorial\model.py", line 63, in test
    for data in testloader:
  File "C:\Users\B00830189\AppData\Local\anaconda3\envs\flower_tutorial\lib\site-packages\torch\utils\data\dataloader.py", line 628, in __next__
    data = self._next_data()
  File "C:\Users\B00830189\AppData\Local\anaconda3\envs\flower_tutorial\lib\site-packages\torch\utils\data\dataloader.py", line 1316, in _next_data
    idx, data = self._get_data()
  File "C:\Users\B00830189\AppData\Local\anaconda3\envs\flower_tutorial\lib\site-packages\torch\utils\data\dataloader.py", line 1282, in _get_data
    success, data = self._try_get_data()
  File "C:\Users\B00830189\AppData\Local\anaconda3\envs\flower_tutorial\lib\site-packages\torch\utils\data\dataloader.py", line 1133, in _try_get_data
    raise RuntimeError('DataLoader worker (pid(s) {}) exited unexpectedly'.format(pids_str)) from e
RuntimeError: DataLoader worker (pid(s) 5576, 11788) exited unexpectedly
[2024-05-24 14:24:40,567][flwr][ERROR] - [36mray::launch_and_evaluate()[39m (pid=9844, ip=127.0.0.1)
  File "C:\Users\B00830189\AppData\Local\anaconda3\envs\flower_tutorial\lib\multiprocessing\queues.py", line 108, in get
    raise Empty
_queue.Empty

The above exception was the direct cause of the following exception:

[36mray::launch_and_evaluate()[39m (pid=9844, ip=127.0.0.1)
  File "python\ray\_raylet.pyx", line 633, in ray._raylet.execute_task
  File "python\ray\_raylet.pyx", line 674, in ray._raylet.execute_task
  File "python\ray\_raylet.pyx", line 640, in ray._raylet.execute_task
  File "python\ray\_raylet.pyx", line 644, in ray._raylet.execute_task
  File "C:\Users\B00830189\AppData\Local\anaconda3\envs\flower_tutorial\lib\site-packages\flwr\simulation\ray_transport\ray_client_proxy.py", line 160, in launch_and_evaluate
    return maybe_call_evaluate(
  File "C:\Users\B00830189\AppData\Local\anaconda3\envs\flower_tutorial\lib\site-packages\flwr\client\client.py", line 205, in maybe_call_evaluate
    return client.evaluate(evaluate_ins)
  File "C:\Users\B00830189\AppData\Local\anaconda3\envs\flower_tutorial\lib\site-packages\flwr\client\app.py", line 321, in _evaluate
    results = self.numpy_client.evaluate(parameters, ins.config)  # type: ignore
  File "C:\Users\B00830189\OneDrive - Ulster University\phd\Code\Demos\Flower\FlowerTutorial\client.py", line 55, in evaluate
    loss, accuracy = test(self.model, self.valloader, self.device)
  File "C:\Users\B00830189\OneDrive - Ulster University\phd\Code\Demos\Flower\FlowerTutorial\model.py", line 63, in test
    for data in testloader:
  File "C:\Users\B00830189\AppData\Local\anaconda3\envs\flower_tutorial\lib\site-packages\torch\utils\data\dataloader.py", line 628, in __next__
    data = self._next_data()
  File "C:\Users\B00830189\AppData\Local\anaconda3\envs\flower_tutorial\lib\site-packages\torch\utils\data\dataloader.py", line 1316, in _next_data
    idx, data = self._get_data()
  File "C:\Users\B00830189\AppData\Local\anaconda3\envs\flower_tutorial\lib\site-packages\torch\utils\data\dataloader.py", line 1282, in _get_data
    success, data = self._try_get_data()
  File "C:\Users\B00830189\AppData\Local\anaconda3\envs\flower_tutorial\lib\site-packages\torch\utils\data\dataloader.py", line 1133, in _try_get_data
    raise RuntimeError('DataLoader worker (pid(s) {}) exited unexpectedly'.format(pids_str)) from e
RuntimeError: DataLoader worker (pid(s) 3148, 9556) exited unexpectedly
[2024-05-24 14:24:43,134][flwr][ERROR] - [36mray::launch_and_evaluate()[39m (pid=14596, ip=127.0.0.1)
  File "python\ray\_raylet.pyx", line 602, in ray._raylet.execute_task
  File "python\ray\_raylet.pyx", line 624, in ray._raylet.execute_task
  File "python\ray\_raylet.pyx", line 456, in ray._raylet.raise_if_dependency_failed
ray.exceptions.RaySystemError: System error: [WinError 1455] The paging file is too small for this operation to complete. Error loading "C:\Users\B00830189\AppData\Local\anaconda3\envs\flower_tutorial\lib\site-packages\torch\lib\shm.dll" or one of its dependencies.
traceback: Traceback (most recent call last):
  File "C:\Users\B00830189\AppData\Local\anaconda3\envs\flower_tutorial\lib\site-packages\ray\serialization.py", line 309, in deserialize_objects
    obj = self._deserialize_object(data, metadata, object_ref)
  File "C:\Users\B00830189\AppData\Local\anaconda3\envs\flower_tutorial\lib\site-packages\ray\serialization.py", line 215, in _deserialize_object
    return self._deserialize_msgpack_data(data, metadata_fields)
  File "C:\Users\B00830189\AppData\Local\anaconda3\envs\flower_tutorial\lib\site-packages\ray\serialization.py", line 174, in _deserialize_msgpack_data
    python_objects = self._deserialize_pickle5_data(pickle5_data)
  File "C:\Users\B00830189\AppData\Local\anaconda3\envs\flower_tutorial\lib\site-packages\ray\serialization.py", line 164, in _deserialize_pickle5_data
    obj = pickle.loads(in_band)
  File "C:\Users\B00830189\AppData\Local\anaconda3\envs\flower_tutorial\lib\site-packages\torch\__init__.py", line 128, in <module>
    raise err
OSError: [WinError 1455] The paging file is too small for this operation to complete. Error loading "C:\Users\B00830189\AppData\Local\anaconda3\envs\flower_tutorial\lib\site-packages\torch\lib\shm.dll" or one of its dependencies.
[2024-05-24 14:24:43,166][flwr][ERROR] - [36mray::launch_and_evaluate()[39m (pid=14596, ip=127.0.0.1)
  File "python\ray\_raylet.pyx", line 602, in ray._raylet.execute_task
  File "python\ray\_raylet.pyx", line 624, in ray._raylet.execute_task
  File "python\ray\_raylet.pyx", line 456, in ray._raylet.raise_if_dependency_failed
ray.exceptions.RaySystemError: System error: [WinError 1455] The paging file is too small for this operation to complete. Error loading "C:\Users\B00830189\AppData\Local\anaconda3\envs\flower_tutorial\lib\site-packages\torch\lib\shm.dll" or one of its dependencies.
traceback: Traceback (most recent call last):
  File "C:\Users\B00830189\AppData\Local\anaconda3\envs\flower_tutorial\lib\site-packages\ray\serialization.py", line 309, in deserialize_objects
    obj = self._deserialize_object(data, metadata, object_ref)
  File "C:\Users\B00830189\AppData\Local\anaconda3\envs\flower_tutorial\lib\site-packages\ray\serialization.py", line 215, in _deserialize_object
    return self._deserialize_msgpack_data(data, metadata_fields)
  File "C:\Users\B00830189\AppData\Local\anaconda3\envs\flower_tutorial\lib\site-packages\ray\serialization.py", line 174, in _deserialize_msgpack_data
    python_objects = self._deserialize_pickle5_data(pickle5_data)
  File "C:\Users\B00830189\AppData\Local\anaconda3\envs\flower_tutorial\lib\site-packages\ray\serialization.py", line 164, in _deserialize_pickle5_data
    obj = pickle.loads(in_band)
  File "C:\Users\B00830189\AppData\Local\anaconda3\envs\flower_tutorial\lib\site-packages\torch\__init__.py", line 128, in <module>
    raise err
OSError: [WinError 1455] The paging file is too small for this operation to complete. Error loading "C:\Users\B00830189\AppData\Local\anaconda3\envs\flower_tutorial\lib\site-packages\torch\lib\shm.dll" or one of its dependencies.
